Internal Server Error: /api/v1/dslamport/command/
Traceback (most recent call last):
  File "/usr/local/lib/python3.8/dist-packages/django/core/handlers/exception.py", line 47, in inner
    response = get_response(request)
  File "/usr/local/lib/python3.8/dist-packages/django/core/handlers/base.py", line 179, in _get_response
    response = wrapped_callback(request, *callback_args, **callback_kwargs)
  File "/usr/local/lib/python3.8/dist-packages/django/views/decorators/csrf.py", line 54, in wrapped_view
    return view_func(*args, **kwargs)
  File "/usr/local/lib/python3.8/dist-packages/django/views/generic/base.py", line 70, in view
    return self.dispatch(request, *args, **kwargs)
  File "/usr/local/lib/python3.8/dist-packages/rest_framework/views.py", line 509, in dispatch
    response = self.handle_exception(exc)
  File "/usr/local/lib/python3.8/dist-packages/rest_framework/views.py", line 469, in handle_exception
    self.raise_uncaught_exception(exc)
  File "/usr/local/lib/python3.8/dist-packages/rest_framework/views.py", line 480, in raise_uncaught_exception
    raise exc
  File "/usr/local/lib/python3.8/dist-packages/rest_framework/views.py", line 506, in dispatch
    response = handler(request, *args, **kwargs)
  File "/opt/portmanv3/portman_web/dslam/views.py", line 1194, in post
    result = utility.dslam_port_run_command(dslam_obj.pk, command, params)
  File "/opt/portmanv3/portman_web/dslam/utility.py", line 21, in dslam_port_run_command
    return c.add_command(dslam_id, command, params)
  File "/usr/local/lib/python3.8/dist-packages/jsonrpclib/jsonrpc.py", line 821, in __call__
    return self.__send(self.__name, args)
  File "/usr/local/lib/python3.8/dist-packages/jsonrpclib/jsonrpc.py", line 696, in _request
    check_for_errors(response)
  File "/usr/local/lib/python3.8/dist-packages/jsonrpclib/jsonrpc.py", line 1453, in check_for_errors
    raise ProtocolError((code, message))
jsonrpclib.jsonrpc.ProtocolError: (-32603, 'Server error: File "/opt/portmanv3/portman_core2/vendors/command_factory.py", line 13, in get_type | Exception: Resource Type "show cart" is Not Registered!\n')
Internal Server Error: /api/v1/dslamport/command/
Traceback (most recent call last):
  File "/usr/local/lib/python3.8/dist-packages/django/core/handlers/exception.py", line 47, in inner
    response = get_response(request)
  File "/usr/local/lib/python3.8/dist-packages/django/core/handlers/base.py", line 179, in _get_response
    response = wrapped_callback(request, *callback_args, **callback_kwargs)
  File "/usr/local/lib/python3.8/dist-packages/django/views/decorators/csrf.py", line 54, in wrapped_view
    return view_func(*args, **kwargs)
  File "/usr/local/lib/python3.8/dist-packages/django/views/generic/base.py", line 70, in view
    return self.dispatch(request, *args, **kwargs)
  File "/usr/local/lib/python3.8/dist-packages/rest_framework/views.py", line 509, in dispatch
    response = self.handle_exception(exc)
  File "/usr/local/lib/python3.8/dist-packages/rest_framework/views.py", line 469, in handle_exception
    self.raise_uncaught_exception(exc)
  File "/usr/local/lib/python3.8/dist-packages/rest_framework/views.py", line 480, in raise_uncaught_exception
    raise exc
  File "/usr/local/lib/python3.8/dist-packages/rest_framework/views.py", line 506, in dispatch
    response = handler(request, *args, **kwargs)
  File "/opt/portmanv3/portman_web/dslam/views.py", line 1194, in post
    result = utility.dslam_port_run_command(dslam_obj.pk, command, params)
  File "/opt/portmanv3/portman_web/dslam/utility.py", line 21, in dslam_port_run_command
    return c.add_command(dslam_id, command, params)
  File "/usr/local/lib/python3.8/dist-packages/jsonrpclib/jsonrpc.py", line 821, in __call__
    return self.__send(self.__name, args)
  File "/usr/local/lib/python3.8/dist-packages/jsonrpclib/jsonrpc.py", line 695, in _request
    response = self._run_request(request)
  File "/usr/local/lib/python3.8/dist-packages/jsonrpclib/jsonrpc.py", line 730, in _run_request
    response = self.__transport.request(
  File "/usr/lib/python3.8/xmlrpc/client.py", line 1153, in request
    return self.single_request(host, handler, request_body, verbose)
  File "/usr/local/lib/python3.8/dist-packages/jsonrpclib/jsonrpc.py", line 413, in single_request
    self.send_content(connection, request_body)
  File "/usr/local/lib/python3.8/dist-packages/jsonrpclib/jsonrpc.py", line 476, in send_content
    connection.endheaders()
  File "/usr/lib/python3.8/http/client.py", line 1250, in endheaders
    self._send_output(message_body, encode_chunked=encode_chunked)
  File "/usr/lib/python3.8/http/client.py", line 1010, in _send_output
    self.send(msg)
  File "/usr/lib/python3.8/http/client.py", line 950, in send
    self.connect()
  File "/usr/lib/python3.8/http/client.py", line 921, in connect
    self.sock = self._create_connection(
  File "/usr/lib/python3.8/socket.py", line 808, in create_connection
    raise err
  File "/usr/lib/python3.8/socket.py", line 796, in create_connection
    sock.connect(sa)
ConnectionRefusedError: [Errno 111] Connection refused
Internal Server Error: /api/v1/dslamport/command/
Traceback (most recent call last):
  File "/usr/local/lib/python3.8/dist-packages/django/core/handlers/exception.py", line 47, in inner
    response = get_response(request)
  File "/usr/local/lib/python3.8/dist-packages/django/core/handlers/base.py", line 179, in _get_response
    response = wrapped_callback(request, *callback_args, **callback_kwargs)
  File "/usr/local/lib/python3.8/dist-packages/django/views/decorators/csrf.py", line 54, in wrapped_view
    return view_func(*args, **kwargs)
  File "/usr/local/lib/python3.8/dist-packages/django/views/generic/base.py", line 70, in view
    return self.dispatch(request, *args, **kwargs)
  File "/usr/local/lib/python3.8/dist-packages/rest_framework/views.py", line 509, in dispatch
    response = self.handle_exception(exc)
  File "/usr/local/lib/python3.8/dist-packages/rest_framework/views.py", line 469, in handle_exception
    self.raise_uncaught_exception(exc)
  File "/usr/local/lib/python3.8/dist-packages/rest_framework/views.py", line 480, in raise_uncaught_exception
    raise exc
  File "/usr/local/lib/python3.8/dist-packages/rest_framework/views.py", line 506, in dispatch
    response = handler(request, *args, **kwargs)
  File "/opt/portmanv3/portman_web/dslam/views.py", line 1194, in post
    result = utility.dslam_port_run_command(dslam_obj.pk, command, params)
  File "/opt/portmanv3/portman_web/dslam/utility.py", line 21, in dslam_port_run_command
    return c.add_command(dslam_id, command, params)
  File "/usr/local/lib/python3.8/dist-packages/jsonrpclib/jsonrpc.py", line 821, in __call__
    return self.__send(self.__name, args)
  File "/usr/local/lib/python3.8/dist-packages/jsonrpclib/jsonrpc.py", line 695, in _request
    response = self._run_request(request)
  File "/usr/local/lib/python3.8/dist-packages/jsonrpclib/jsonrpc.py", line 730, in _run_request
    response = self.__transport.request(
  File "/usr/lib/python3.8/xmlrpc/client.py", line 1153, in request
    return self.single_request(host, handler, request_body, verbose)
  File "/usr/local/lib/python3.8/dist-packages/jsonrpclib/jsonrpc.py", line 413, in single_request
    self.send_content(connection, request_body)
  File "/usr/local/lib/python3.8/dist-packages/jsonrpclib/jsonrpc.py", line 476, in send_content
    connection.endheaders()
  File "/usr/lib/python3.8/http/client.py", line 1250, in endheaders
    self._send_output(message_body, encode_chunked=encode_chunked)
  File "/usr/lib/python3.8/http/client.py", line 1010, in _send_output
    self.send(msg)
  File "/usr/lib/python3.8/http/client.py", line 950, in send
    self.connect()
  File "/usr/lib/python3.8/http/client.py", line 921, in connect
    self.sock = self._create_connection(
  File "/usr/lib/python3.8/socket.py", line 808, in create_connection
    raise err
  File "/usr/lib/python3.8/socket.py", line 796, in create_connection
    sock.connect(sa)
ConnectionRefusedError: [Errno 111] Connection refused
Internal Server Error: /api/v1/dslamport/command/
Traceback (most recent call last):
  File "/usr/local/lib/python3.8/dist-packages/django/core/handlers/exception.py", line 47, in inner
    response = get_response(request)
  File "/usr/local/lib/python3.8/dist-packages/django/core/handlers/base.py", line 179, in _get_response
    response = wrapped_callback(request, *callback_args, **callback_kwargs)
  File "/usr/local/lib/python3.8/dist-packages/django/views/decorators/csrf.py", line 54, in wrapped_view
    return view_func(*args, **kwargs)
  File "/usr/local/lib/python3.8/dist-packages/django/views/generic/base.py", line 70, in view
    return self.dispatch(request, *args, **kwargs)
  File "/usr/local/lib/python3.8/dist-packages/rest_framework/views.py", line 509, in dispatch
    response = self.handle_exception(exc)
  File "/usr/local/lib/python3.8/dist-packages/rest_framework/views.py", line 469, in handle_exception
    self.raise_uncaught_exception(exc)
  File "/usr/local/lib/python3.8/dist-packages/rest_framework/views.py", line 480, in raise_uncaught_exception
    raise exc
  File "/usr/local/lib/python3.8/dist-packages/rest_framework/views.py", line 506, in dispatch
    response = handler(request, *args, **kwargs)
  File "/opt/portmanv3/portman_web/dslam/views.py", line 1194, in post
    result = utility.dslam_port_run_command(dslam_obj.pk, command, params)
  File "/opt/portmanv3/portman_web/dslam/utility.py", line 21, in dslam_port_run_command
    return c.add_command(dslam_id, command, params)
  File "/usr/local/lib/python3.8/dist-packages/jsonrpclib/jsonrpc.py", line 821, in __call__
    return self.__send(self.__name, args)
  File "/usr/local/lib/python3.8/dist-packages/jsonrpclib/jsonrpc.py", line 695, in _request
    response = self._run_request(request)
  File "/usr/local/lib/python3.8/dist-packages/jsonrpclib/jsonrpc.py", line 730, in _run_request
    response = self.__transport.request(
  File "/usr/lib/python3.8/xmlrpc/client.py", line 1153, in request
    return self.single_request(host, handler, request_body, verbose)
  File "/usr/local/lib/python3.8/dist-packages/jsonrpclib/jsonrpc.py", line 413, in single_request
    self.send_content(connection, request_body)
  File "/usr/local/lib/python3.8/dist-packages/jsonrpclib/jsonrpc.py", line 476, in send_content
    connection.endheaders()
  File "/usr/lib/python3.8/http/client.py", line 1250, in endheaders
    self._send_output(message_body, encode_chunked=encode_chunked)
  File "/usr/lib/python3.8/http/client.py", line 1010, in _send_output
    self.send(msg)
  File "/usr/lib/python3.8/http/client.py", line 950, in send
    self.connect()
  File "/usr/lib/python3.8/http/client.py", line 921, in connect
    self.sock = self._create_connection(
  File "/usr/lib/python3.8/socket.py", line 808, in create_connection
    raise err
  File "/usr/lib/python3.8/socket.py", line 796, in create_connection
    sock.connect(sa)
ConnectionRefusedError: [Errno 111] Connection refused
Internal Server Error: /api/v1/dslamport/command/
Traceback (most recent call last):
  File "/usr/local/lib/python3.8/dist-packages/django/core/handlers/exception.py", line 47, in inner
    response = get_response(request)
  File "/usr/local/lib/python3.8/dist-packages/django/core/handlers/base.py", line 179, in _get_response
    response = wrapped_callback(request, *callback_args, **callback_kwargs)
  File "/usr/local/lib/python3.8/dist-packages/django/views/decorators/csrf.py", line 54, in wrapped_view
    return view_func(*args, **kwargs)
  File "/usr/local/lib/python3.8/dist-packages/django/views/generic/base.py", line 70, in view
    return self.dispatch(request, *args, **kwargs)
  File "/usr/local/lib/python3.8/dist-packages/rest_framework/views.py", line 509, in dispatch
    response = self.handle_exception(exc)
  File "/usr/local/lib/python3.8/dist-packages/rest_framework/views.py", line 469, in handle_exception
    self.raise_uncaught_exception(exc)
  File "/usr/local/lib/python3.8/dist-packages/rest_framework/views.py", line 480, in raise_uncaught_exception
    raise exc
  File "/usr/local/lib/python3.8/dist-packages/rest_framework/views.py", line 506, in dispatch
    response = handler(request, *args, **kwargs)
  File "/opt/portmanv3/portman_web/dslam/views.py", line 1194, in post
    result = utility.dslam_port_run_command(dslam_obj.pk, command, params)
  File "/opt/portmanv3/portman_web/dslam/utility.py", line 21, in dslam_port_run_command
    return c.add_command(dslam_id, command, params)
  File "/usr/local/lib/python3.8/dist-packages/jsonrpclib/jsonrpc.py", line 821, in __call__
    return self.__send(self.__name, args)
  File "/usr/local/lib/python3.8/dist-packages/jsonrpclib/jsonrpc.py", line 695, in _request
    response = self._run_request(request)
  File "/usr/local/lib/python3.8/dist-packages/jsonrpclib/jsonrpc.py", line 730, in _run_request
    response = self.__transport.request(
  File "/usr/lib/python3.8/xmlrpc/client.py", line 1153, in request
    return self.single_request(host, handler, request_body, verbose)
  File "/usr/local/lib/python3.8/dist-packages/jsonrpclib/jsonrpc.py", line 413, in single_request
    self.send_content(connection, request_body)
  File "/usr/local/lib/python3.8/dist-packages/jsonrpclib/jsonrpc.py", line 476, in send_content
    connection.endheaders()
  File "/usr/lib/python3.8/http/client.py", line 1250, in endheaders
    self._send_output(message_body, encode_chunked=encode_chunked)
  File "/usr/lib/python3.8/http/client.py", line 1010, in _send_output
    self.send(msg)
  File "/usr/lib/python3.8/http/client.py", line 950, in send
    self.connect()
  File "/usr/lib/python3.8/http/client.py", line 921, in connect
    self.sock = self._create_connection(
  File "/usr/lib/python3.8/socket.py", line 808, in create_connection
    raise err
  File "/usr/lib/python3.8/socket.py", line 796, in create_connection
    sock.connect(sa)
ConnectionRefusedError: [Errno 111] Connection refused
Internal Server Error: /api/v1/dslamport/command/
Traceback (most recent call last):
  File "/usr/local/lib/python3.8/dist-packages/django/core/handlers/exception.py", line 47, in inner
    response = get_response(request)
  File "/usr/local/lib/python3.8/dist-packages/django/core/handlers/base.py", line 179, in _get_response
    response = wrapped_callback(request, *callback_args, **callback_kwargs)
  File "/usr/local/lib/python3.8/dist-packages/django/views/decorators/csrf.py", line 54, in wrapped_view
    return view_func(*args, **kwargs)
  File "/usr/local/lib/python3.8/dist-packages/django/views/generic/base.py", line 70, in view
    return self.dispatch(request, *args, **kwargs)
  File "/usr/local/lib/python3.8/dist-packages/rest_framework/views.py", line 509, in dispatch
    response = self.handle_exception(exc)
  File "/usr/local/lib/python3.8/dist-packages/rest_framework/views.py", line 469, in handle_exception
    self.raise_uncaught_exception(exc)
  File "/usr/local/lib/python3.8/dist-packages/rest_framework/views.py", line 480, in raise_uncaught_exception
    raise exc
  File "/usr/local/lib/python3.8/dist-packages/rest_framework/views.py", line 506, in dispatch
    response = handler(request, *args, **kwargs)
  File "/opt/portmanv3/portman_web/dslam/views.py", line 1194, in post
    result = utility.dslam_port_run_command(dslam_obj.pk, command, params)
  File "/opt/portmanv3/portman_web/dslam/utility.py", line 21, in dslam_port_run_command
    return c.add_command(dslam_id, command, params)
  File "/usr/local/lib/python3.8/dist-packages/jsonrpclib/jsonrpc.py", line 821, in __call__
    return self.__send(self.__name, args)
  File "/usr/local/lib/python3.8/dist-packages/jsonrpclib/jsonrpc.py", line 695, in _request
    response = self._run_request(request)
  File "/usr/local/lib/python3.8/dist-packages/jsonrpclib/jsonrpc.py", line 730, in _run_request
    response = self.__transport.request(
  File "/usr/lib/python3.8/xmlrpc/client.py", line 1153, in request
    return self.single_request(host, handler, request_body, verbose)
  File "/usr/local/lib/python3.8/dist-packages/jsonrpclib/jsonrpc.py", line 413, in single_request
    self.send_content(connection, request_body)
  File "/usr/local/lib/python3.8/dist-packages/jsonrpclib/jsonrpc.py", line 476, in send_content
    connection.endheaders()
  File "/usr/lib/python3.8/http/client.py", line 1250, in endheaders
    self._send_output(message_body, encode_chunked=encode_chunked)
  File "/usr/lib/python3.8/http/client.py", line 1010, in _send_output
    self.send(msg)
  File "/usr/lib/python3.8/http/client.py", line 950, in send
    self.connect()
  File "/usr/lib/python3.8/http/client.py", line 921, in connect
    self.sock = self._create_connection(
  File "/usr/lib/python3.8/socket.py", line 808, in create_connection
    raise err
  File "/usr/lib/python3.8/socket.py", line 796, in create_connection
    sock.connect(sa)
ConnectionRefusedError: [Errno 111] Connection refused
Not Found: /favicon.ico
Unauthorized: /api/v1/switch/switch_run_command/
Unauthorized: /api/v1/switch-command/
Unauthorized: /api/v1/users/get_permission/
Unauthorized: /api/v1/switch/
Unauthorized: /api/v1/users/get_permission/
Unauthorized: /api/v1/users/get_permission/
Unauthorized: /api/v1/users/get_permission/
Unauthorized: /api/v1/users/get_permission/
Unauthorized: /api/v1/users/get_permission/
Unauthorized: /api/v1/users/get_permission/
Not Found: /api/v1/dslam//
Not Found: /api/v1/dslam//
Not Found: /api/v1/dslam//
