Unauthorized: /api/v1/users/login/
Unauthorized: /api/v1/users/login/
Unauthorized: /api/v1/users/login/
Unauthorized: /api/v1/users/login/
Unauthorized: /api/v1/users/login/
Not Found: /favicon.ico
Unauthorized: /api/v1/dslam-port/385347/report/
Unauthorized: /api/v1/port-command/
Unauthorized: /api/v1/command/
Unauthorized: /api/v1/dslam-port/385347/
Unauthorized: /api/v1/users/login/
Unauthorized: /api/v1/users/login/
Not Found: /api/v1/users/login/
Unauthorized: /api/v1/users/get_permission/
Internal Server Error: /api/v1/router/
Traceback (most recent call last):
  File "/usr/local/lib/python3.8/dist-packages/django/core/handlers/exception.py", line 47, in inner
    response = get_response(request)
  File "/usr/local/lib/python3.8/dist-packages/django/core/handlers/base.py", line 179, in _get_response
    response = wrapped_callback(request, *callback_args, **callback_kwargs)
  File "/usr/local/lib/python3.8/dist-packages/django/views/decorators/csrf.py", line 54, in wrapped_view
    return view_func(*args, **kwargs)
  File "/usr/local/lib/python3.8/dist-packages/rest_framework/viewsets.py", line 125, in view
    return self.dispatch(request, *args, **kwargs)
  File "/usr/local/lib/python3.8/dist-packages/rest_framework/views.py", line 509, in dispatch
    response = self.handle_exception(exc)
  File "/usr/local/lib/python3.8/dist-packages/rest_framework/views.py", line 469, in handle_exception
    self.raise_uncaught_exception(exc)
  File "/usr/local/lib/python3.8/dist-packages/rest_framework/views.py", line 480, in raise_uncaught_exception
    raise exc
  File "/usr/local/lib/python3.8/dist-packages/rest_framework/views.py", line 506, in dispatch
    response = handler(request, *args, **kwargs)
  File "/usr/local/lib/python3.8/dist-packages/rest_framework/mixins.py", line 42, in list
    serializer = self.get_serializer(page, many=True)
  File "/opt/portmanv3/portman_web/router/views.py", line 66, in get_serializer
    return RouterSerializer(request=self.request, *args, **kwargs)
  File "/usr/local/lib/python3.8/dist-packages/rest_framework/serializers.py", line 121, in __new__
    return cls.many_init(*args, **kwargs)
  File "/usr/local/lib/python3.8/dist-packages/rest_framework/serializers.py", line 146, in many_init
    child_serializer = cls(*args, **kwargs)
  File "/usr/local/lib/python3.8/dist-packages/rest_framework/serializers.py", line 115, in __init__
    super().__init__(**kwargs)
TypeError: __init__() got an unexpected keyword argument 'request'
Internal Server Error: /api/v1/router/
Traceback (most recent call last):
  File "/usr/local/lib/python3.8/dist-packages/django/core/handlers/exception.py", line 47, in inner
    response = get_response(request)
  File "/usr/local/lib/python3.8/dist-packages/django/core/handlers/base.py", line 179, in _get_response
    response = wrapped_callback(request, *callback_args, **callback_kwargs)
  File "/usr/local/lib/python3.8/dist-packages/django/views/decorators/csrf.py", line 54, in wrapped_view
    return view_func(*args, **kwargs)
  File "/usr/local/lib/python3.8/dist-packages/rest_framework/viewsets.py", line 125, in view
    return self.dispatch(request, *args, **kwargs)
  File "/usr/local/lib/python3.8/dist-packages/rest_framework/views.py", line 509, in dispatch
    response = self.handle_exception(exc)
  File "/usr/local/lib/python3.8/dist-packages/rest_framework/views.py", line 469, in handle_exception
    self.raise_uncaught_exception(exc)
  File "/usr/local/lib/python3.8/dist-packages/rest_framework/views.py", line 480, in raise_uncaught_exception
    raise exc
  File "/usr/local/lib/python3.8/dist-packages/rest_framework/views.py", line 506, in dispatch
    response = handler(request, *args, **kwargs)
  File "/usr/local/lib/python3.8/dist-packages/rest_framework/mixins.py", line 42, in list
    serializer = self.get_serializer(page, many=True)
  File "/opt/portmanv3/portman_web/router/views.py", line 66, in get_serializer
    return RouterSerializer(request=self.request, *args, **kwargs)
  File "/usr/local/lib/python3.8/dist-packages/rest_framework/serializers.py", line 121, in __new__
    return cls.many_init(*args, **kwargs)
  File "/usr/local/lib/python3.8/dist-packages/rest_framework/serializers.py", line 146, in many_init
    child_serializer = cls(*args, **kwargs)
  File "/usr/local/lib/python3.8/dist-packages/rest_framework/serializers.py", line 115, in __init__
    super().__init__(**kwargs)
TypeError: __init__() got an unexpected keyword argument 'request'
Internal Server Error: /api/v1/router/
Traceback (most recent call last):
  File "/usr/local/lib/python3.8/dist-packages/django/core/handlers/exception.py", line 47, in inner
    response = get_response(request)
  File "/usr/local/lib/python3.8/dist-packages/django/core/handlers/base.py", line 179, in _get_response
    response = wrapped_callback(request, *callback_args, **callback_kwargs)
  File "/usr/local/lib/python3.8/dist-packages/django/views/decorators/csrf.py", line 54, in wrapped_view
    return view_func(*args, **kwargs)
  File "/usr/local/lib/python3.8/dist-packages/rest_framework/viewsets.py", line 125, in view
    return self.dispatch(request, *args, **kwargs)
  File "/usr/local/lib/python3.8/dist-packages/rest_framework/views.py", line 509, in dispatch
    response = self.handle_exception(exc)
  File "/usr/local/lib/python3.8/dist-packages/rest_framework/views.py", line 469, in handle_exception
    self.raise_uncaught_exception(exc)
  File "/usr/local/lib/python3.8/dist-packages/rest_framework/views.py", line 480, in raise_uncaught_exception
    raise exc
  File "/usr/local/lib/python3.8/dist-packages/rest_framework/views.py", line 506, in dispatch
    response = handler(request, *args, **kwargs)
  File "/usr/local/lib/python3.8/dist-packages/rest_framework/mixins.py", line 42, in list
    serializer = self.get_serializer(page, many=True)
  File "/opt/portmanv3/portman_web/router/views.py", line 66, in get_serializer
    return RouterSerializer(request=self.request, *args, **kwargs)
  File "/usr/local/lib/python3.8/dist-packages/rest_framework/serializers.py", line 121, in __new__
    return cls.many_init(*args, **kwargs)
  File "/usr/local/lib/python3.8/dist-packages/rest_framework/serializers.py", line 146, in many_init
    child_serializer = cls(*args, **kwargs)
  File "/usr/local/lib/python3.8/dist-packages/rest_framework/serializers.py", line 115, in __init__
    super().__init__(**kwargs)
TypeError: __init__() got an unexpected keyword argument 'request'
Internal Server Error: /api/v1/router/
Traceback (most recent call last):
  File "/usr/local/lib/python3.8/dist-packages/django/core/handlers/exception.py", line 47, in inner
    response = get_response(request)
  File "/usr/local/lib/python3.8/dist-packages/django/core/handlers/base.py", line 179, in _get_response
    response = wrapped_callback(request, *callback_args, **callback_kwargs)
  File "/usr/local/lib/python3.8/dist-packages/django/views/decorators/csrf.py", line 54, in wrapped_view
    return view_func(*args, **kwargs)
  File "/usr/local/lib/python3.8/dist-packages/rest_framework/viewsets.py", line 104, in view
    self = cls(**initkwargs)
  File "/opt/portmanv3/portman_web/router/views.py", line 68, in __init__
    super(DSLAMSerializer, self).__init__(*args, **kwargs)
NameError: name 'DSLAMSerializer' is not defined
Internal Server Error: /api/v1/router/
Traceback (most recent call last):
  File "/usr/local/lib/python3.8/dist-packages/django/core/handlers/exception.py", line 47, in inner
    response = get_response(request)
  File "/usr/local/lib/python3.8/dist-packages/django/core/handlers/base.py", line 179, in _get_response
    response = wrapped_callback(request, *callback_args, **callback_kwargs)
  File "/usr/local/lib/python3.8/dist-packages/django/views/decorators/csrf.py", line 54, in wrapped_view
    return view_func(*args, **kwargs)
  File "/usr/local/lib/python3.8/dist-packages/rest_framework/viewsets.py", line 104, in view
    self = cls(**initkwargs)
  File "/opt/portmanv3/portman_web/router/views.py", line 68, in __init__
    super(RouterSerializer, self).__init__(*args, **kwargs)
TypeError: super(type, obj): obj must be an instance or subtype of type
Internal Server Error: /api/v1/router/
Traceback (most recent call last):
  File "/usr/local/lib/python3.8/dist-packages/django/core/handlers/exception.py", line 47, in inner
    response = get_response(request)
  File "/usr/local/lib/python3.8/dist-packages/django/core/handlers/base.py", line 179, in _get_response
    response = wrapped_callback(request, *callback_args, **callback_kwargs)
  File "/usr/local/lib/python3.8/dist-packages/django/views/decorators/csrf.py", line 54, in wrapped_view
    return view_func(*args, **kwargs)
  File "/usr/local/lib/python3.8/dist-packages/rest_framework/viewsets.py", line 104, in view
    self = cls(**initkwargs)
  File "/opt/portmanv3/portman_web/router/views.py", line 68, in __init__
    super(RouterSerializer, self).__init__(*args, **kwargs)
TypeError: super(type, obj): obj must be an instance or subtype of type
Internal Server Error: /api/v1/router/
Traceback (most recent call last):
  File "/usr/local/lib/python3.8/dist-packages/django/core/handlers/exception.py", line 47, in inner
    response = get_response(request)
  File "/usr/local/lib/python3.8/dist-packages/django/core/handlers/base.py", line 179, in _get_response
    response = wrapped_callback(request, *callback_args, **callback_kwargs)
  File "/usr/local/lib/python3.8/dist-packages/django/views/decorators/csrf.py", line 54, in wrapped_view
    return view_func(*args, **kwargs)
  File "/usr/local/lib/python3.8/dist-packages/rest_framework/viewsets.py", line 104, in view
    self = cls(**initkwargs)
  File "/opt/portmanv3/portman_web/router/views.py", line 68, in __init__
    super(RouterSerializer, self).__init__(*args, **kwargs)
TypeError: super(type, obj): obj must be an instance or subtype of type
Internal Server Error: /api/v1/router/
Traceback (most recent call last):
  File "/usr/local/lib/python3.8/dist-packages/django/core/handlers/exception.py", line 47, in inner
    response = get_response(request)
  File "/usr/local/lib/python3.8/dist-packages/django/core/handlers/base.py", line 179, in _get_response
    response = wrapped_callback(request, *callback_args, **callback_kwargs)
  File "/usr/local/lib/python3.8/dist-packages/django/views/decorators/csrf.py", line 54, in wrapped_view
    return view_func(*args, **kwargs)
  File "/usr/local/lib/python3.8/dist-packages/rest_framework/viewsets.py", line 104, in view
    self = cls(**initkwargs)
  File "/opt/portmanv3/portman_web/router/views.py", line 68, in __init__
    super(RouterSerializer, self).__init__(*args, **kwargs)
TypeError: super(type, obj): obj must be an instance or subtype of type
Internal Server Error: /api/v1/router/
Traceback (most recent call last):
  File "/usr/local/lib/python3.8/dist-packages/django/core/handlers/exception.py", line 47, in inner
    response = get_response(request)
  File "/usr/local/lib/python3.8/dist-packages/django/core/handlers/base.py", line 179, in _get_response
    response = wrapped_callback(request, *callback_args, **callback_kwargs)
  File "/usr/local/lib/python3.8/dist-packages/django/views/decorators/csrf.py", line 54, in wrapped_view
    return view_func(*args, **kwargs)
  File "/usr/local/lib/python3.8/dist-packages/rest_framework/viewsets.py", line 104, in view
    self = cls(**initkwargs)
  File "/opt/portmanv3/portman_web/router/views.py", line 68, in __init__
    super(RouterSerializer, self).__init__(*args, **kwargs)
TypeError: super(type, obj): obj must be an instance or subtype of type
Unauthorized: /api/v1/users/get_permission/
