Method Not Allowed: /api/v1/province/get_provinces/
Internal Server Error: /api/v1/province/get_provinces/
Traceback (most recent call last):
  File "/home/mrtbadboy/.local/lib/python3.9/site-packages/django/core/handlers/exception.py", line 47, in inner
    response = get_response(request)
  File "/home/mrtbadboy/.local/lib/python3.9/site-packages/django/core/handlers/base.py", line 181, in _get_response
    response = wrapped_callback(request, *callback_args, **callback_kwargs)
  File "/home/mrtbadboy/.local/lib/python3.9/site-packages/django/views/decorators/csrf.py", line 54, in wrapped_view
    return view_func(*args, **kwargs)
  File "/home/mrtbadboy/.local/lib/python3.9/site-packages/django/views/generic/base.py", line 70, in view
    return self.dispatch(request, *args, **kwargs)
  File "/home/mrtbadboy/.local/lib/python3.9/site-packages/rest_framework/views.py", line 511, in dispatch
    self.response = self.finalize_response(request, response, *args, **kwargs)
  File "/home/mrtbadboy/.local/lib/python3.9/site-packages/rest_framework/views.py", line 423, in finalize_response
    assert isinstance(response, HttpResponseBase), (
AssertionError: Expected a `Response`, `HttpResponse` or `HttpStreamingResponse` to be returned from the view, but received a `<class 'django.db.models.query.QuerySet'>`
Not Found: /favicon.ico
Not Found: /favicon.ico
Not Found: /api/v1/province/get_cities_by_province_id/
Internal Server Error: /api/v1/contact/search_ports/
Traceback (most recent call last):
  File "/home/mrtbadboy/.local/lib/python3.9/site-packages/django/core/handlers/exception.py", line 47, in inner
    response = get_response(request)
  File "/home/mrtbadboy/.local/lib/python3.9/site-packages/django/core/handlers/base.py", line 181, in _get_response
    response = wrapped_callback(request, *callback_args, **callback_kwargs)
  File "/home/mrtbadboy/.local/lib/python3.9/site-packages/django/views/decorators/csrf.py", line 54, in wrapped_view
    return view_func(*args, **kwargs)
  File "/home/mrtbadboy/.local/lib/python3.9/site-packages/django/views/generic/base.py", line 70, in view
    return self.dispatch(request, *args, **kwargs)
  File "/home/mrtbadboy/.local/lib/python3.9/site-packages/rest_framework/views.py", line 511, in dispatch
    self.response = self.finalize_response(request, response, *args, **kwargs)
  File "/home/mrtbadboy/.local/lib/python3.9/site-packages/rest_framework/views.py", line 423, in finalize_response
    assert isinstance(response, HttpResponseBase), (
AssertionError: Expected a `Response`, `HttpResponse` or `HttpStreamingResponse` to be returned from the view, but received a `<class 'str'>`
Internal Server Error: /api/v1/contact/update_status_ports
Traceback (most recent call last):
  File "/home/mrtbadboy/.local/lib/python3.9/site-packages/django/core/handlers/exception.py", line 47, in inner
    response = get_response(request)
  File "/home/mrtbadboy/.local/lib/python3.9/site-packages/django/utils/deprecation.py", line 116, in __call__
    response = self.process_request(request)
  File "/home/mrtbadboy/.local/lib/python3.9/site-packages/django/middleware/common.py", line 54, in process_request
    path = self.get_full_path_with_slash(request)
  File "/home/mrtbadboy/.local/lib/python3.9/site-packages/django/middleware/common.py", line 88, in get_full_path_with_slash
    raise RuntimeError(
RuntimeError: You called this URL via POST, but the URL doesn't end in a slash and you have APPEND_SLASH set. Django can't redirect to the slash URL while maintaining POST data. Change your form to point to localhost:2080/api/v1/contact/update_status_ports/ (note the trailing slash), or set APPEND_SLASH=False in your Django settings.
Unauthorized: /api/v1/contact/update_status_ports/
Internal Server Error: /api/v1/contact/update_status_ports/
Traceback (most recent call last):
  File "/home/mrtbadboy/.local/lib/python3.9/site-packages/django/core/handlers/exception.py", line 47, in inner
    response = get_response(request)
  File "/home/mrtbadboy/.local/lib/python3.9/site-packages/django/core/handlers/base.py", line 181, in _get_response
    response = wrapped_callback(request, *callback_args, **callback_kwargs)
  File "/home/mrtbadboy/.local/lib/python3.9/site-packages/django/views/decorators/csrf.py", line 54, in wrapped_view
    return view_func(*args, **kwargs)
  File "/home/mrtbadboy/.local/lib/python3.9/site-packages/django/views/generic/base.py", line 70, in view
    return self.dispatch(request, *args, **kwargs)
  File "/home/mrtbadboy/.local/lib/python3.9/site-packages/rest_framework/views.py", line 511, in dispatch
    self.response = self.finalize_response(request, response, *args, **kwargs)
  File "/home/mrtbadboy/.local/lib/python3.9/site-packages/rest_framework/views.py", line 423, in finalize_response
    assert isinstance(response, HttpResponseBase), (
AssertionError: Expected a `Response`, `HttpResponse` or `HttpStreamingResponse` to be returned from the view, but received a `<class 'contact.models.Order'>`
Internal Server Error: /api/v1/contact/update_status_ports/
Traceback (most recent call last):
  File "/home/mrtbadboy/.local/lib/python3.9/site-packages/django/core/handlers/exception.py", line 47, in inner
    response = get_response(request)
  File "/home/mrtbadboy/.local/lib/python3.9/site-packages/django/core/handlers/base.py", line 181, in _get_response
    response = wrapped_callback(request, *callback_args, **callback_kwargs)
  File "/home/mrtbadboy/.local/lib/python3.9/site-packages/django/views/decorators/csrf.py", line 54, in wrapped_view
    return view_func(*args, **kwargs)
  File "/home/mrtbadboy/.local/lib/python3.9/site-packages/django/views/generic/base.py", line 70, in view
    return self.dispatch(request, *args, **kwargs)
  File "/home/mrtbadboy/.local/lib/python3.9/site-packages/rest_framework/views.py", line 511, in dispatch
    self.response = self.finalize_response(request, response, *args, **kwargs)
  File "/home/mrtbadboy/.local/lib/python3.9/site-packages/rest_framework/views.py", line 423, in finalize_response
    assert isinstance(response, HttpResponseBase), (
AssertionError: Expected a `Response`, `HttpResponse` or `HttpStreamingResponse` to be returned from the view, but received a `<class 'str'>`
Internal Server Error: /api/v1/contact/update_status_ports/
Traceback (most recent call last):
  File "/home/mrtbadboy/.local/lib/python3.9/site-packages/django/core/handlers/exception.py", line 47, in inner
    response = get_response(request)
  File "/home/mrtbadboy/.local/lib/python3.9/site-packages/django/core/handlers/base.py", line 204, in _get_response
    response = response.render()
  File "/home/mrtbadboy/.local/lib/python3.9/site-packages/django/template/response.py", line 105, in render
    self.content = self.rendered_content
  File "/home/mrtbadboy/.local/lib/python3.9/site-packages/rest_framework/response.py", line 70, in rendered_content
    ret = renderer.render(self.data, accepted_media_type, context)
  File "/home/mrtbadboy/.local/lib/python3.9/site-packages/rest_framework/renderers.py", line 100, in render
    ret = json.dumps(
  File "/home/mrtbadboy/.local/lib/python3.9/site-packages/rest_framework/utils/json.py", line 25, in dumps
    return json.dumps(*args, **kwargs)
  File "/usr/lib/python3.9/json/__init__.py", line 234, in dumps
    return cls(
  File "/usr/lib/python3.9/json/encoder.py", line 199, in encode
    chunks = self.iterencode(o, _one_shot=True)
  File "/usr/lib/python3.9/json/encoder.py", line 257, in iterencode
    return _iterencode(o, 0)
  File "/home/mrtbadboy/.local/lib/python3.9/site-packages/rest_framework/utils/encoders.py", line 67, in default
    return super().default(obj)
  File "/usr/lib/python3.9/json/encoder.py", line 179, in default
    raise TypeError(f'Object of type {o.__class__.__name__} '
TypeError: Object of type Order is not JSON serializable
Method Not Allowed: /api/v1/contact/get_ordr_port_info/
Unauthorized: /api/v1/contact/get_ordr_port_info/
Method Not Allowed: /api/v1/contact/get_ordr_port_info/
Method Not Allowed: /api/v1/contact/get_ordr_port_info/
Unauthorized: /api/v1/contact/update_status_ports/
Internal Server Error: /api/v1/contact/update_status_ports/
Internal Server Error: /api/v1/dslamport/register-port/
Traceback (most recent call last):
  File "/opt/portmanv3/portman_web/dslam/views.py", line 3607, in post
    result = utility.dslam_port_run_command(dslam_obj.id, 'add to vlan', params)
  File "/opt/portmanv3/portman_web/dslam/utility.py", line 21, in dslam_port_run_command
    return c.add_command(dslam_id, command, params)
  File "/home/mrtbadboy/.local/lib/python3.9/site-packages/jsonrpclib/jsonrpc.py", line 263, in __call__
    return self.__send(self.__name, args)
  File "/home/mrtbadboy/.local/lib/python3.9/site-packages/jsonrpclib/jsonrpc.py", line 213, in _request
    check_for_errors(response)
  File "/home/mrtbadboy/.local/lib/python3.9/site-packages/jsonrpclib/jsonrpc.py", line 542, in check_for_errors
    raise ProtocolError((code, message))
jsonrpclib.jsonrpc.ProtocolError: (-32603, 'Server error:   File "/usr/lib/python3.9/multiprocessing/connection.py", line 635, in SocketClient | ConnectionRefusedError: [Errno 111] Connection refused')

During handling of the above exception, another exception occurred:

Traceback (most recent call last):
  File "/opt/portmanv3/portman_web/dslam/views.py", line 3648, in post
    Mail.Send_Mail(mail_info)
  File "/opt/portmanv3/portman_web/dslam/mail.py", line 20, in Send_Mail
    server.login("oss-problems@pishgaman.net", "Oss_9r0@123")
  File "/usr/lib/python3.9/smtplib.py", line 730, in login
    raise SMTPException("No suitable authentication method found.")
smtplib.SMTPException: No suitable authentication method found.

During handling of the above exception, another exception occurred:

Traceback (most recent call last):
  File "/home/mrtbadboy/.local/lib/python3.9/site-packages/django/core/handlers/exception.py", line 47, in inner
    response = get_response(request)
  File "/home/mrtbadboy/.local/lib/python3.9/site-packages/django/core/handlers/base.py", line 181, in _get_response
    response = wrapped_callback(request, *callback_args, **callback_kwargs)
  File "/home/mrtbadboy/.local/lib/python3.9/site-packages/django/views/decorators/csrf.py", line 54, in wrapped_view
    return view_func(*args, **kwargs)
  File "/home/mrtbadboy/.local/lib/python3.9/site-packages/django/views/generic/base.py", line 70, in view
    return self.dispatch(request, *args, **kwargs)
  File "/home/mrtbadboy/.local/lib/python3.9/site-packages/rest_framework/views.py", line 509, in dispatch
    response = self.handle_exception(exc)
  File "/home/mrtbadboy/.local/lib/python3.9/site-packages/rest_framework/views.py", line 469, in handle_exception
    self.raise_uncaught_exception(exc)
  File "/home/mrtbadboy/.local/lib/python3.9/site-packages/rest_framework/views.py", line 480, in raise_uncaught_exception
    raise exc
  File "/home/mrtbadboy/.local/lib/python3.9/site-packages/rest_framework/views.py", line 506, in dispatch
    response = handler(request, *args, **kwargs)
  File "/opt/portmanv3/portman_web/dslam/views.py", line 3727, in post
    Mail.Send_Mail(mail_info)
  File "/opt/portmanv3/portman_web/dslam/mail.py", line 20, in Send_Mail
    server.login("oss-problems@pishgaman.net", "Oss_9r0@123")
  File "/usr/lib/python3.9/smtplib.py", line 730, in login
    raise SMTPException("No suitable authentication method found.")
smtplib.SMTPException: No suitable authentication method found.
Internal Server Error: /api/v1/dslamport/register-port/
Traceback (most recent call last):
  File "/opt/portmanv3/portman_web/dslam/views.py", line 3605, in post
    result = utility.dslam_port_run_command(dslam_obj.id, 'add to vlan', params)
  File "/opt/portmanv3/portman_web/dslam/utility.py", line 21, in dslam_port_run_command
    return c.add_command(dslam_id, command, params)
  File "/home/mrtbadboy/.local/lib/python3.9/site-packages/jsonrpclib/jsonrpc.py", line 263, in __call__
    return self.__send(self.__name, args)
  File "/home/mrtbadboy/.local/lib/python3.9/site-packages/jsonrpclib/jsonrpc.py", line 213, in _request
    check_for_errors(response)
  File "/home/mrtbadboy/.local/lib/python3.9/site-packages/jsonrpclib/jsonrpc.py", line 542, in check_for_errors
    raise ProtocolError((code, message))
jsonrpclib.jsonrpc.ProtocolError: (-32603, 'Server error:   File "/usr/lib/python3.9/multiprocessing/connection.py", line 635, in SocketClient | ConnectionRefusedError: [Errno 111] Connection refused')

During handling of the above exception, another exception occurred:

Traceback (most recent call last):
  File "/opt/portmanv3/portman_web/dslam/views.py", line 3646, in post
    Mail.Send_Mail(mail_info)
  File "/opt/portmanv3/portman_web/dslam/mail.py", line 20, in Send_Mail
    server.login("oss-problems@pishgaman.net", "Oss_9r0@123")
  File "/usr/lib/python3.9/smtplib.py", line 730, in login
    raise SMTPException("No suitable authentication method found.")
smtplib.SMTPException: No suitable authentication method found.

During handling of the above exception, another exception occurred:

Traceback (most recent call last):
  File "/home/mrtbadboy/.local/lib/python3.9/site-packages/django/core/handlers/exception.py", line 47, in inner
    response = get_response(request)
  File "/home/mrtbadboy/.local/lib/python3.9/site-packages/django/core/handlers/base.py", line 181, in _get_response
    response = wrapped_callback(request, *callback_args, **callback_kwargs)
  File "/home/mrtbadboy/.local/lib/python3.9/site-packages/django/views/decorators/csrf.py", line 54, in wrapped_view
    return view_func(*args, **kwargs)
  File "/home/mrtbadboy/.local/lib/python3.9/site-packages/django/views/generic/base.py", line 70, in view
    return self.dispatch(request, *args, **kwargs)
  File "/home/mrtbadboy/.local/lib/python3.9/site-packages/rest_framework/views.py", line 509, in dispatch
    response = self.handle_exception(exc)
  File "/home/mrtbadboy/.local/lib/python3.9/site-packages/rest_framework/views.py", line 469, in handle_exception
    self.raise_uncaught_exception(exc)
  File "/home/mrtbadboy/.local/lib/python3.9/site-packages/rest_framework/views.py", line 480, in raise_uncaught_exception
    raise exc
  File "/home/mrtbadboy/.local/lib/python3.9/site-packages/rest_framework/views.py", line 506, in dispatch
    response = handler(request, *args, **kwargs)
  File "/opt/portmanv3/portman_web/dslam/views.py", line 3725, in post
    Mail.Send_Mail(mail_info)
  File "/opt/portmanv3/portman_web/dslam/mail.py", line 20, in Send_Mail
    server.login("oss-problems@pishgaman.net", "Oss_9r0@123")
  File "/usr/lib/python3.9/smtplib.py", line 730, in login
    raise SMTPException("No suitable authentication method found.")
smtplib.SMTPException: No suitable authentication method found.
Bad Request: /api/v1/dslamport/register-port/
Bad Request: /api/v1/dslamport/register-port/
Bad Request: /api/v1/dslamport/register-port/
Bad Request: /api/v1/dslamport/register-port/
Not Found: /api/v1/dslamport/run-commandV3/
Not Found: /api/v1/dslamport/run-commandV3/
Unauthorized: /api/v1/dslamport/register-port/
Not Found: /favicon.ico
Not Found: /logout/
Not Found: /logout/
Not Found: /
Not Found: /favicon.ico
Not Found: /logout/
Not Found: /logout/
Not Found: /login
Unauthorized: /api/v1/users/login/
Unauthorized: /api/v1/users/login/
Not Found: /api/v1/user/login/
Internal Server Error: /api/v1/users/login/
Internal Server Error: /api/v1/users/login/
Internal Server Error: /api/v1/users/login/
Internal Server Error: /api/v1/users/login/
Internal Server Error: /api/v1/users/login/
Internal Server Error: /api/v1/users/login/
Internal Server Error: /api/v1/users/login/
Internal Server Error: /api/v1/users/login/
