Internal Server Error: /api/v1/dslamport/farzanegan_provider_date/
Traceback (most recent call last):
  File "/home/mrtbadboy/.local/lib/python3.9/site-packages/django/core/handlers/exception.py", line 47, in inner
    response = get_response(request)
  File "/home/mrtbadboy/.local/lib/python3.9/site-packages/django/core/handlers/base.py", line 181, in _get_response
    response = wrapped_callback(request, *callback_args, **callback_kwargs)
  File "/home/mrtbadboy/.local/lib/python3.9/site-packages/django/views/decorators/csrf.py", line 54, in wrapped_view
    return view_func(*args, **kwargs)
  File "/home/mrtbadboy/.local/lib/python3.9/site-packages/django/views/generic/base.py", line 70, in view
    return self.dispatch(request, *args, **kwargs)
  File "/home/mrtbadboy/.local/lib/python3.9/site-packages/rest_framework/views.py", line 511, in dispatch
    self.response = self.finalize_response(request, response, *args, **kwargs)
  File "/home/mrtbadboy/.local/lib/python3.9/site-packages/rest_framework/views.py", line 423, in finalize_response
    assert isinstance(response, HttpResponseBase), (
AssertionError: Expected a `Response`, `HttpResponse` or `HttpStreamingResponse` to be returned from the view, but received a `<class 'NoneType'>`
Internal Server Error: /api/v1/dslamport/farzanegan_provider_date/
Traceback (most recent call last):
  File "/home/mrtbadboy/.local/lib/python3.9/site-packages/django/core/handlers/exception.py", line 47, in inner
    response = get_response(request)
  File "/home/mrtbadboy/.local/lib/python3.9/site-packages/django/core/handlers/base.py", line 204, in _get_response
    response = response.render()
  File "/home/mrtbadboy/.local/lib/python3.9/site-packages/django/template/response.py", line 105, in render
    self.content = self.rendered_content
  File "/home/mrtbadboy/.local/lib/python3.9/site-packages/rest_framework/response.py", line 70, in rendered_content
    ret = renderer.render(self.data, accepted_media_type, context)
  File "/home/mrtbadboy/.local/lib/python3.9/site-packages/rest_framework/renderers.py", line 100, in render
    ret = json.dumps(
  File "/home/mrtbadboy/.local/lib/python3.9/site-packages/rest_framework/utils/json.py", line 25, in dumps
    return json.dumps(*args, **kwargs)
  File "/usr/lib/python3.9/json/__init__.py", line 234, in dumps
    return cls(
  File "/usr/lib/python3.9/json/encoder.py", line 199, in encode
    chunks = self.iterencode(o, _one_shot=True)
  File "/usr/lib/python3.9/json/encoder.py", line 257, in iterencode
    return _iterencode(o, 0)
  File "/home/mrtbadboy/.local/lib/python3.9/site-packages/rest_framework/utils/encoders.py", line 67, in default
    return super().default(obj)
  File "/usr/lib/python3.9/json/encoder.py", line 179, in default
    raise TypeError(f'Object of type {o.__class__.__name__} '
TypeError: Object of type FarzaneganProviderData is not JSON serializable
Internal Server Error: /api/v1/dslamport/farzanegan_provider_date/
Traceback (most recent call last):
  File "/home/mrtbadboy/.local/lib/python3.9/site-packages/django/core/handlers/exception.py", line 47, in inner
    response = get_response(request)
  File "/home/mrtbadboy/.local/lib/python3.9/site-packages/django/core/handlers/base.py", line 204, in _get_response
    response = response.render()
  File "/home/mrtbadboy/.local/lib/python3.9/site-packages/django/template/response.py", line 105, in render
    self.content = self.rendered_content
  File "/home/mrtbadboy/.local/lib/python3.9/site-packages/rest_framework/response.py", line 70, in rendered_content
    ret = renderer.render(self.data, accepted_media_type, context)
  File "/home/mrtbadboy/.local/lib/python3.9/site-packages/rest_framework/renderers.py", line 100, in render
    ret = json.dumps(
  File "/home/mrtbadboy/.local/lib/python3.9/site-packages/rest_framework/utils/json.py", line 25, in dumps
    return json.dumps(*args, **kwargs)
  File "/usr/lib/python3.9/json/__init__.py", line 234, in dumps
    return cls(
  File "/usr/lib/python3.9/json/encoder.py", line 199, in encode
    chunks = self.iterencode(o, _one_shot=True)
  File "/usr/lib/python3.9/json/encoder.py", line 257, in iterencode
    return _iterencode(o, 0)
  File "/home/mrtbadboy/.local/lib/python3.9/site-packages/rest_framework/utils/encoders.py", line 67, in default
    return super().default(obj)
  File "/usr/lib/python3.9/json/encoder.py", line 179, in default
    raise TypeError(f'Object of type {o.__class__.__name__} '
TypeError: Object of type FarzaneganProviderData is not JSON serializable
Internal Server Error: /api/v1/dslamport/farzanegan_provider_date/
Traceback (most recent call last):
  File "/home/mrtbadboy/.local/lib/python3.9/site-packages/django/core/handlers/exception.py", line 47, in inner
    response = get_response(request)
  File "/home/mrtbadboy/.local/lib/python3.9/site-packages/django/core/handlers/base.py", line 181, in _get_response
    response = wrapped_callback(request, *callback_args, **callback_kwargs)
  File "/home/mrtbadboy/.local/lib/python3.9/site-packages/django/views/decorators/csrf.py", line 54, in wrapped_view
    return view_func(*args, **kwargs)
  File "/home/mrtbadboy/.local/lib/python3.9/site-packages/django/views/generic/base.py", line 70, in view
    return self.dispatch(request, *args, **kwargs)
  File "/home/mrtbadboy/.local/lib/python3.9/site-packages/rest_framework/views.py", line 509, in dispatch
    response = self.handle_exception(exc)
  File "/home/mrtbadboy/.local/lib/python3.9/site-packages/rest_framework/views.py", line 469, in handle_exception
    self.raise_uncaught_exception(exc)
  File "/home/mrtbadboy/.local/lib/python3.9/site-packages/rest_framework/views.py", line 480, in raise_uncaught_exception
    raise exc
  File "/home/mrtbadboy/.local/lib/python3.9/site-packages/rest_framework/views.py", line 506, in dispatch
    response = handler(request, *args, **kwargs)
  File "/opt/portmanv3/portman_web/contact/views.py", line 476, in post
    farzanegan_provider_data = FarzaneganProviderData.objects.filter(provider=provider).order_by('-created').first().value()
AttributeError: 'FarzaneganProviderData' object has no attribute 'value'
Internal Server Error: /api/v1/dslamport/farzanegan_provider_date/
Traceback (most recent call last):
  File "/home/mrtbadboy/.local/lib/python3.9/site-packages/django/core/handlers/exception.py", line 47, in inner
    response = get_response(request)
  File "/home/mrtbadboy/.local/lib/python3.9/site-packages/django/core/handlers/base.py", line 181, in _get_response
    response = wrapped_callback(request, *callback_args, **callback_kwargs)
  File "/home/mrtbadboy/.local/lib/python3.9/site-packages/django/views/decorators/csrf.py", line 54, in wrapped_view
    return view_func(*args, **kwargs)
  File "/home/mrtbadboy/.local/lib/python3.9/site-packages/django/views/generic/base.py", line 70, in view
    return self.dispatch(request, *args, **kwargs)
  File "/home/mrtbadboy/.local/lib/python3.9/site-packages/rest_framework/views.py", line 509, in dispatch
    response = self.handle_exception(exc)
  File "/home/mrtbadboy/.local/lib/python3.9/site-packages/rest_framework/views.py", line 469, in handle_exception
    self.raise_uncaught_exception(exc)
  File "/home/mrtbadboy/.local/lib/python3.9/site-packages/rest_framework/views.py", line 480, in raise_uncaught_exception
    raise exc
  File "/home/mrtbadboy/.local/lib/python3.9/site-packages/rest_framework/views.py", line 506, in dispatch
    response = handler(request, *args, **kwargs)
  File "/opt/portmanv3/portman_web/contact/views.py", line 476, in post
    farzanegan_provider_data = FarzaneganProviderData.objects.filter(provider_id=provider).order_by('-created').first().value()
AttributeError: 'FarzaneganProviderData' object has no attribute 'value'
Internal Server Error: /api/v1/dslamport/farzanegan_provider_date/
Traceback (most recent call last):
  File "/home/mrtbadboy/.local/lib/python3.9/site-packages/django/core/handlers/exception.py", line 47, in inner
    response = get_response(request)
  File "/home/mrtbadboy/.local/lib/python3.9/site-packages/django/core/handlers/base.py", line 181, in _get_response
    response = wrapped_callback(request, *callback_args, **callback_kwargs)
  File "/home/mrtbadboy/.local/lib/python3.9/site-packages/django/views/decorators/csrf.py", line 54, in wrapped_view
    return view_func(*args, **kwargs)
  File "/home/mrtbadboy/.local/lib/python3.9/site-packages/django/views/generic/base.py", line 70, in view
    return self.dispatch(request, *args, **kwargs)
  File "/home/mrtbadboy/.local/lib/python3.9/site-packages/rest_framework/views.py", line 509, in dispatch
    response = self.handle_exception(exc)
  File "/home/mrtbadboy/.local/lib/python3.9/site-packages/rest_framework/views.py", line 469, in handle_exception
    self.raise_uncaught_exception(exc)
  File "/home/mrtbadboy/.local/lib/python3.9/site-packages/rest_framework/views.py", line 480, in raise_uncaught_exception
    raise exc
  File "/home/mrtbadboy/.local/lib/python3.9/site-packages/rest_framework/views.py", line 506, in dispatch
    response = handler(request, *args, **kwargs)
  File "/opt/portmanv3/portman_web/contact/views.py", line 476, in post
    farzanegan_provider_data = FarzaneganProviderData.objects.filter(provider_id=1).order_by('-created').first().value()
AttributeError: 'FarzaneganProviderData' object has no attribute 'value'
Internal Server Error: /api/v1/dslamport/farzanegan_provider_date/
Traceback (most recent call last):
  File "/home/mrtbadboy/.local/lib/python3.9/site-packages/django/core/handlers/exception.py", line 47, in inner
    response = get_response(request)
  File "/home/mrtbadboy/.local/lib/python3.9/site-packages/django/core/handlers/base.py", line 181, in _get_response
    response = wrapped_callback(request, *callback_args, **callback_kwargs)
  File "/home/mrtbadboy/.local/lib/python3.9/site-packages/django/views/decorators/csrf.py", line 54, in wrapped_view
    return view_func(*args, **kwargs)
  File "/home/mrtbadboy/.local/lib/python3.9/site-packages/django/views/generic/base.py", line 70, in view
    return self.dispatch(request, *args, **kwargs)
  File "/home/mrtbadboy/.local/lib/python3.9/site-packages/rest_framework/views.py", line 509, in dispatch
    response = self.handle_exception(exc)
  File "/home/mrtbadboy/.local/lib/python3.9/site-packages/rest_framework/views.py", line 469, in handle_exception
    self.raise_uncaught_exception(exc)
  File "/home/mrtbadboy/.local/lib/python3.9/site-packages/rest_framework/views.py", line 480, in raise_uncaught_exception
    raise exc
  File "/home/mrtbadboy/.local/lib/python3.9/site-packages/rest_framework/views.py", line 506, in dispatch
    response = handler(request, *args, **kwargs)
  File "/opt/portmanv3/portman_web/contact/views.py", line 476, in post
    farzanegan_provider_data = FarzaneganProviderData.objects.filter(provider_id=1).order_by('-created').value()
AttributeError: 'QuerySet' object has no attribute 'value'
Internal Server Error: /api/v1/dslamport/farzanegan_provider_date/
Traceback (most recent call last):
  File "/home/mrtbadboy/.local/lib/python3.9/site-packages/django/core/handlers/exception.py", line 47, in inner
    response = get_response(request)
  File "/home/mrtbadboy/.local/lib/python3.9/site-packages/django/core/handlers/base.py", line 204, in _get_response
    response = response.render()
  File "/home/mrtbadboy/.local/lib/python3.9/site-packages/django/template/response.py", line 105, in render
    self.content = self.rendered_content
  File "/home/mrtbadboy/.local/lib/python3.9/site-packages/rest_framework/response.py", line 70, in rendered_content
    ret = renderer.render(self.data, accepted_media_type, context)
  File "/home/mrtbadboy/.local/lib/python3.9/site-packages/rest_framework/renderers.py", line 100, in render
    ret = json.dumps(
  File "/home/mrtbadboy/.local/lib/python3.9/site-packages/rest_framework/utils/json.py", line 25, in dumps
    return json.dumps(*args, **kwargs)
  File "/usr/lib/python3.9/json/__init__.py", line 234, in dumps
    return cls(
  File "/usr/lib/python3.9/json/encoder.py", line 199, in encode
    chunks = self.iterencode(o, _one_shot=True)
  File "/usr/lib/python3.9/json/encoder.py", line 257, in iterencode
    return _iterencode(o, 0)
  File "/home/mrtbadboy/.local/lib/python3.9/site-packages/rest_framework/utils/encoders.py", line 67, in default
    return super().default(obj)
  File "/usr/lib/python3.9/json/encoder.py", line 179, in default
    raise TypeError(f'Object of type {o.__class__.__name__} '
TypeError: Object of type FarzaneganProviderData is not JSON serializable
Internal Server Error: /api/v1/dslamport/farzanegan_provider_date/
Traceback (most recent call last):
  File "/home/mrtbadboy/.local/lib/python3.9/site-packages/django/core/handlers/exception.py", line 47, in inner
    response = get_response(request)
  File "/home/mrtbadboy/.local/lib/python3.9/site-packages/django/core/handlers/base.py", line 181, in _get_response
    response = wrapped_callback(request, *callback_args, **callback_kwargs)
  File "/home/mrtbadboy/.local/lib/python3.9/site-packages/django/views/decorators/csrf.py", line 54, in wrapped_view
    return view_func(*args, **kwargs)
  File "/home/mrtbadboy/.local/lib/python3.9/site-packages/django/views/generic/base.py", line 70, in view
    return self.dispatch(request, *args, **kwargs)
  File "/home/mrtbadboy/.local/lib/python3.9/site-packages/rest_framework/views.py", line 509, in dispatch
    response = self.handle_exception(exc)
  File "/home/mrtbadboy/.local/lib/python3.9/site-packages/rest_framework/views.py", line 469, in handle_exception
    self.raise_uncaught_exception(exc)
  File "/home/mrtbadboy/.local/lib/python3.9/site-packages/rest_framework/views.py", line 480, in raise_uncaught_exception
    raise exc
  File "/home/mrtbadboy/.local/lib/python3.9/site-packages/rest_framework/views.py", line 506, in dispatch
    response = handler(request, *args, **kwargs)
  File "/opt/portmanv3/portman_web/contact/views.py", line 476, in post
    farzanegan_provider_data = FarzaneganProviderData.objects.filter(provider_id=1).value()
AttributeError: 'QuerySet' object has no attribute 'value'
Internal Server Error: /api/v1/dslamport/farzanegan_provider_date/
Traceback (most recent call last):
  File "/home/mrtbadboy/.local/lib/python3.9/site-packages/django/core/handlers/exception.py", line 47, in inner
    response = get_response(request)
  File "/home/mrtbadboy/.local/lib/python3.9/site-packages/django/core/handlers/base.py", line 204, in _get_response
    response = response.render()
  File "/home/mrtbadboy/.local/lib/python3.9/site-packages/django/template/response.py", line 105, in render
    self.content = self.rendered_content
  File "/home/mrtbadboy/.local/lib/python3.9/site-packages/rest_framework/response.py", line 70, in rendered_content
    ret = renderer.render(self.data, accepted_media_type, context)
  File "/home/mrtbadboy/.local/lib/python3.9/site-packages/rest_framework/renderers.py", line 100, in render
    ret = json.dumps(
  File "/home/mrtbadboy/.local/lib/python3.9/site-packages/rest_framework/utils/json.py", line 25, in dumps
    return json.dumps(*args, **kwargs)
  File "/usr/lib/python3.9/json/__init__.py", line 234, in dumps
    return cls(
  File "/usr/lib/python3.9/json/encoder.py", line 199, in encode
    chunks = self.iterencode(o, _one_shot=True)
  File "/usr/lib/python3.9/json/encoder.py", line 257, in iterencode
    return _iterencode(o, 0)
  File "/home/mrtbadboy/.local/lib/python3.9/site-packages/rest_framework/utils/encoders.py", line 67, in default
    return super().default(obj)
  File "/usr/lib/python3.9/json/encoder.py", line 179, in default
    raise TypeError(f'Object of type {o.__class__.__name__} '
TypeError: Object of type FarzaneganProviderData is not JSON serializable
Not Found: /api/v1/dslamport/farzanegan_provider_date
Unauthorized: /api/v1/partak/get_partak_provinces/
