Unauthorized: /api/v1/users/login/
Unauthorized: /api/v1/users/login/
Unauthorized: /api/v1/users/login/
Unauthorized: /api/v1/users/login/
Unauthorized: /api/v1/users/login/
Not Found: /favicon.ico
Unauthorized: /api/v1/dslam-port/385347/report/
Unauthorized: /api/v1/port-command/
Unauthorized: /api/v1/command/
Unauthorized: /api/v1/dslam-port/385347/
Unauthorized: /api/v1/users/login/
Unauthorized: /api/v1/users/login/
Not Found: /api/v1/users/login/
Unauthorized: /api/v1/users/get_permission/
Internal Server Error: /api/v1/router/
Traceback (most recent call last):
  File "/usr/local/lib/python3.8/dist-packages/django/core/handlers/exception.py", line 47, in inner
    response = get_response(request)
  File "/usr/local/lib/python3.8/dist-packages/django/core/handlers/base.py", line 179, in _get_response
    response = wrapped_callback(request, *callback_args, **callback_kwargs)
  File "/usr/local/lib/python3.8/dist-packages/django/views/decorators/csrf.py", line 54, in wrapped_view
    return view_func(*args, **kwargs)
  File "/usr/local/lib/python3.8/dist-packages/rest_framework/viewsets.py", line 125, in view
    return self.dispatch(request, *args, **kwargs)
  File "/usr/local/lib/python3.8/dist-packages/rest_framework/views.py", line 509, in dispatch
    response = self.handle_exception(exc)
  File "/usr/local/lib/python3.8/dist-packages/rest_framework/views.py", line 469, in handle_exception
    self.raise_uncaught_exception(exc)
  File "/usr/local/lib/python3.8/dist-packages/rest_framework/views.py", line 480, in raise_uncaught_exception
    raise exc
  File "/usr/local/lib/python3.8/dist-packages/rest_framework/views.py", line 506, in dispatch
    response = handler(request, *args, **kwargs)
  File "/usr/local/lib/python3.8/dist-packages/rest_framework/mixins.py", line 42, in list
    serializer = self.get_serializer(page, many=True)
  File "/opt/portmanv3/portman_web/router/views.py", line 66, in get_serializer
    return RouterSerializer(request=self.request, *args, **kwargs)
  File "/usr/local/lib/python3.8/dist-packages/rest_framework/serializers.py", line 121, in __new__
    return cls.many_init(*args, **kwargs)
  File "/usr/local/lib/python3.8/dist-packages/rest_framework/serializers.py", line 146, in many_init
    child_serializer = cls(*args, **kwargs)
  File "/usr/local/lib/python3.8/dist-packages/rest_framework/serializers.py", line 115, in __init__
    super().__init__(**kwargs)
TypeError: __init__() got an unexpected keyword argument 'request'
Internal Server Error: /api/v1/router/
Traceback (most recent call last):
  File "/usr/local/lib/python3.8/dist-packages/django/core/handlers/exception.py", line 47, in inner
    response = get_response(request)
  File "/usr/local/lib/python3.8/dist-packages/django/core/handlers/base.py", line 179, in _get_response
    response = wrapped_callback(request, *callback_args, **callback_kwargs)
  File "/usr/local/lib/python3.8/dist-packages/django/views/decorators/csrf.py", line 54, in wrapped_view
    return view_func(*args, **kwargs)
  File "/usr/local/lib/python3.8/dist-packages/rest_framework/viewsets.py", line 125, in view
    return self.dispatch(request, *args, **kwargs)
  File "/usr/local/lib/python3.8/dist-packages/rest_framework/views.py", line 509, in dispatch
    response = self.handle_exception(exc)
  File "/usr/local/lib/python3.8/dist-packages/rest_framework/views.py", line 469, in handle_exception
    self.raise_uncaught_exception(exc)
  File "/usr/local/lib/python3.8/dist-packages/rest_framework/views.py", line 480, in raise_uncaught_exception
    raise exc
  File "/usr/local/lib/python3.8/dist-packages/rest_framework/views.py", line 506, in dispatch
    response = handler(request, *args, **kwargs)
  File "/usr/local/lib/python3.8/dist-packages/rest_framework/mixins.py", line 42, in list
    serializer = self.get_serializer(page, many=True)
  File "/opt/portmanv3/portman_web/router/views.py", line 66, in get_serializer
    return RouterSerializer(request=self.request, *args, **kwargs)
  File "/usr/local/lib/python3.8/dist-packages/rest_framework/serializers.py", line 121, in __new__
    return cls.many_init(*args, **kwargs)
  File "/usr/local/lib/python3.8/dist-packages/rest_framework/serializers.py", line 146, in many_init
    child_serializer = cls(*args, **kwargs)
  File "/usr/local/lib/python3.8/dist-packages/rest_framework/serializers.py", line 115, in __init__
    super().__init__(**kwargs)
TypeError: __init__() got an unexpected keyword argument 'request'
Internal Server Error: /api/v1/router/
Traceback (most recent call last):
  File "/usr/local/lib/python3.8/dist-packages/django/core/handlers/exception.py", line 47, in inner
    response = get_response(request)
  File "/usr/local/lib/python3.8/dist-packages/django/core/handlers/base.py", line 179, in _get_response
    response = wrapped_callback(request, *callback_args, **callback_kwargs)
  File "/usr/local/lib/python3.8/dist-packages/django/views/decorators/csrf.py", line 54, in wrapped_view
    return view_func(*args, **kwargs)
  File "/usr/local/lib/python3.8/dist-packages/rest_framework/viewsets.py", line 125, in view
    return self.dispatch(request, *args, **kwargs)
  File "/usr/local/lib/python3.8/dist-packages/rest_framework/views.py", line 509, in dispatch
    response = self.handle_exception(exc)
  File "/usr/local/lib/python3.8/dist-packages/rest_framework/views.py", line 469, in handle_exception
    self.raise_uncaught_exception(exc)
  File "/usr/local/lib/python3.8/dist-packages/rest_framework/views.py", line 480, in raise_uncaught_exception
    raise exc
  File "/usr/local/lib/python3.8/dist-packages/rest_framework/views.py", line 506, in dispatch
    response = handler(request, *args, **kwargs)
  File "/usr/local/lib/python3.8/dist-packages/rest_framework/mixins.py", line 42, in list
    serializer = self.get_serializer(page, many=True)
  File "/opt/portmanv3/portman_web/router/views.py", line 66, in get_serializer
    return RouterSerializer(request=self.request, *args, **kwargs)
  File "/usr/local/lib/python3.8/dist-packages/rest_framework/serializers.py", line 121, in __new__
    return cls.many_init(*args, **kwargs)
  File "/usr/local/lib/python3.8/dist-packages/rest_framework/serializers.py", line 146, in many_init
    child_serializer = cls(*args, **kwargs)
  File "/usr/local/lib/python3.8/dist-packages/rest_framework/serializers.py", line 115, in __init__
    super().__init__(**kwargs)
TypeError: __init__() got an unexpected keyword argument 'request'
Internal Server Error: /api/v1/router/
Traceback (most recent call last):
  File "/usr/local/lib/python3.8/dist-packages/django/core/handlers/exception.py", line 47, in inner
    response = get_response(request)
  File "/usr/local/lib/python3.8/dist-packages/django/core/handlers/base.py", line 179, in _get_response
    response = wrapped_callback(request, *callback_args, **callback_kwargs)
  File "/usr/local/lib/python3.8/dist-packages/django/views/decorators/csrf.py", line 54, in wrapped_view
    return view_func(*args, **kwargs)
  File "/usr/local/lib/python3.8/dist-packages/rest_framework/viewsets.py", line 104, in view
    self = cls(**initkwargs)
  File "/opt/portmanv3/portman_web/router/views.py", line 68, in __init__
    super(DSLAMSerializer, self).__init__(*args, **kwargs)
NameError: name 'DSLAMSerializer' is not defined
Internal Server Error: /api/v1/router/
Traceback (most recent call last):
  File "/usr/local/lib/python3.8/dist-packages/django/core/handlers/exception.py", line 47, in inner
    response = get_response(request)
  File "/usr/local/lib/python3.8/dist-packages/django/core/handlers/base.py", line 179, in _get_response
    response = wrapped_callback(request, *callback_args, **callback_kwargs)
  File "/usr/local/lib/python3.8/dist-packages/django/views/decorators/csrf.py", line 54, in wrapped_view
    return view_func(*args, **kwargs)
  File "/usr/local/lib/python3.8/dist-packages/rest_framework/viewsets.py", line 104, in view
    self = cls(**initkwargs)
  File "/opt/portmanv3/portman_web/router/views.py", line 68, in __init__
    super(RouterSerializer, self).__init__(*args, **kwargs)
TypeError: super(type, obj): obj must be an instance or subtype of type
Internal Server Error: /api/v1/router/
Traceback (most recent call last):
  File "/usr/local/lib/python3.8/dist-packages/django/core/handlers/exception.py", line 47, in inner
    response = get_response(request)
  File "/usr/local/lib/python3.8/dist-packages/django/core/handlers/base.py", line 179, in _get_response
    response = wrapped_callback(request, *callback_args, **callback_kwargs)
  File "/usr/local/lib/python3.8/dist-packages/django/views/decorators/csrf.py", line 54, in wrapped_view
    return view_func(*args, **kwargs)
  File "/usr/local/lib/python3.8/dist-packages/rest_framework/viewsets.py", line 104, in view
    self = cls(**initkwargs)
  File "/opt/portmanv3/portman_web/router/views.py", line 68, in __init__
    super(RouterSerializer, self).__init__(*args, **kwargs)
TypeError: super(type, obj): obj must be an instance or subtype of type
Internal Server Error: /api/v1/router/
Traceback (most recent call last):
  File "/usr/local/lib/python3.8/dist-packages/django/core/handlers/exception.py", line 47, in inner
    response = get_response(request)
  File "/usr/local/lib/python3.8/dist-packages/django/core/handlers/base.py", line 179, in _get_response
    response = wrapped_callback(request, *callback_args, **callback_kwargs)
  File "/usr/local/lib/python3.8/dist-packages/django/views/decorators/csrf.py", line 54, in wrapped_view
    return view_func(*args, **kwargs)
  File "/usr/local/lib/python3.8/dist-packages/rest_framework/viewsets.py", line 104, in view
    self = cls(**initkwargs)
  File "/opt/portmanv3/portman_web/router/views.py", line 68, in __init__
    super(RouterSerializer, self).__init__(*args, **kwargs)
TypeError: super(type, obj): obj must be an instance or subtype of type
Internal Server Error: /api/v1/router/
Traceback (most recent call last):
  File "/usr/local/lib/python3.8/dist-packages/django/core/handlers/exception.py", line 47, in inner
    response = get_response(request)
  File "/usr/local/lib/python3.8/dist-packages/django/core/handlers/base.py", line 179, in _get_response
    response = wrapped_callback(request, *callback_args, **callback_kwargs)
  File "/usr/local/lib/python3.8/dist-packages/django/views/decorators/csrf.py", line 54, in wrapped_view
    return view_func(*args, **kwargs)
  File "/usr/local/lib/python3.8/dist-packages/rest_framework/viewsets.py", line 104, in view
    self = cls(**initkwargs)
  File "/opt/portmanv3/portman_web/router/views.py", line 68, in __init__
    super(RouterSerializer, self).__init__(*args, **kwargs)
TypeError: super(type, obj): obj must be an instance or subtype of type
Internal Server Error: /api/v1/router/
Traceback (most recent call last):
  File "/usr/local/lib/python3.8/dist-packages/django/core/handlers/exception.py", line 47, in inner
    response = get_response(request)
  File "/usr/local/lib/python3.8/dist-packages/django/core/handlers/base.py", line 179, in _get_response
    response = wrapped_callback(request, *callback_args, **callback_kwargs)
  File "/usr/local/lib/python3.8/dist-packages/django/views/decorators/csrf.py", line 54, in wrapped_view
    return view_func(*args, **kwargs)
  File "/usr/local/lib/python3.8/dist-packages/rest_framework/viewsets.py", line 104, in view
    self = cls(**initkwargs)
  File "/opt/portmanv3/portman_web/router/views.py", line 68, in __init__
    super(RouterSerializer, self).__init__(*args, **kwargs)
TypeError: super(type, obj): obj must be an instance or subtype of type
Unauthorized: /api/v1/users/get_permission/
Bad Request: /api/v1/switch/connect_handler_test/
Bad Request: /api/v1/switch/connect_handler_test/
Unauthorized: /api/v1/switch/connect_handler_test/
Unauthorized: /api/v1/switch/connect_handler_test/
Unauthorized: /api/v1/switch/connect_handler_test/
Not Found: /api/v1/switch/connect_handler_test/
Not Found: /
Not Found: /api/v1/switch/connect_handler_test/
Not Found: /api/v1/switch/connect_handler_test/
Not Found: /api/v1/switch/connect_handler_test/
Not Found: /api/v1/switch/connect_handler_test/
Method Not Allowed: /api/v1/switch/connect_handler_test/
Not Found: /api/v1/switch/connect_handler_test/
Not Found: /api/v1/switch/connect_handler_test/
Not Found: /api/v1/switch/connect_handler_test/
Not Found: /api/v1/switch/connect_handler_test/
Not Found: /api/v1/switch/connect_handler_test/
Method Not Allowed: /api/v1/dslamport/get_hosts_from_zabbix/
Internal Server Error: /api/v1/dslamport/get_hosts_from_zabbix/
Traceback (most recent call last):
  File "/usr/lib/python3/dist-packages/requests/models.py", line 379, in prepare_url
    scheme, auth, host, port, path, query, fragment = parse_url(url)
  File "/usr/lib/python3/dist-packages/urllib3/util/url.py", line 392, in parse_url
    return six.raise_from(LocationParseError(source_url), None)
  File "<string>", line 2, in raise_from
urllib3.exceptions.LocationParseError: Failed to parse: https://zabbix.pishgaman.net/api_jsonrpc.php

During handling of the above exception, another exception occurred:

Traceback (most recent call last):
  File "/opt/portmanv3/portman_web/dslam/views.py", line 7047, in post
    response = requests.post(zabbix_url, data=zabbix_login_data, headers={"Content-Type": "application/json"})
  File "/usr/lib/python3/dist-packages/requests/api.py", line 116, in post
    return request('post', url, data=data, json=json, **kwargs)
  File "/usr/lib/python3/dist-packages/requests/api.py", line 60, in request
    return session.request(method=method, url=url, **kwargs)
  File "/usr/lib/python3/dist-packages/requests/sessions.py", line 519, in request
    prep = self.prepare_request(req)
  File "/usr/lib/python3/dist-packages/requests/sessions.py", line 452, in prepare_request
    p.prepare(
  File "/usr/lib/python3/dist-packages/requests/models.py", line 313, in prepare
    self.prepare_url(url, params)
  File "/usr/lib/python3/dist-packages/requests/models.py", line 381, in prepare_url
    raise InvalidURL(*e.args)
requests.exceptions.InvalidURL: Failed to parse: https://zabbix.pishgaman.net/api_jsonrpc.php

During handling of the above exception, another exception occurred:

Traceback (most recent call last):
  File "/home/mrtbadboy/.local/lib/python3.8/site-packages/django/core/handlers/exception.py", line 47, in inner
    response = get_response(request)
  File "/home/mrtbadboy/.local/lib/python3.8/site-packages/django/core/handlers/base.py", line 179, in _get_response
    response = wrapped_callback(request, *callback_args, **callback_kwargs)
  File "/home/mrtbadboy/.local/lib/python3.8/site-packages/django/views/decorators/csrf.py", line 54, in wrapped_view
    return view_func(*args, **kwargs)
  File "/home/mrtbadboy/.local/lib/python3.8/site-packages/django/views/generic/base.py", line 70, in view
    return self.dispatch(request, *args, **kwargs)
  File "/home/mrtbadboy/.local/lib/python3.8/site-packages/rest_framework/views.py", line 509, in dispatch
    response = self.handle_exception(exc)
  File "/home/mrtbadboy/.local/lib/python3.8/site-packages/rest_framework/views.py", line 469, in handle_exception
    self.raise_uncaught_exception(exc)
  File "/home/mrtbadboy/.local/lib/python3.8/site-packages/rest_framework/views.py", line 480, in raise_uncaught_exception
    raise exc
  File "/home/mrtbadboy/.local/lib/python3.8/site-packages/rest_framework/views.py", line 506, in dispatch
    response = handler(request, *args, **kwargs)
  File "/opt/portmanv3/portman_web/dslam/views.py", line 7098, in post
    return Response({'message': str(ex) + "  " + str(host)}, status=status.HTTP_500_INTERNAL_SERVER_ERROR)
UnboundLocalError: local variable 'host' referenced before assignment
Not Found: /api/v1/switch/connect_handler_test/
Not Found: /api/v1/router/router-runCommand/
Not Found: /api/v1/switch/connect_handler_test/
Not Found: /api/v1/switch/connect_handler_test/
Not Found: /api/v1/switch/connect_handler_test/
Not Found: /api/v1/switch/connect_handler_test/
Not Found: /api/v1/switch/connect_handler_test/
Not Found: /api/v1/switch/connect_handler_test/
Not Found: /api/v1/switch/connect_handler_test/
Method Not Allowed: /api/v1/routerCommands/routerRunCommand/
Method Not Allowed: /api/v1/switch/connect_handler_test/
Internal Server Error: /api/v1/portmap/
Traceback (most recent call last):
  File "/home/mrtbadboy/.local/lib/python3.8/site-packages/django/core/handlers/exception.py", line 47, in inner
    response = get_response(request)
  File "/home/mrtbadboy/.local/lib/python3.8/site-packages/django/core/handlers/base.py", line 179, in _get_response
    response = wrapped_callback(request, *callback_args, **callback_kwargs)
  File "/home/mrtbadboy/.local/lib/python3.8/site-packages/django/views/decorators/csrf.py", line 54, in wrapped_view
    return view_func(*args, **kwargs)
  File "/home/mrtbadboy/.local/lib/python3.8/site-packages/rest_framework/viewsets.py", line 125, in view
    return self.dispatch(request, *args, **kwargs)
  File "/home/mrtbadboy/.local/lib/python3.8/site-packages/rest_framework/views.py", line 509, in dispatch
    response = self.handle_exception(exc)
  File "/home/mrtbadboy/.local/lib/python3.8/site-packages/rest_framework/views.py", line 469, in handle_exception
    self.raise_uncaught_exception(exc)
  File "/home/mrtbadboy/.local/lib/python3.8/site-packages/rest_framework/views.py", line 480, in raise_uncaught_exception
    raise exc
  File "/home/mrtbadboy/.local/lib/python3.8/site-packages/rest_framework/views.py", line 506, in dispatch
    response = handler(request, *args, **kwargs)
  File "/home/mrtbadboy/.local/lib/python3.8/site-packages/rest_framework/mixins.py", line 38, in list
    queryset = self.filter_queryset(self.get_queryset())
  File "/opt/portmanv3/portman_web/contact/views.py", line 76, in get_queryset
    queryset = queryset.filter(status=status)
  File "/home/mrtbadboy/.local/lib/python3.8/site-packages/django/db/models/query.py", line 942, in filter
    return self._filter_or_exclude(False, *args, **kwargs)
  File "/home/mrtbadboy/.local/lib/python3.8/site-packages/django/db/models/query.py", line 962, in _filter_or_exclude
    clone._filter_or_exclude_inplace(negate, *args, **kwargs)
  File "/home/mrtbadboy/.local/lib/python3.8/site-packages/django/db/models/query.py", line 969, in _filter_or_exclude_inplace
    self._query.add_q(Q(*args, **kwargs))
  File "/home/mrtbadboy/.local/lib/python3.8/site-packages/django/db/models/sql/query.py", line 1358, in add_q
    clause, _ = self._add_q(q_object, self.used_aliases)
  File "/home/mrtbadboy/.local/lib/python3.8/site-packages/django/db/models/sql/query.py", line 1377, in _add_q
    child_clause, needed_inner = self.build_filter(
  File "/home/mrtbadboy/.local/lib/python3.8/site-packages/django/db/models/sql/query.py", line 1258, in build_filter
    lookups, parts, reffed_expression = self.solve_lookup_type(arg)
  File "/home/mrtbadboy/.local/lib/python3.8/site-packages/django/db/models/sql/query.py", line 1084, in solve_lookup_type
    _, field, _, lookup_parts = self.names_to_path(lookup_splitted, self.get_meta())
  File "/home/mrtbadboy/.local/lib/python3.8/site-packages/django/db/models/sql/query.py", line 1481, in names_to_path
    raise FieldError("Cannot resolve keyword '%s' into field. "
django.core.exceptions.FieldError: Cannot resolve keyword 'status' into field. Choices are: fqdn, id, order_contact_id, port_number, ranjePhoneNumber, rastin_order_id, slot_number, telco_Column, telco_connection, telco_row, username
Internal Server Error: /api/v1/portmap/
Traceback (most recent call last):
  File "/home/mrtbadboy/.local/lib/python3.8/site-packages/django/core/handlers/exception.py", line 47, in inner
    response = get_response(request)
  File "/home/mrtbadboy/.local/lib/python3.8/site-packages/django/core/handlers/base.py", line 179, in _get_response
    response = wrapped_callback(request, *callback_args, **callback_kwargs)
  File "/home/mrtbadboy/.local/lib/python3.8/site-packages/django/views/decorators/csrf.py", line 54, in wrapped_view
    return view_func(*args, **kwargs)
  File "/home/mrtbadboy/.local/lib/python3.8/site-packages/rest_framework/viewsets.py", line 125, in view
    return self.dispatch(request, *args, **kwargs)
  File "/home/mrtbadboy/.local/lib/python3.8/site-packages/rest_framework/views.py", line 509, in dispatch
    response = self.handle_exception(exc)
  File "/home/mrtbadboy/.local/lib/python3.8/site-packages/rest_framework/views.py", line 469, in handle_exception
    self.raise_uncaught_exception(exc)
  File "/home/mrtbadboy/.local/lib/python3.8/site-packages/rest_framework/views.py", line 480, in raise_uncaught_exception
    raise exc
  File "/home/mrtbadboy/.local/lib/python3.8/site-packages/rest_framework/views.py", line 506, in dispatch
    response = handler(request, *args, **kwargs)
  File "/home/mrtbadboy/.local/lib/python3.8/site-packages/rest_framework/mixins.py", line 38, in list
    queryset = self.filter_queryset(self.get_queryset())
  File "/opt/portmanv3/portman_web/contact/views.py", line 90, in get_queryset
    queryset = queryset.order_by(sort_field)
  File "/home/mrtbadboy/.local/lib/python3.8/site-packages/django/db/models/query.py", line 1134, in order_by
    obj.query.add_ordering(*field_names)
  File "/home/mrtbadboy/.local/lib/python3.8/site-packages/django/db/models/sql/query.py", line 1928, in add_ordering
    raise FieldError('Invalid order_by arguments: %s' % errors)
django.core.exceptions.FieldError: Invalid order_by arguments: [None]
Internal Server Error: /api/v1/portmap/
Traceback (most recent call last):
  File "/home/mrtbadboy/.local/lib/python3.8/site-packages/django/db/backends/utils.py", line 84, in _execute
    return self.cursor.execute(sql, params)
psycopg2.errors.UndefinedColumn: column contact_order.telco_Column does not exist
LINE 1: ...rder"."port_number", "contact_order"."telco_row", "contact_o...
                                                             ^


The above exception was the direct cause of the following exception:

Traceback (most recent call last):
  File "/home/mrtbadboy/.local/lib/python3.8/site-packages/django/core/handlers/exception.py", line 47, in inner
    response = get_response(request)
  File "/home/mrtbadboy/.local/lib/python3.8/site-packages/django/core/handlers/base.py", line 179, in _get_response
    response = wrapped_callback(request, *callback_args, **callback_kwargs)
  File "/home/mrtbadboy/.local/lib/python3.8/site-packages/django/views/decorators/csrf.py", line 54, in wrapped_view
    return view_func(*args, **kwargs)
  File "/home/mrtbadboy/.local/lib/python3.8/site-packages/rest_framework/viewsets.py", line 125, in view
    return self.dispatch(request, *args, **kwargs)
  File "/home/mrtbadboy/.local/lib/python3.8/site-packages/rest_framework/views.py", line 509, in dispatch
    response = self.handle_exception(exc)
  File "/home/mrtbadboy/.local/lib/python3.8/site-packages/rest_framework/views.py", line 469, in handle_exception
    self.raise_uncaught_exception(exc)
  File "/home/mrtbadboy/.local/lib/python3.8/site-packages/rest_framework/views.py", line 480, in raise_uncaught_exception
    raise exc
  File "/home/mrtbadboy/.local/lib/python3.8/site-packages/rest_framework/views.py", line 506, in dispatch
    response = handler(request, *args, **kwargs)
  File "/home/mrtbadboy/.local/lib/python3.8/site-packages/rest_framework/mixins.py", line 40, in list
    page = self.paginate_queryset(queryset)
  File "/home/mrtbadboy/.local/lib/python3.8/site-packages/rest_framework/generics.py", line 171, in paginate_queryset
    return self.paginator.paginate_queryset(queryset, self.request, view=self)
  File "/home/mrtbadboy/.local/lib/python3.8/site-packages/rest_framework/pagination.py", line 219, in paginate_queryset
    return list(self.page)
  File "/home/mrtbadboy/.local/lib/python3.8/site-packages/django/core/paginator.py", line 143, in __len__
    return len(self.object_list)
  File "/home/mrtbadboy/.local/lib/python3.8/site-packages/django/db/models/query.py", line 269, in __len__
    self._fetch_all()
  File "/home/mrtbadboy/.local/lib/python3.8/site-packages/django/db/models/query.py", line 1308, in _fetch_all
    self._result_cache = list(self._iterable_class(self))
  File "/home/mrtbadboy/.local/lib/python3.8/site-packages/django/db/models/query.py", line 53, in __iter__
    results = compiler.execute_sql(chunked_fetch=self.chunked_fetch, chunk_size=self.chunk_size)
  File "/home/mrtbadboy/.local/lib/python3.8/site-packages/django/db/models/sql/compiler.py", line 1156, in execute_sql
    cursor.execute(sql, params)
  File "/home/mrtbadboy/.local/lib/python3.8/site-packages/django/db/backends/utils.py", line 98, in execute
    return super().execute(sql, params)
  File "/home/mrtbadboy/.local/lib/python3.8/site-packages/django/db/backends/utils.py", line 66, in execute
    return self._execute_with_wrappers(sql, params, many=False, executor=self._execute)
  File "/home/mrtbadboy/.local/lib/python3.8/site-packages/django/db/backends/utils.py", line 75, in _execute_with_wrappers
    return executor(sql, params, many, context)
  File "/home/mrtbadboy/.local/lib/python3.8/site-packages/django/db/backends/utils.py", line 84, in _execute
    return self.cursor.execute(sql, params)
  File "/home/mrtbadboy/.local/lib/python3.8/site-packages/django/db/utils.py", line 90, in __exit__
    raise dj_exc_value.with_traceback(traceback) from exc_value
  File "/home/mrtbadboy/.local/lib/python3.8/site-packages/django/db/backends/utils.py", line 84, in _execute
    return self.cursor.execute(sql, params)
django.db.utils.ProgrammingError: column contact_order.telco_Column does not exist
LINE 1: ...rder"."port_number", "contact_order"."telco_row", "contact_o...
                                                             ^

Internal Server Error: /api/v1/portmap/
Traceback (most recent call last):
  File "/home/mrtbadboy/.local/lib/python3.8/site-packages/django/db/backends/utils.py", line 84, in _execute
    return self.cursor.execute(sql, params)
psycopg2.errors.UndefinedColumn: column contact_order.telco_column does not exist
LINE 1: ...rder"."port_number", "contact_order"."telco_row", "contact_o...
                                                             ^


The above exception was the direct cause of the following exception:

Traceback (most recent call last):
  File "/home/mrtbadboy/.local/lib/python3.8/site-packages/django/core/handlers/exception.py", line 47, in inner
    response = get_response(request)
  File "/home/mrtbadboy/.local/lib/python3.8/site-packages/django/core/handlers/base.py", line 179, in _get_response
    response = wrapped_callback(request, *callback_args, **callback_kwargs)
  File "/home/mrtbadboy/.local/lib/python3.8/site-packages/django/views/decorators/csrf.py", line 54, in wrapped_view
    return view_func(*args, **kwargs)
  File "/home/mrtbadboy/.local/lib/python3.8/site-packages/rest_framework/viewsets.py", line 125, in view
    return self.dispatch(request, *args, **kwargs)
  File "/home/mrtbadboy/.local/lib/python3.8/site-packages/rest_framework/views.py", line 509, in dispatch
    response = self.handle_exception(exc)
  File "/home/mrtbadboy/.local/lib/python3.8/site-packages/rest_framework/views.py", line 469, in handle_exception
    self.raise_uncaught_exception(exc)
  File "/home/mrtbadboy/.local/lib/python3.8/site-packages/rest_framework/views.py", line 480, in raise_uncaught_exception
    raise exc
  File "/home/mrtbadboy/.local/lib/python3.8/site-packages/rest_framework/views.py", line 506, in dispatch
    response = handler(request, *args, **kwargs)
  File "/home/mrtbadboy/.local/lib/python3.8/site-packages/rest_framework/mixins.py", line 40, in list
    page = self.paginate_queryset(queryset)
  File "/home/mrtbadboy/.local/lib/python3.8/site-packages/rest_framework/generics.py", line 171, in paginate_queryset
    return self.paginator.paginate_queryset(queryset, self.request, view=self)
  File "/home/mrtbadboy/.local/lib/python3.8/site-packages/rest_framework/pagination.py", line 219, in paginate_queryset
    return list(self.page)
  File "/home/mrtbadboy/.local/lib/python3.8/site-packages/django/core/paginator.py", line 143, in __len__
    return len(self.object_list)
  File "/home/mrtbadboy/.local/lib/python3.8/site-packages/django/db/models/query.py", line 269, in __len__
    self._fetch_all()
  File "/home/mrtbadboy/.local/lib/python3.8/site-packages/django/db/models/query.py", line 1308, in _fetch_all
    self._result_cache = list(self._iterable_class(self))
  File "/home/mrtbadboy/.local/lib/python3.8/site-packages/django/db/models/query.py", line 53, in __iter__
    results = compiler.execute_sql(chunked_fetch=self.chunked_fetch, chunk_size=self.chunk_size)
  File "/home/mrtbadboy/.local/lib/python3.8/site-packages/django/db/models/sql/compiler.py", line 1156, in execute_sql
    cursor.execute(sql, params)
  File "/home/mrtbadboy/.local/lib/python3.8/site-packages/django/db/backends/utils.py", line 98, in execute
    return super().execute(sql, params)
  File "/home/mrtbadboy/.local/lib/python3.8/site-packages/django/db/backends/utils.py", line 66, in execute
    return self._execute_with_wrappers(sql, params, many=False, executor=self._execute)
  File "/home/mrtbadboy/.local/lib/python3.8/site-packages/django/db/backends/utils.py", line 75, in _execute_with_wrappers
    return executor(sql, params, many, context)
  File "/home/mrtbadboy/.local/lib/python3.8/site-packages/django/db/backends/utils.py", line 84, in _execute
    return self.cursor.execute(sql, params)
  File "/home/mrtbadboy/.local/lib/python3.8/site-packages/django/db/utils.py", line 90, in __exit__
    raise dj_exc_value.with_traceback(traceback) from exc_value
  File "/home/mrtbadboy/.local/lib/python3.8/site-packages/django/db/backends/utils.py", line 84, in _execute
    return self.cursor.execute(sql, params)
django.db.utils.ProgrammingError: column contact_order.telco_column does not exist
LINE 1: ...rder"."port_number", "contact_order"."telco_row", "contact_o...
                                                             ^

Internal Server Error: /api/v1/portmap/
Traceback (most recent call last):
  File "/home/mrtbadboy/.local/lib/python3.8/site-packages/django/core/handlers/exception.py", line 47, in inner
    response = get_response(request)
  File "/home/mrtbadboy/.local/lib/python3.8/site-packages/django/core/handlers/base.py", line 179, in _get_response
    response = wrapped_callback(request, *callback_args, **callback_kwargs)
  File "/home/mrtbadboy/.local/lib/python3.8/site-packages/django/views/decorators/csrf.py", line 54, in wrapped_view
    return view_func(*args, **kwargs)
  File "/home/mrtbadboy/.local/lib/python3.8/site-packages/rest_framework/viewsets.py", line 125, in view
    return self.dispatch(request, *args, **kwargs)
  File "/home/mrtbadboy/.local/lib/python3.8/site-packages/rest_framework/views.py", line 509, in dispatch
    response = self.handle_exception(exc)
  File "/home/mrtbadboy/.local/lib/python3.8/site-packages/rest_framework/views.py", line 469, in handle_exception
    self.raise_uncaught_exception(exc)
  File "/home/mrtbadboy/.local/lib/python3.8/site-packages/rest_framework/views.py", line 480, in raise_uncaught_exception
    raise exc
  File "/home/mrtbadboy/.local/lib/python3.8/site-packages/rest_framework/views.py", line 506, in dispatch
    response = handler(request, *args, **kwargs)
  File "/home/mrtbadboy/.local/lib/python3.8/site-packages/rest_framework/mixins.py", line 43, in list
    return self.get_paginated_response(serializer.data)
  File "/home/mrtbadboy/.local/lib/python3.8/site-packages/rest_framework/serializers.py", line 745, in data
    ret = super().data
  File "/home/mrtbadboy/.local/lib/python3.8/site-packages/rest_framework/serializers.py", line 246, in data
    self._data = self.to_representation(self.instance)
  File "/home/mrtbadboy/.local/lib/python3.8/site-packages/rest_framework/serializers.py", line 663, in to_representation
    return [
  File "/home/mrtbadboy/.local/lib/python3.8/site-packages/rest_framework/serializers.py", line 664, in <listcomp>
    self.child.to_representation(item) for item in iterable
  File "/home/mrtbadboy/.local/lib/python3.8/site-packages/rest_framework/serializers.py", line 500, in to_representation
    for field in fields:
  File "/home/mrtbadboy/.local/lib/python3.8/site-packages/rest_framework/serializers.py", line 361, in _readable_fields
    for field in self.fields.values():
  File "/home/mrtbadboy/.local/lib/python3.8/site-packages/django/utils/functional.py", line 48, in __get__
    res = instance.__dict__[self.name] = self.func(instance)
  File "/home/mrtbadboy/.local/lib/python3.8/site-packages/rest_framework/serializers.py", line 349, in fields
    for key, value in self.get_fields().items():
  File "/home/mrtbadboy/.local/lib/python3.8/site-packages/rest_framework/serializers.py", line 1053, in get_fields
    field_class, field_kwargs = self.build_field(
  File "/home/mrtbadboy/.local/lib/python3.8/site-packages/rest_framework/serializers.py", line 1199, in build_field
    return self.build_unknown_field(field_name, model_class)
  File "/home/mrtbadboy/.local/lib/python3.8/site-packages/rest_framework/serializers.py", line 1317, in build_unknown_field
    raise ImproperlyConfigured(
django.core.exceptions.ImproperlyConfigured: Field name `telco_Column` is not valid for model `Order`.
Unauthorized: /api/v1/dslamport/check_port_conflict/
Unauthorized: /api/v1/dslamport/check_port_conflict/
Unauthorized: /api/v1/dslamport/check_port_conflict/
Unauthorized: /api/v1/dslamport/check_port_conflict/
Unauthorized: /api/v1/dslamport/check_port_conflict/
Unauthorized: /api/v1/dslamport/check_port_conflict/
Internal Server Error: /api/v1/dslamport/check_port_conflict/
Internal Server Error: /api/v1/dslamport/check_port_conflict/
Unauthorized: /api/v1/switch/connect_handler_test/
Not Found: /favicon.ico
Not Found: /logout/
Not Found: /
Not Found: /favicon.ico
Unauthorized: /api/v1/router/router-runCommand/
Unauthorized: /api/v1/switch/connect_handler_test/
Internal Server Error: /users/get-token
Traceback (most recent call last):
  File "/home/mrtbadboy/PycharmProjects/PortmanV3/venv/lib/python3.8/site-packages/django/db/backends/base/base.py", line 219, in ensure_connection
    self.connect()
  File "/home/mrtbadboy/PycharmProjects/PortmanV3/venv/lib/python3.8/site-packages/django/utils/asyncio.py", line 26, in inner
    return func(*args, **kwargs)
  File "/home/mrtbadboy/PycharmProjects/PortmanV3/venv/lib/python3.8/site-packages/django/db/backends/base/base.py", line 200, in connect
    self.connection = self.get_new_connection(conn_params)
  File "/home/mrtbadboy/PycharmProjects/PortmanV3/venv/lib/python3.8/site-packages/django/utils/asyncio.py", line 26, in inner
    return func(*args, **kwargs)
  File "/home/mrtbadboy/PycharmProjects/PortmanV3/venv/lib/python3.8/site-packages/django/db/backends/postgresql/base.py", line 187, in get_new_connection
    connection = Database.connect(**conn_params)
  File "/home/mrtbadboy/PycharmProjects/PortmanV3/venv/lib/python3.8/site-packages/psycopg2/__init__.py", line 127, in connect
    conn = _connect(dsn, connection_factory=connection_factory, **kwasync)
psycopg2.OperationalError: could not connect to server: Connection refused
	Is the server running on host "5.202.129.160" and accepting
	TCP/IP connections on port 5432?


The above exception was the direct cause of the following exception:

Traceback (most recent call last):
  File "/home/mrtbadboy/PycharmProjects/PortmanV3/venv/lib/python3.8/site-packages/django/core/handlers/exception.py", line 47, in inner
    response = get_response(request)
  File "/home/mrtbadboy/PycharmProjects/PortmanV3/venv/lib/python3.8/site-packages/django/core/handlers/base.py", line 179, in _get_response
    response = wrapped_callback(request, *callback_args, **callback_kwargs)
  File "/home/mrtbadboy/PycharmProjects/PortmanV3/venv/lib/python3.8/site-packages/django/views/decorators/csrf.py", line 54, in wrapped_view
    return view_func(*args, **kwargs)
  File "/home/mrtbadboy/PycharmProjects/PortmanV3/venv/lib/python3.8/site-packages/django/views/generic/base.py", line 70, in view
    return self.dispatch(request, *args, **kwargs)
  File "/home/mrtbadboy/PycharmProjects/PortmanV3/venv/lib/python3.8/site-packages/rest_framework/views.py", line 509, in dispatch
    response = self.handle_exception(exc)
  File "/home/mrtbadboy/PycharmProjects/PortmanV3/venv/lib/python3.8/site-packages/rest_framework/views.py", line 469, in handle_exception
    self.raise_uncaught_exception(exc)
  File "/home/mrtbadboy/PycharmProjects/PortmanV3/venv/lib/python3.8/site-packages/rest_framework/views.py", line 480, in raise_uncaught_exception
    raise exc
  File "/home/mrtbadboy/PycharmProjects/PortmanV3/venv/lib/python3.8/site-packages/rest_framework/views.py", line 506, in dispatch
    response = handler(request, *args, **kwargs)
  File "/home/mrtbadboy/PycharmProjects/PortmanV3/venv/lib/python3.8/site-packages/rest_framework_jwt/views.py", line 57, in post
    if serializer.is_valid():
  File "/home/mrtbadboy/PycharmProjects/PortmanV3/venv/lib/python3.8/site-packages/rest_framework/serializers.py", line 220, in is_valid
    self._validated_data = self.run_validation(self.initial_data)
  File "/home/mrtbadboy/PycharmProjects/PortmanV3/venv/lib/python3.8/site-packages/rest_framework/serializers.py", line 422, in run_validation
    value = self.validate(value)
  File "/home/mrtbadboy/PycharmProjects/PortmanV3/venv/lib/python3.8/site-packages/rest_framework_jwt/serializers.py", line 50, in validate
    user = authenticate(**credentials)
  File "/home/mrtbadboy/PycharmProjects/PortmanV3/venv/lib/python3.8/site-packages/django/contrib/auth/__init__.py", line 73, in authenticate
    user = backend.authenticate(request, **credentials)
  File "/home/mrtbadboy/PycharmProjects/PortmanV3/venv/lib/python3.8/site-packages/django/contrib/auth/backends.py", line 42, in authenticate
    user = UserModel._default_manager.get_by_natural_key(username)
  File "/home/mrtbadboy/PycharmProjects/PortmanV3/venv/lib/python3.8/site-packages/django/contrib/auth/base_user.py", line 45, in get_by_natural_key
    return self.get(**{self.model.USERNAME_FIELD: username})
  File "/home/mrtbadboy/PycharmProjects/PortmanV3/venv/lib/python3.8/site-packages/django/db/models/manager.py", line 85, in manager_method
    return getattr(self.get_queryset(), name)(*args, **kwargs)
  File "/home/mrtbadboy/PycharmProjects/PortmanV3/venv/lib/python3.8/site-packages/django/db/models/query.py", line 425, in get
    num = len(clone)
  File "/home/mrtbadboy/PycharmProjects/PortmanV3/venv/lib/python3.8/site-packages/django/db/models/query.py", line 269, in __len__
    self._fetch_all()
  File "/home/mrtbadboy/PycharmProjects/PortmanV3/venv/lib/python3.8/site-packages/django/db/models/query.py", line 1308, in _fetch_all
    self._result_cache = list(self._iterable_class(self))
  File "/home/mrtbadboy/PycharmProjects/PortmanV3/venv/lib/python3.8/site-packages/django/db/models/query.py", line 53, in __iter__
    results = compiler.execute_sql(chunked_fetch=self.chunked_fetch, chunk_size=self.chunk_size)
  File "/home/mrtbadboy/PycharmProjects/PortmanV3/venv/lib/python3.8/site-packages/django/db/models/sql/compiler.py", line 1154, in execute_sql
    cursor = self.connection.cursor()
  File "/home/mrtbadboy/PycharmProjects/PortmanV3/venv/lib/python3.8/site-packages/django/utils/asyncio.py", line 26, in inner
    return func(*args, **kwargs)
  File "/home/mrtbadboy/PycharmProjects/PortmanV3/venv/lib/python3.8/site-packages/django/db/backends/base/base.py", line 259, in cursor
    return self._cursor()
  File "/home/mrtbadboy/PycharmProjects/PortmanV3/venv/lib/python3.8/site-packages/django/db/backends/base/base.py", line 235, in _cursor
    self.ensure_connection()
  File "/home/mrtbadboy/PycharmProjects/PortmanV3/venv/lib/python3.8/site-packages/django/utils/asyncio.py", line 26, in inner
    return func(*args, **kwargs)
  File "/home/mrtbadboy/PycharmProjects/PortmanV3/venv/lib/python3.8/site-packages/django/db/backends/base/base.py", line 219, in ensure_connection
    self.connect()
  File "/home/mrtbadboy/PycharmProjects/PortmanV3/venv/lib/python3.8/site-packages/django/db/utils.py", line 90, in __exit__
    raise dj_exc_value.with_traceback(traceback) from exc_value
  File "/home/mrtbadboy/PycharmProjects/PortmanV3/venv/lib/python3.8/site-packages/django/db/backends/base/base.py", line 219, in ensure_connection
    self.connect()
  File "/home/mrtbadboy/PycharmProjects/PortmanV3/venv/lib/python3.8/site-packages/django/utils/asyncio.py", line 26, in inner
    return func(*args, **kwargs)
  File "/home/mrtbadboy/PycharmProjects/PortmanV3/venv/lib/python3.8/site-packages/django/db/backends/base/base.py", line 200, in connect
    self.connection = self.get_new_connection(conn_params)
  File "/home/mrtbadboy/PycharmProjects/PortmanV3/venv/lib/python3.8/site-packages/django/utils/asyncio.py", line 26, in inner
    return func(*args, **kwargs)
  File "/home/mrtbadboy/PycharmProjects/PortmanV3/venv/lib/python3.8/site-packages/django/db/backends/postgresql/base.py", line 187, in get_new_connection
    connection = Database.connect(**conn_params)
  File "/home/mrtbadboy/PycharmProjects/PortmanV3/venv/lib/python3.8/site-packages/psycopg2/__init__.py", line 127, in connect
    conn = _connect(dsn, connection_factory=connection_factory, **kwasync)
django.db.utils.OperationalError: could not connect to server: Connection refused
	Is the server running on host "5.202.129.160" and accepting
	TCP/IP connections on port 5432?

Not Found: /logout/
Not Found: /logout/
Method Not Allowed: /api/v1/router/router-runCommand/
Method Not Allowed: /api/v1/dslamport/run-command/
Internal Server Error: /api/v1/dslamport/run-command/
Traceback (most recent call last):
  File "/home/mrtbadboy/PycharmProjects/PortmanV3/venv/lib/python3.8/site-packages/django/db/backends/base/base.py", line 219, in ensure_connection
    self.connect()
  File "/home/mrtbadboy/PycharmProjects/PortmanV3/venv/lib/python3.8/site-packages/django/utils/asyncio.py", line 26, in inner
    return func(*args, **kwargs)
  File "/home/mrtbadboy/PycharmProjects/PortmanV3/venv/lib/python3.8/site-packages/django/db/backends/base/base.py", line 200, in connect
    self.connection = self.get_new_connection(conn_params)
  File "/home/mrtbadboy/PycharmProjects/PortmanV3/venv/lib/python3.8/site-packages/django/utils/asyncio.py", line 26, in inner
    return func(*args, **kwargs)
  File "/home/mrtbadboy/PycharmProjects/PortmanV3/venv/lib/python3.8/site-packages/django/db/backends/postgresql/base.py", line 187, in get_new_connection
    connection = Database.connect(**conn_params)
  File "/home/mrtbadboy/PycharmProjects/PortmanV3/venv/lib/python3.8/site-packages/psycopg2/__init__.py", line 127, in connect
    conn = _connect(dsn, connection_factory=connection_factory, **kwasync)
psycopg2.OperationalError: could not connect to server: Connection refused
	Is the server running on host "5.202.129.160" and accepting
	TCP/IP connections on port 5432?


The above exception was the direct cause of the following exception:

Traceback (most recent call last):
  File "/home/mrtbadboy/PycharmProjects/PortmanV3/venv/lib/python3.8/site-packages/django/core/handlers/exception.py", line 47, in inner
    response = get_response(request)
  File "/home/mrtbadboy/PycharmProjects/PortmanV3/venv/lib/python3.8/site-packages/django/core/handlers/base.py", line 179, in _get_response
    response = wrapped_callback(request, *callback_args, **callback_kwargs)
  File "/home/mrtbadboy/PycharmProjects/PortmanV3/venv/lib/python3.8/site-packages/django/views/decorators/csrf.py", line 54, in wrapped_view
    return view_func(*args, **kwargs)
  File "/home/mrtbadboy/PycharmProjects/PortmanV3/venv/lib/python3.8/site-packages/django/views/generic/base.py", line 70, in view
    return self.dispatch(request, *args, **kwargs)
  File "/home/mrtbadboy/PycharmProjects/PortmanV3/venv/lib/python3.8/site-packages/rest_framework/views.py", line 509, in dispatch
    response = self.handle_exception(exc)
  File "/home/mrtbadboy/PycharmProjects/PortmanV3/venv/lib/python3.8/site-packages/rest_framework/views.py", line 469, in handle_exception
    self.raise_uncaught_exception(exc)
  File "/home/mrtbadboy/PycharmProjects/PortmanV3/venv/lib/python3.8/site-packages/rest_framework/views.py", line 480, in raise_uncaught_exception
    raise exc
  File "/home/mrtbadboy/PycharmProjects/PortmanV3/venv/lib/python3.8/site-packages/rest_framework/views.py", line 497, in dispatch
    self.initial(request, *args, **kwargs)
  File "/home/mrtbadboy/PycharmProjects/PortmanV3/venv/lib/python3.8/site-packages/rest_framework/views.py", line 414, in initial
    self.perform_authentication(request)
  File "/home/mrtbadboy/PycharmProjects/PortmanV3/venv/lib/python3.8/site-packages/rest_framework/views.py", line 324, in perform_authentication
    request.user
  File "/home/mrtbadboy/PycharmProjects/PortmanV3/venv/lib/python3.8/site-packages/rest_framework/request.py", line 227, in user
    self._authenticate()
  File "/home/mrtbadboy/PycharmProjects/PortmanV3/venv/lib/python3.8/site-packages/rest_framework/request.py", line 380, in _authenticate
    user_auth_tuple = authenticator.authenticate(self)
  File "/home/mrtbadboy/PycharmProjects/PortmanV3/venv/lib/python3.8/site-packages/rest_framework_jwt/authentication.py", line 43, in authenticate
    user = self.authenticate_credentials(payload)
  File "/home/mrtbadboy/PycharmProjects/PortmanV3/venv/lib/python3.8/site-packages/rest_framework_jwt/authentication.py", line 59, in authenticate_credentials
    user = User.objects.get_by_natural_key(username)
  File "/home/mrtbadboy/PycharmProjects/PortmanV3/venv/lib/python3.8/site-packages/django/contrib/auth/base_user.py", line 45, in get_by_natural_key
    return self.get(**{self.model.USERNAME_FIELD: username})
  File "/home/mrtbadboy/PycharmProjects/PortmanV3/venv/lib/python3.8/site-packages/django/db/models/manager.py", line 85, in manager_method
    return getattr(self.get_queryset(), name)(*args, **kwargs)
  File "/home/mrtbadboy/PycharmProjects/PortmanV3/venv/lib/python3.8/site-packages/django/db/models/query.py", line 425, in get
    num = len(clone)
  File "/home/mrtbadboy/PycharmProjects/PortmanV3/venv/lib/python3.8/site-packages/django/db/models/query.py", line 269, in __len__
    self._fetch_all()
  File "/home/mrtbadboy/PycharmProjects/PortmanV3/venv/lib/python3.8/site-packages/django/db/models/query.py", line 1308, in _fetch_all
    self._result_cache = list(self._iterable_class(self))
  File "/home/mrtbadboy/PycharmProjects/PortmanV3/venv/lib/python3.8/site-packages/django/db/models/query.py", line 53, in __iter__
    results = compiler.execute_sql(chunked_fetch=self.chunked_fetch, chunk_size=self.chunk_size)
  File "/home/mrtbadboy/PycharmProjects/PortmanV3/venv/lib/python3.8/site-packages/django/db/models/sql/compiler.py", line 1154, in execute_sql
    cursor = self.connection.cursor()
  File "/home/mrtbadboy/PycharmProjects/PortmanV3/venv/lib/python3.8/site-packages/django/utils/asyncio.py", line 26, in inner
    return func(*args, **kwargs)
  File "/home/mrtbadboy/PycharmProjects/PortmanV3/venv/lib/python3.8/site-packages/django/db/backends/base/base.py", line 259, in cursor
    return self._cursor()
  File "/home/mrtbadboy/PycharmProjects/PortmanV3/venv/lib/python3.8/site-packages/django/db/backends/base/base.py", line 235, in _cursor
    self.ensure_connection()
  File "/home/mrtbadboy/PycharmProjects/PortmanV3/venv/lib/python3.8/site-packages/django/utils/asyncio.py", line 26, in inner
    return func(*args, **kwargs)
  File "/home/mrtbadboy/PycharmProjects/PortmanV3/venv/lib/python3.8/site-packages/django/db/backends/base/base.py", line 219, in ensure_connection
    self.connect()
  File "/home/mrtbadboy/PycharmProjects/PortmanV3/venv/lib/python3.8/site-packages/django/db/utils.py", line 90, in __exit__
    raise dj_exc_value.with_traceback(traceback) from exc_value
  File "/home/mrtbadboy/PycharmProjects/PortmanV3/venv/lib/python3.8/site-packages/django/db/backends/base/base.py", line 219, in ensure_connection
    self.connect()
  File "/home/mrtbadboy/PycharmProjects/PortmanV3/venv/lib/python3.8/site-packages/django/utils/asyncio.py", line 26, in inner
    return func(*args, **kwargs)
  File "/home/mrtbadboy/PycharmProjects/PortmanV3/venv/lib/python3.8/site-packages/django/db/backends/base/base.py", line 200, in connect
    self.connection = self.get_new_connection(conn_params)
  File "/home/mrtbadboy/PycharmProjects/PortmanV3/venv/lib/python3.8/site-packages/django/utils/asyncio.py", line 26, in inner
    return func(*args, **kwargs)
  File "/home/mrtbadboy/PycharmProjects/PortmanV3/venv/lib/python3.8/site-packages/django/db/backends/postgresql/base.py", line 187, in get_new_connection
    connection = Database.connect(**conn_params)
  File "/home/mrtbadboy/PycharmProjects/PortmanV3/venv/lib/python3.8/site-packages/psycopg2/__init__.py", line 127, in connect
    conn = _connect(dsn, connection_factory=connection_factory, **kwasync)
django.db.utils.OperationalError: could not connect to server: Connection refused
	Is the server running on host "5.202.129.160" and accepting
	TCP/IP connections on port 5432?

Unauthorized: /api/v1/switch/command/
Not Found: /api/v1/switch/command/
Not Found: /api/v1/switch/command/
Internal Server Error: /api/v1/switch-command/
Traceback (most recent call last):
  File "/home/mrtbadboy/PycharmProjects/PortmanV3/venv/lib/python3.8/site-packages/django/core/handlers/exception.py", line 47, in inner
    response = get_response(request)
  File "/home/mrtbadboy/PycharmProjects/PortmanV3/venv/lib/python3.8/site-packages/django/core/handlers/base.py", line 179, in _get_response
    response = wrapped_callback(request, *callback_args, **callback_kwargs)
  File "/home/mrtbadboy/PycharmProjects/PortmanV3/venv/lib/python3.8/site-packages/django/views/decorators/csrf.py", line 54, in wrapped_view
    return view_func(*args, **kwargs)
  File "/home/mrtbadboy/PycharmProjects/PortmanV3/venv/lib/python3.8/site-packages/rest_framework/viewsets.py", line 125, in view
    return self.dispatch(request, *args, **kwargs)
  File "/home/mrtbadboy/PycharmProjects/PortmanV3/venv/lib/python3.8/site-packages/rest_framework/views.py", line 509, in dispatch
    response = self.handle_exception(exc)
  File "/home/mrtbadboy/PycharmProjects/PortmanV3/venv/lib/python3.8/site-packages/rest_framework/views.py", line 469, in handle_exception
    self.raise_uncaught_exception(exc)
  File "/home/mrtbadboy/PycharmProjects/PortmanV3/venv/lib/python3.8/site-packages/rest_framework/views.py", line 480, in raise_uncaught_exception
    raise exc
  File "/home/mrtbadboy/PycharmProjects/PortmanV3/venv/lib/python3.8/site-packages/rest_framework/views.py", line 506, in dispatch
    response = handler(request, *args, **kwargs)
  File "/home/mrtbadboy/PycharmProjects/PortmanV3/venv/lib/python3.8/site-packages/rest_framework/mixins.py", line 45, in list
    serializer = self.get_serializer(queryset, many=True)
  File "/home/mrtbadboy/PycharmProjects/PortmanV3/venv/lib/python3.8/site-packages/rest_framework/generics.py", line 110, in get_serializer
    return serializer_class(*args, **kwargs)
  File "/home/mrtbadboy/PycharmProjects/PortmanV3/venv/lib/python3.8/site-packages/rest_framework/serializers.py", line 121, in __new__
    return cls.many_init(*args, **kwargs)
  File "/home/mrtbadboy/PycharmProjects/PortmanV3/venv/lib/python3.8/site-packages/rest_framework/serializers.py", line 146, in many_init
    child_serializer = cls(*args, **kwargs)
  File "/opt/portmanv3/portman_web/switch/serializers.py", line 33, in __init__
    super(SwitchSerializer, self).__init__(*args, **kwargs)
TypeError: super(type, obj): obj must be an instance or subtype of type
Not Found: /api/v1/switch/command/
Not Found: /api/v1/switch/command/
Not Found: /api/v1/switch/command/
Not Found: /api/v1/switch/command/
Not Found: /api/v1/switch/command/
Not Found: /api/v1/switch/command/
Not Found: /api/v1/switch/command/
Not Found: /api/v1/switch/command/
Not Found: /api/v1/switch/command/
Internal Server Error: /api/v1/switch-command/
Traceback (most recent call last):
  File "/home/mrtbadboy/PycharmProjects/PortmanV3/venv/lib/python3.8/site-packages/django/core/handlers/exception.py", line 47, in inner
    response = get_response(request)
  File "/home/mrtbadboy/PycharmProjects/PortmanV3/venv/lib/python3.8/site-packages/django/core/handlers/base.py", line 179, in _get_response
    response = wrapped_callback(request, *callback_args, **callback_kwargs)
  File "/home/mrtbadboy/PycharmProjects/PortmanV3/venv/lib/python3.8/site-packages/django/views/decorators/csrf.py", line 54, in wrapped_view
    return view_func(*args, **kwargs)
  File "/home/mrtbadboy/PycharmProjects/PortmanV3/venv/lib/python3.8/site-packages/rest_framework/viewsets.py", line 125, in view
    return self.dispatch(request, *args, **kwargs)
  File "/home/mrtbadboy/PycharmProjects/PortmanV3/venv/lib/python3.8/site-packages/rest_framework/views.py", line 509, in dispatch
    response = self.handle_exception(exc)
  File "/home/mrtbadboy/PycharmProjects/PortmanV3/venv/lib/python3.8/site-packages/rest_framework/views.py", line 469, in handle_exception
    self.raise_uncaught_exception(exc)
  File "/home/mrtbadboy/PycharmProjects/PortmanV3/venv/lib/python3.8/site-packages/rest_framework/views.py", line 480, in raise_uncaught_exception
    raise exc
  File "/home/mrtbadboy/PycharmProjects/PortmanV3/venv/lib/python3.8/site-packages/rest_framework/views.py", line 506, in dispatch
    response = handler(request, *args, **kwargs)
  File "/home/mrtbadboy/PycharmProjects/PortmanV3/venv/lib/python3.8/site-packages/rest_framework/mixins.py", line 45, in list
    serializer = self.get_serializer(queryset, many=True)
  File "/home/mrtbadboy/PycharmProjects/PortmanV3/venv/lib/python3.8/site-packages/rest_framework/generics.py", line 110, in get_serializer
    return serializer_class(*args, **kwargs)
  File "/home/mrtbadboy/PycharmProjects/PortmanV3/venv/lib/python3.8/site-packages/rest_framework/serializers.py", line 121, in __new__
    return cls.many_init(*args, **kwargs)
  File "/home/mrtbadboy/PycharmProjects/PortmanV3/venv/lib/python3.8/site-packages/rest_framework/serializers.py", line 146, in many_init
    child_serializer = cls(*args, **kwargs)
  File "/opt/portmanv3/portman_web/switch/serializers.py", line 33, in __init__
    super(SwitchSerializer, self).__init__(*args, **kwargs)
TypeError: super(type, obj): obj must be an instance or subtype of type
Internal Server Error: /api/v1/switch-command/
Traceback (most recent call last):
  File "/home/mrtbadboy/PycharmProjects/PortmanV3/venv/lib/python3.8/site-packages/django/core/handlers/exception.py", line 47, in inner
    response = get_response(request)
  File "/home/mrtbadboy/PycharmProjects/PortmanV3/venv/lib/python3.8/site-packages/django/core/handlers/base.py", line 179, in _get_response
    response = wrapped_callback(request, *callback_args, **callback_kwargs)
  File "/home/mrtbadboy/PycharmProjects/PortmanV3/venv/lib/python3.8/site-packages/django/views/decorators/csrf.py", line 54, in wrapped_view
    return view_func(*args, **kwargs)
  File "/home/mrtbadboy/PycharmProjects/PortmanV3/venv/lib/python3.8/site-packages/rest_framework/viewsets.py", line 125, in view
    return self.dispatch(request, *args, **kwargs)
  File "/home/mrtbadboy/PycharmProjects/PortmanV3/venv/lib/python3.8/site-packages/rest_framework/views.py", line 509, in dispatch
    response = self.handle_exception(exc)
  File "/home/mrtbadboy/PycharmProjects/PortmanV3/venv/lib/python3.8/site-packages/rest_framework/views.py", line 469, in handle_exception
    self.raise_uncaught_exception(exc)
  File "/home/mrtbadboy/PycharmProjects/PortmanV3/venv/lib/python3.8/site-packages/rest_framework/views.py", line 480, in raise_uncaught_exception
    raise exc
  File "/home/mrtbadboy/PycharmProjects/PortmanV3/venv/lib/python3.8/site-packages/rest_framework/views.py", line 506, in dispatch
    response = handler(request, *args, **kwargs)
  File "/home/mrtbadboy/PycharmProjects/PortmanV3/venv/lib/python3.8/site-packages/rest_framework/mixins.py", line 45, in list
    serializer = self.get_serializer(queryset, many=True)
  File "/home/mrtbadboy/PycharmProjects/PortmanV3/venv/lib/python3.8/site-packages/rest_framework/generics.py", line 110, in get_serializer
    return serializer_class(*args, **kwargs)
  File "/home/mrtbadboy/PycharmProjects/PortmanV3/venv/lib/python3.8/site-packages/rest_framework/serializers.py", line 121, in __new__
    return cls.many_init(*args, **kwargs)
  File "/home/mrtbadboy/PycharmProjects/PortmanV3/venv/lib/python3.8/site-packages/rest_framework/serializers.py", line 146, in many_init
    child_serializer = cls(*args, **kwargs)
  File "/opt/portmanv3/portman_web/switch/serializers.py", line 33, in __init__
    super(SwitchSerializer, self).__init__(*args, **kwargs)
TypeError: super(type, obj): obj must be an instance or subtype of type
Not Found: /api/v1/switch/command/
Not Found: /api/v1/switch/command/
Not Found: /api/v1/switch/command/
Not Found: /api/v1/contact/portmap
Not Found: /api/v1/switch/command/
Not Found: /api/v1/switch/command/
Not Found: /api/v1/switch/command/
Not Found: /api/v1/switch/command/
Not Found: /api/v1/switch/command/
Not Found: /api/v1/switch/command/
Internal Server Error: /api/v1/command2/
Traceback (most recent call last):
  File "/home/mrtbadboy/PycharmProjects/PortmanV3/venv/lib/python3.8/site-packages/django/core/handlers/exception.py", line 47, in inner
    response = get_response(request)
  File "/home/mrtbadboy/PycharmProjects/PortmanV3/venv/lib/python3.8/site-packages/django/core/handlers/base.py", line 179, in _get_response
    response = wrapped_callback(request, *callback_args, **callback_kwargs)
  File "/home/mrtbadboy/PycharmProjects/PortmanV3/venv/lib/python3.8/site-packages/django/views/decorators/csrf.py", line 54, in wrapped_view
    return view_func(*args, **kwargs)
  File "/home/mrtbadboy/PycharmProjects/PortmanV3/venv/lib/python3.8/site-packages/rest_framework/viewsets.py", line 125, in view
    return self.dispatch(request, *args, **kwargs)
  File "/home/mrtbadboy/PycharmProjects/PortmanV3/venv/lib/python3.8/site-packages/rest_framework/views.py", line 509, in dispatch
    response = self.handle_exception(exc)
  File "/home/mrtbadboy/PycharmProjects/PortmanV3/venv/lib/python3.8/site-packages/rest_framework/views.py", line 469, in handle_exception
    self.raise_uncaught_exception(exc)
  File "/home/mrtbadboy/PycharmProjects/PortmanV3/venv/lib/python3.8/site-packages/rest_framework/views.py", line 480, in raise_uncaught_exception
    raise exc
  File "/home/mrtbadboy/PycharmProjects/PortmanV3/venv/lib/python3.8/site-packages/rest_framework/views.py", line 506, in dispatch
    response = handler(request, *args, **kwargs)
  File "/home/mrtbadboy/PycharmProjects/PortmanV3/venv/lib/python3.8/site-packages/rest_framework/mixins.py", line 45, in list
    serializer = self.get_serializer(queryset, many=True)
  File "/home/mrtbadboy/PycharmProjects/PortmanV3/venv/lib/python3.8/site-packages/rest_framework/generics.py", line 110, in get_serializer
    return serializer_class(*args, **kwargs)
  File "/home/mrtbadboy/PycharmProjects/PortmanV3/venv/lib/python3.8/site-packages/rest_framework/serializers.py", line 121, in __new__
    return cls.many_init(*args, **kwargs)
  File "/home/mrtbadboy/PycharmProjects/PortmanV3/venv/lib/python3.8/site-packages/rest_framework/serializers.py", line 146, in many_init
    child_serializer = cls(*args, **kwargs)
  File "/opt/portmanv3/portman_web/switch/serializers.py", line 33, in __init__
    super(SwitchSerializer, self).__init__(*args, **kwargs)
TypeError: super(type, obj): obj must be an instance or subtype of type
Not Found: /api/v1/command2
Internal Server Error: /api/v1/switch-command/
Traceback (most recent call last):
  File "/home/mrtbadboy/PycharmProjects/PortmanV3/venv/lib/python3.8/site-packages/django/core/handlers/exception.py", line 47, in inner
    response = get_response(request)
  File "/home/mrtbadboy/PycharmProjects/PortmanV3/venv/lib/python3.8/site-packages/django/core/handlers/base.py", line 179, in _get_response
    response = wrapped_callback(request, *callback_args, **callback_kwargs)
  File "/home/mrtbadboy/PycharmProjects/PortmanV3/venv/lib/python3.8/site-packages/django/views/decorators/csrf.py", line 54, in wrapped_view
    return view_func(*args, **kwargs)
  File "/home/mrtbadboy/PycharmProjects/PortmanV3/venv/lib/python3.8/site-packages/rest_framework/viewsets.py", line 125, in view
    return self.dispatch(request, *args, **kwargs)
  File "/home/mrtbadboy/PycharmProjects/PortmanV3/venv/lib/python3.8/site-packages/rest_framework/views.py", line 509, in dispatch
    response = self.handle_exception(exc)
  File "/home/mrtbadboy/PycharmProjects/PortmanV3/venv/lib/python3.8/site-packages/rest_framework/views.py", line 469, in handle_exception
    self.raise_uncaught_exception(exc)
  File "/home/mrtbadboy/PycharmProjects/PortmanV3/venv/lib/python3.8/site-packages/rest_framework/views.py", line 480, in raise_uncaught_exception
    raise exc
  File "/home/mrtbadboy/PycharmProjects/PortmanV3/venv/lib/python3.8/site-packages/rest_framework/views.py", line 506, in dispatch
    response = handler(request, *args, **kwargs)
  File "/home/mrtbadboy/PycharmProjects/PortmanV3/venv/lib/python3.8/site-packages/rest_framework/mixins.py", line 45, in list
    serializer = self.get_serializer(queryset, many=True)
  File "/home/mrtbadboy/PycharmProjects/PortmanV3/venv/lib/python3.8/site-packages/rest_framework/generics.py", line 110, in get_serializer
    return serializer_class(*args, **kwargs)
  File "/home/mrtbadboy/PycharmProjects/PortmanV3/venv/lib/python3.8/site-packages/rest_framework/serializers.py", line 121, in __new__
    return cls.many_init(*args, **kwargs)
  File "/home/mrtbadboy/PycharmProjects/PortmanV3/venv/lib/python3.8/site-packages/rest_framework/serializers.py", line 146, in many_init
    child_serializer = cls(*args, **kwargs)
  File "/opt/portmanv3/portman_web/switch/serializers.py", line 33, in __init__
    super(SwitchSerializer, self).__init__(*args, **kwargs)
TypeError: super(type, obj): obj must be an instance or subtype of type
Internal Server Error: /api/v1/switch-command/
Traceback (most recent call last):
  File "/home/mrtbadboy/PycharmProjects/PortmanV3/venv/lib/python3.8/site-packages/rest_framework/fields.py", line 457, in get_attribute
    return get_attribute(instance, self.source_attrs)
  File "/home/mrtbadboy/PycharmProjects/PortmanV3/venv/lib/python3.8/site-packages/rest_framework/fields.py", line 97, in get_attribute
    instance = getattr(instance, attr)
AttributeError: 'SwitchCommand' object has no attribute 'device_ip'

During handling of the above exception, another exception occurred:

Traceback (most recent call last):
  File "/home/mrtbadboy/PycharmProjects/PortmanV3/venv/lib/python3.8/site-packages/django/core/handlers/exception.py", line 47, in inner
    response = get_response(request)
  File "/home/mrtbadboy/PycharmProjects/PortmanV3/venv/lib/python3.8/site-packages/django/core/handlers/base.py", line 179, in _get_response
    response = wrapped_callback(request, *callback_args, **callback_kwargs)
  File "/home/mrtbadboy/PycharmProjects/PortmanV3/venv/lib/python3.8/site-packages/django/views/decorators/csrf.py", line 54, in wrapped_view
    return view_func(*args, **kwargs)
  File "/home/mrtbadboy/PycharmProjects/PortmanV3/venv/lib/python3.8/site-packages/rest_framework/viewsets.py", line 125, in view
    return self.dispatch(request, *args, **kwargs)
  File "/home/mrtbadboy/PycharmProjects/PortmanV3/venv/lib/python3.8/site-packages/rest_framework/views.py", line 509, in dispatch
    response = self.handle_exception(exc)
  File "/home/mrtbadboy/PycharmProjects/PortmanV3/venv/lib/python3.8/site-packages/rest_framework/views.py", line 469, in handle_exception
    self.raise_uncaught_exception(exc)
  File "/home/mrtbadboy/PycharmProjects/PortmanV3/venv/lib/python3.8/site-packages/rest_framework/views.py", line 480, in raise_uncaught_exception
    raise exc
  File "/home/mrtbadboy/PycharmProjects/PortmanV3/venv/lib/python3.8/site-packages/rest_framework/views.py", line 506, in dispatch
    response = handler(request, *args, **kwargs)
  File "/home/mrtbadboy/PycharmProjects/PortmanV3/venv/lib/python3.8/site-packages/rest_framework/mixins.py", line 46, in list
    return Response(serializer.data)
  File "/home/mrtbadboy/PycharmProjects/PortmanV3/venv/lib/python3.8/site-packages/rest_framework/serializers.py", line 745, in data
    ret = super().data
  File "/home/mrtbadboy/PycharmProjects/PortmanV3/venv/lib/python3.8/site-packages/rest_framework/serializers.py", line 246, in data
    self._data = self.to_representation(self.instance)
  File "/home/mrtbadboy/PycharmProjects/PortmanV3/venv/lib/python3.8/site-packages/rest_framework/serializers.py", line 663, in to_representation
    return [
  File "/home/mrtbadboy/PycharmProjects/PortmanV3/venv/lib/python3.8/site-packages/rest_framework/serializers.py", line 664, in <listcomp>
    self.child.to_representation(item) for item in iterable
  File "/home/mrtbadboy/PycharmProjects/PortmanV3/venv/lib/python3.8/site-packages/rest_framework/serializers.py", line 502, in to_representation
    attribute = field.get_attribute(instance)
  File "/home/mrtbadboy/PycharmProjects/PortmanV3/venv/lib/python3.8/site-packages/rest_framework/fields.py", line 490, in get_attribute
    raise type(exc)(msg)
AttributeError: Got AttributeError when attempting to get a value for field `device_ip` on serializer `SwitchCommandSerializer`.
The serializer field might be named incorrectly and not match any attribute or key on the `SwitchCommand` instance.
Original exception text was: 'SwitchCommand' object has no attribute 'device_ip'.
Internal Server Error: /api/v1/switch-command/
Traceback (most recent call last):
  File "/home/mrtbadboy/PycharmProjects/PortmanV3/venv/lib/python3.8/site-packages/rest_framework/fields.py", line 457, in get_attribute
    return get_attribute(instance, self.source_attrs)
  File "/home/mrtbadboy/PycharmProjects/PortmanV3/venv/lib/python3.8/site-packages/rest_framework/fields.py", line 97, in get_attribute
    instance = getattr(instance, attr)
AttributeError: 'SwitchCommand' object has no attribute 'device_ip'

During handling of the above exception, another exception occurred:

Traceback (most recent call last):
  File "/home/mrtbadboy/PycharmProjects/PortmanV3/venv/lib/python3.8/site-packages/django/core/handlers/exception.py", line 47, in inner
    response = get_response(request)
  File "/home/mrtbadboy/PycharmProjects/PortmanV3/venv/lib/python3.8/site-packages/django/core/handlers/base.py", line 179, in _get_response
    response = wrapped_callback(request, *callback_args, **callback_kwargs)
  File "/home/mrtbadboy/PycharmProjects/PortmanV3/venv/lib/python3.8/site-packages/django/views/decorators/csrf.py", line 54, in wrapped_view
    return view_func(*args, **kwargs)
  File "/home/mrtbadboy/PycharmProjects/PortmanV3/venv/lib/python3.8/site-packages/rest_framework/viewsets.py", line 125, in view
    return self.dispatch(request, *args, **kwargs)
  File "/home/mrtbadboy/PycharmProjects/PortmanV3/venv/lib/python3.8/site-packages/rest_framework/views.py", line 509, in dispatch
    response = self.handle_exception(exc)
  File "/home/mrtbadboy/PycharmProjects/PortmanV3/venv/lib/python3.8/site-packages/rest_framework/views.py", line 469, in handle_exception
    self.raise_uncaught_exception(exc)
  File "/home/mrtbadboy/PycharmProjects/PortmanV3/venv/lib/python3.8/site-packages/rest_framework/views.py", line 480, in raise_uncaught_exception
    raise exc
  File "/home/mrtbadboy/PycharmProjects/PortmanV3/venv/lib/python3.8/site-packages/rest_framework/views.py", line 506, in dispatch
    response = handler(request, *args, **kwargs)
  File "/home/mrtbadboy/PycharmProjects/PortmanV3/venv/lib/python3.8/site-packages/rest_framework/mixins.py", line 46, in list
    return Response(serializer.data)
  File "/home/mrtbadboy/PycharmProjects/PortmanV3/venv/lib/python3.8/site-packages/rest_framework/serializers.py", line 745, in data
    ret = super().data
  File "/home/mrtbadboy/PycharmProjects/PortmanV3/venv/lib/python3.8/site-packages/rest_framework/serializers.py", line 246, in data
    self._data = self.to_representation(self.instance)
  File "/home/mrtbadboy/PycharmProjects/PortmanV3/venv/lib/python3.8/site-packages/rest_framework/serializers.py", line 663, in to_representation
    return [
  File "/home/mrtbadboy/PycharmProjects/PortmanV3/venv/lib/python3.8/site-packages/rest_framework/serializers.py", line 664, in <listcomp>
    self.child.to_representation(item) for item in iterable
  File "/home/mrtbadboy/PycharmProjects/PortmanV3/venv/lib/python3.8/site-packages/rest_framework/serializers.py", line 502, in to_representation
    attribute = field.get_attribute(instance)
  File "/home/mrtbadboy/PycharmProjects/PortmanV3/venv/lib/python3.8/site-packages/rest_framework/fields.py", line 490, in get_attribute
    raise type(exc)(msg)
AttributeError: Got AttributeError when attempting to get a value for field `device_ip` on serializer `SwitchCommandSerializer`.
The serializer field might be named incorrectly and not match any attribute or key on the `SwitchCommand` instance.
Original exception text was: 'SwitchCommand' object has no attribute 'device_ip'.
Internal Server Error: /api/v1/switch-command/
Traceback (most recent call last):
  File "/home/mrtbadboy/PycharmProjects/PortmanV3/venv/lib/python3.8/site-packages/django/core/handlers/exception.py", line 47, in inner
    response = get_response(request)
  File "/home/mrtbadboy/PycharmProjects/PortmanV3/venv/lib/python3.8/site-packages/django/core/handlers/base.py", line 179, in _get_response
    response = wrapped_callback(request, *callback_args, **callback_kwargs)
  File "/home/mrtbadboy/PycharmProjects/PortmanV3/venv/lib/python3.8/site-packages/django/views/decorators/csrf.py", line 54, in wrapped_view
    return view_func(*args, **kwargs)
  File "/home/mrtbadboy/PycharmProjects/PortmanV3/venv/lib/python3.8/site-packages/rest_framework/viewsets.py", line 125, in view
    return self.dispatch(request, *args, **kwargs)
  File "/home/mrtbadboy/PycharmProjects/PortmanV3/venv/lib/python3.8/site-packages/rest_framework/views.py", line 509, in dispatch
    response = self.handle_exception(exc)
  File "/home/mrtbadboy/PycharmProjects/PortmanV3/venv/lib/python3.8/site-packages/rest_framework/views.py", line 469, in handle_exception
    self.raise_uncaught_exception(exc)
  File "/home/mrtbadboy/PycharmProjects/PortmanV3/venv/lib/python3.8/site-packages/rest_framework/views.py", line 480, in raise_uncaught_exception
    raise exc
  File "/home/mrtbadboy/PycharmProjects/PortmanV3/venv/lib/python3.8/site-packages/rest_framework/views.py", line 506, in dispatch
    response = handler(request, *args, **kwargs)
  File "/home/mrtbadboy/PycharmProjects/PortmanV3/venv/lib/python3.8/site-packages/rest_framework/mixins.py", line 46, in list
    return Response(serializer.data)
  File "/home/mrtbadboy/PycharmProjects/PortmanV3/venv/lib/python3.8/site-packages/rest_framework/serializers.py", line 745, in data
    ret = super().data
  File "/home/mrtbadboy/PycharmProjects/PortmanV3/venv/lib/python3.8/site-packages/rest_framework/serializers.py", line 246, in data
    self._data = self.to_representation(self.instance)
  File "/home/mrtbadboy/PycharmProjects/PortmanV3/venv/lib/python3.8/site-packages/rest_framework/serializers.py", line 663, in to_representation
    return [
  File "/home/mrtbadboy/PycharmProjects/PortmanV3/venv/lib/python3.8/site-packages/rest_framework/serializers.py", line 664, in <listcomp>
    self.child.to_representation(item) for item in iterable
  File "/home/mrtbadboy/PycharmProjects/PortmanV3/venv/lib/python3.8/site-packages/rest_framework/serializers.py", line 500, in to_representation
    for field in fields:
  File "/home/mrtbadboy/PycharmProjects/PortmanV3/venv/lib/python3.8/site-packages/rest_framework/serializers.py", line 361, in _readable_fields
    for field in self.fields.values():
  File "/home/mrtbadboy/PycharmProjects/PortmanV3/venv/lib/python3.8/site-packages/django/utils/functional.py", line 48, in __get__
    res = instance.__dict__[self.name] = self.func(instance)
  File "/home/mrtbadboy/PycharmProjects/PortmanV3/venv/lib/python3.8/site-packages/rest_framework/serializers.py", line 349, in fields
    for key, value in self.get_fields().items():
  File "/home/mrtbadboy/PycharmProjects/PortmanV3/venv/lib/python3.8/site-packages/rest_framework/serializers.py", line 1053, in get_fields
    field_class, field_kwargs = self.build_field(
  File "/home/mrtbadboy/PycharmProjects/PortmanV3/venv/lib/python3.8/site-packages/rest_framework/serializers.py", line 1199, in build_field
    return self.build_unknown_field(field_name, model_class)
  File "/home/mrtbadboy/PycharmProjects/PortmanV3/venv/lib/python3.8/site-packages/rest_framework/serializers.py", line 1317, in build_unknown_field
    raise ImproperlyConfigured(
django.core.exceptions.ImproperlyConfigured: Field name `switch_command_description` is not valid for model `Switch`.
Internal Server Error: /api/v1/switch-command/
Traceback (most recent call last):
  File "/home/mrtbadboy/PycharmProjects/PortmanV3/venv/lib/python3.8/site-packages/django/core/handlers/exception.py", line 47, in inner
    response = get_response(request)
  File "/home/mrtbadboy/PycharmProjects/PortmanV3/venv/lib/python3.8/site-packages/django/core/handlers/base.py", line 179, in _get_response
    response = wrapped_callback(request, *callback_args, **callback_kwargs)
  File "/home/mrtbadboy/PycharmProjects/PortmanV3/venv/lib/python3.8/site-packages/django/views/decorators/csrf.py", line 54, in wrapped_view
    return view_func(*args, **kwargs)
  File "/home/mrtbadboy/PycharmProjects/PortmanV3/venv/lib/python3.8/site-packages/rest_framework/viewsets.py", line 125, in view
    return self.dispatch(request, *args, **kwargs)
  File "/home/mrtbadboy/PycharmProjects/PortmanV3/venv/lib/python3.8/site-packages/rest_framework/views.py", line 509, in dispatch
    response = self.handle_exception(exc)
  File "/home/mrtbadboy/PycharmProjects/PortmanV3/venv/lib/python3.8/site-packages/rest_framework/views.py", line 469, in handle_exception
    self.raise_uncaught_exception(exc)
  File "/home/mrtbadboy/PycharmProjects/PortmanV3/venv/lib/python3.8/site-packages/rest_framework/views.py", line 480, in raise_uncaught_exception
    raise exc
  File "/home/mrtbadboy/PycharmProjects/PortmanV3/venv/lib/python3.8/site-packages/rest_framework/views.py", line 506, in dispatch
    response = handler(request, *args, **kwargs)
  File "/home/mrtbadboy/PycharmProjects/PortmanV3/venv/lib/python3.8/site-packages/rest_framework/mixins.py", line 46, in list
    return Response(serializer.data)
  File "/home/mrtbadboy/PycharmProjects/PortmanV3/venv/lib/python3.8/site-packages/rest_framework/serializers.py", line 745, in data
    ret = super().data
  File "/home/mrtbadboy/PycharmProjects/PortmanV3/venv/lib/python3.8/site-packages/rest_framework/serializers.py", line 246, in data
    self._data = self.to_representation(self.instance)
  File "/home/mrtbadboy/PycharmProjects/PortmanV3/venv/lib/python3.8/site-packages/rest_framework/serializers.py", line 663, in to_representation
    return [
TypeError: 'SwitchCommand' object is not iterable
Bad Request: /
Bad Request: /favicon.ico
Bad Request: /admin/
Unauthorized: /api/v1/switch/swich_run_command/
Method Not Allowed: /api/v1/switch/switch_run_command/
Not Found: /favicon.ico
Unauthorized: /api/v1/switch/switch_run_command/
Unauthorized: /api/v1/switch/switch_run_command/
Internal Server Error: /api/v1/dslam/load_dslam_ports/
Method Not Allowed: /api/v1/dslam/load_dslam_ports/
Internal Server Error: /api/v1/dslam/load_dslam_ports
Traceback (most recent call last):
  File "/home/mrtbadboy/PycharmProjects/PortmanV3/venv/lib/python3.8/site-packages/django/core/handlers/exception.py", line 47, in inner
    response = get_response(request)
  File "/home/mrtbadboy/PycharmProjects/PortmanV3/venv/lib/python3.8/site-packages/django/utils/deprecation.py", line 113, in __call__
    response = self.process_request(request)
  File "/home/mrtbadboy/PycharmProjects/PortmanV3/venv/lib/python3.8/site-packages/django/middleware/common.py", line 54, in process_request
    path = self.get_full_path_with_slash(request)
  File "/home/mrtbadboy/PycharmProjects/PortmanV3/venv/lib/python3.8/site-packages/django/middleware/common.py", line 87, in get_full_path_with_slash
    raise RuntimeError(
RuntimeError: You called this URL via POST, but the URL doesn't end in a slash and you have APPEND_SLASH set. Django can't redirect to the slash URL while maintaining POST data. Change your form to point to localhost:2080/api/v1/dslam/load_dslam_ports/?dslam_id=40&slot_count=10&port_count=10 (note the trailing slash), or set APPEND_SLASH=False in your Django settings.
Internal Server Error: /api/v1/dslam/load_dslam_ports/
Internal Server Error: /api/v1/dslam/load_dslam_ports/
Internal Server Error: /api/v1/dslam/load_dslam_ports/
Not Found: /favicon.ico
Not Found: /favicon.ico
Method Not Allowed: /api/v1/router/router-runCommand/
Method Not Allowed: /api/v1/router/router-runCommand/
Not Found: /api/v1/router/router-runCommand/
Method Not Allowed: /api/v1/router/router-runCommand/
Internal Server Error: /api/v1/router/routerRunCommand/
Internal Server Error: /api/v1/router/routerRunCommand/
Internal Server Error: /api/v1/router/routerRunCommand/
Internal Server Error: /api/v1/router/routerRunCommand/
Internal Server Error: /api/v1/router/routerRunCommand/
Internal Server Error: /api/v1/router/routerRunCommand/
Internal Server Error: /api/v1/router/routerRunCommand/
Internal Server Error: /api/v1/router/routerRunCommand/
Internal Server Error: /api/v1/router/routerRunCommand/
Internal Server Error: /api/v1/router/routerRunCommand/
Internal Server Error: /api/v1/router/routerRunCommand/
Internal Server Error: /api/v1/router/routerRunCommand/
Internal Server Error: /api/v1/router/routerRunCommand/
Internal Server Error: /api/v1/router/routerRunCommand/
Internal Server Error: /api/v1/router/routerRunCommand/
Internal Server Error: /api/v1/router/routerRunCommand/
Internal Server Error: /api/v1/router/routerRunCommand/
Internal Server Error: /api/v1/router/routerRunCommand/
Internal Server Error: /api/v1/router/routerRunCommand/
Internal Server Error: /api/v1/router/routerRunCommand/
Internal Server Error: /api/v1/router/routerRunCommand/
Internal Server Error: /api/v1/router/routerRunCommand/
Internal Server Error: /api/v1/router/routerRunCommand/
Internal Server Error: /api/v1/router/routerRunCommand/
Internal Server Error: /api/v1/router/routerRunCommand/
Internal Server Error: /api/v1/router/routerRunCommand/
Internal Server Error: /api/v1/router/routerRunCommand/
Internal Server Error: /api/v1/router/routerRunCommand/
Internal Server Error: /api/v1/router/routerRunCommand/
Internal Server Error: /api/v1/router/routerRunCommand/
Internal Server Error: /api/v1/router/routerRunCommand/
Internal Server Error: /api/v1/router/routerRunCommand/
Internal Server Error: /api/v1/router/routerRunCommand/
Not Found: /favicon.ico
Unauthorized: /api/v1/switch/switch_run_command/
Unauthorized: /api/v1/dslam/load_dslam_ports/
Not Found: /favicon.ico
Not Found: /favicon.ico
Unauthorized: /api/v1/switch/get_backup_files_name/
Method Not Allowed: /api/v1/switch/get_backup_files_name/
Unauthorized: /api/v1/switch/get_backup_files_name/
Internal Server Error: /api/v1/switch/download_backup_file/
Traceback (most recent call last):
  File "/home/mrtbadboy/PycharmProjects/PortmanV3/venv/lib/python3.8/site-packages/django/core/handlers/exception.py", line 47, in inner
    response = get_response(request)
  File "/home/mrtbadboy/PycharmProjects/PortmanV3/venv/lib/python3.8/site-packages/django/core/handlers/base.py", line 179, in _get_response
    response = wrapped_callback(request, *callback_args, **callback_kwargs)
  File "/home/mrtbadboy/PycharmProjects/PortmanV3/venv/lib/python3.8/site-packages/django/views/decorators/csrf.py", line 54, in wrapped_view
    return view_func(*args, **kwargs)
  File "/home/mrtbadboy/PycharmProjects/PortmanV3/venv/lib/python3.8/site-packages/django/views/generic/base.py", line 70, in view
    return self.dispatch(request, *args, **kwargs)
  File "/home/mrtbadboy/PycharmProjects/PortmanV3/venv/lib/python3.8/site-packages/rest_framework/views.py", line 511, in dispatch
    self.response = self.finalize_response(request, response, *args, **kwargs)
  File "/home/mrtbadboy/PycharmProjects/PortmanV3/venv/lib/python3.8/site-packages/rest_framework/views.py", line 423, in finalize_response
    assert isinstance(response, HttpResponseBase), (
AssertionError: Expected a `Response`, `HttpResponse` or `HttpStreamingResponse` to be returned from the view, but received a `<class 'str'>`
Internal Server Error: /api/v1/switch/download_backup_file/
Traceback (most recent call last):
  File "/home/mrtbadboy/PycharmProjects/PortmanV3/venv/lib/python3.8/site-packages/django/core/handlers/exception.py", line 47, in inner
    response = get_response(request)
  File "/home/mrtbadboy/PycharmProjects/PortmanV3/venv/lib/python3.8/site-packages/django/core/handlers/base.py", line 179, in _get_response
    response = wrapped_callback(request, *callback_args, **callback_kwargs)
  File "/home/mrtbadboy/PycharmProjects/PortmanV3/venv/lib/python3.8/site-packages/django/views/decorators/csrf.py", line 54, in wrapped_view
    return view_func(*args, **kwargs)
  File "/home/mrtbadboy/PycharmProjects/PortmanV3/venv/lib/python3.8/site-packages/django/views/generic/base.py", line 70, in view
    return self.dispatch(request, *args, **kwargs)
  File "/home/mrtbadboy/PycharmProjects/PortmanV3/venv/lib/python3.8/site-packages/rest_framework/views.py", line 511, in dispatch
    self.response = self.finalize_response(request, response, *args, **kwargs)
  File "/home/mrtbadboy/PycharmProjects/PortmanV3/venv/lib/python3.8/site-packages/rest_framework/views.py", line 423, in finalize_response
    assert isinstance(response, HttpResponseBase), (
AssertionError: Expected a `Response`, `HttpResponse` or `HttpStreamingResponse` to be returned from the view, but received a `<class 'str'>`
Not Found: /
Not Found: /favicon.ico
Not Found: /favicon.ico
Internal Server Error: /api/v1/router-command/
Traceback (most recent call last):
  File "/home/mrtbadboy/PycharmProjects/PortmanV3/venv/lib/python3.8/site-packages/django/core/handlers/exception.py", line 47, in inner
    response = get_response(request)
  File "/home/mrtbadboy/PycharmProjects/PortmanV3/venv/lib/python3.8/site-packages/django/core/handlers/base.py", line 179, in _get_response
    response = wrapped_callback(request, *callback_args, **callback_kwargs)
  File "/home/mrtbadboy/PycharmProjects/PortmanV3/venv/lib/python3.8/site-packages/django/views/decorators/csrf.py", line 54, in wrapped_view
    return view_func(*args, **kwargs)
  File "/home/mrtbadboy/PycharmProjects/PortmanV3/venv/lib/python3.8/site-packages/rest_framework/viewsets.py", line 125, in view
    return self.dispatch(request, *args, **kwargs)
  File "/home/mrtbadboy/PycharmProjects/PortmanV3/venv/lib/python3.8/site-packages/rest_framework/views.py", line 509, in dispatch
    response = self.handle_exception(exc)
  File "/home/mrtbadboy/PycharmProjects/PortmanV3/venv/lib/python3.8/site-packages/rest_framework/views.py", line 469, in handle_exception
    self.raise_uncaught_exception(exc)
  File "/home/mrtbadboy/PycharmProjects/PortmanV3/venv/lib/python3.8/site-packages/rest_framework/views.py", line 480, in raise_uncaught_exception
    raise exc
  File "/home/mrtbadboy/PycharmProjects/PortmanV3/venv/lib/python3.8/site-packages/rest_framework/views.py", line 506, in dispatch
    response = handler(request, *args, **kwargs)
  File "/home/mrtbadboy/PycharmProjects/PortmanV3/venv/lib/python3.8/site-packages/rest_framework/mixins.py", line 46, in list
    return Response(serializer.data)
  File "/home/mrtbadboy/PycharmProjects/PortmanV3/venv/lib/python3.8/site-packages/rest_framework/serializers.py", line 745, in data
    ret = super().data
  File "/home/mrtbadboy/PycharmProjects/PortmanV3/venv/lib/python3.8/site-packages/rest_framework/serializers.py", line 246, in data
    self._data = self.to_representation(self.instance)
  File "/home/mrtbadboy/PycharmProjects/PortmanV3/venv/lib/python3.8/site-packages/rest_framework/serializers.py", line 663, in to_representation
    return [
  File "/home/mrtbadboy/PycharmProjects/PortmanV3/venv/lib/python3.8/site-packages/rest_framework/serializers.py", line 664, in <listcomp>
    self.child.to_representation(item) for item in iterable
  File "/home/mrtbadboy/PycharmProjects/PortmanV3/venv/lib/python3.8/site-packages/rest_framework/serializers.py", line 500, in to_representation
    for field in fields:
  File "/home/mrtbadboy/PycharmProjects/PortmanV3/venv/lib/python3.8/site-packages/rest_framework/serializers.py", line 361, in _readable_fields
    for field in self.fields.values():
  File "/home/mrtbadboy/PycharmProjects/PortmanV3/venv/lib/python3.8/site-packages/django/utils/functional.py", line 48, in __get__
    res = instance.__dict__[self.name] = self.func(instance)
  File "/home/mrtbadboy/PycharmProjects/PortmanV3/venv/lib/python3.8/site-packages/rest_framework/serializers.py", line 349, in fields
    for key, value in self.get_fields().items():
  File "/home/mrtbadboy/PycharmProjects/PortmanV3/venv/lib/python3.8/site-packages/rest_framework/serializers.py", line 1053, in get_fields
    field_class, field_kwargs = self.build_field(
  File "/home/mrtbadboy/PycharmProjects/PortmanV3/venv/lib/python3.8/site-packages/rest_framework/serializers.py", line 1199, in build_field
    return self.build_unknown_field(field_name, model_class)
  File "/home/mrtbadboy/PycharmProjects/PortmanV3/venv/lib/python3.8/site-packages/rest_framework/serializers.py", line 1317, in build_unknown_field
    raise ImproperlyConfigured(
django.core.exceptions.ImproperlyConfigured: Field name `switch_command_description` is not valid for model `RouterCommand`.
Internal Server Error: /api/v1/router-command/router_run_command/
Internal Server Error: /api/v1/router-command/router_run_command/
Internal Server Error: /api/v1/router-command/router_run_command/
Internal Server Error: /api/v1/router-command/router_run_command/
Internal Server Error: /api/v1/router-command/router_run_command/
Internal Server Error: /api/v1/router-command/router_run_command/
Internal Server Error: /api/v1/router-command/router_run_command/
Internal Server Error: /api/v1/router-command/router_run_command/
Internal Server Error: /api/v1/router-command/router_run_command/
Internal Server Error: /api/v1/router-command/router_run_command/
Internal Server Error: /api/v1/router/get_router_backup_files_name
Traceback (most recent call last):
  File "/home/mrtbadboy/PycharmProjects/PortmanV3/venv/lib/python3.8/site-packages/django/core/handlers/exception.py", line 47, in inner
    response = get_response(request)
  File "/home/mrtbadboy/PycharmProjects/PortmanV3/venv/lib/python3.8/site-packages/django/utils/deprecation.py", line 113, in __call__
    response = self.process_request(request)
  File "/home/mrtbadboy/PycharmProjects/PortmanV3/venv/lib/python3.8/site-packages/django/middleware/common.py", line 54, in process_request
    path = self.get_full_path_with_slash(request)
  File "/home/mrtbadboy/PycharmProjects/PortmanV3/venv/lib/python3.8/site-packages/django/middleware/common.py", line 87, in get_full_path_with_slash
    raise RuntimeError(
RuntimeError: You called this URL via POST, but the URL doesn't end in a slash and you have APPEND_SLASH set. Django can't redirect to the slash URL while maintaining POST data. Change your form to point to localhost:2080/api/v1/router/get_router_backup_files_name/ (note the trailing slash), or set APPEND_SLASH=False in your Django settings.
Internal Server Error: /api/v1/router-command/router_run_command/
Internal Server Error: /api/v1/router-command/router_run_command/
Internal Server Error: /api/v1/router-command/router_run_command/
Internal Server Error: /api/v1/router-command/router_run_command/
Internal Server Error: /api/v1/router-command/router_run_command/
Internal Server Error: /api/v1/router-command/router_run_command/
Internal Server Error: /api/v1/router-command/router_run_command/
Internal Server Error: /api/v1/router-command/router_run_command/
Internal Server Error: /api/v1/router-command/router_run_command/
Internal Server Error: /api/v1/router-command/router_run_command/
Method Not Allowed: /api/v1/router/routerRunCommand/
Method Not Allowed: /api/v1/router/routerRunCommand/
Method Not Allowed: /api/v1/router/routerRunCommand/
Method Not Allowed: /api/v1/router-command/routerRunCommand/
Method Not Allowed: /api/v1/router-command/routerRunCommand/
Method Not Allowed: /api/v1/router-command/routerRunCommand/
Method Not Allowed: /api/v1/router-command/routerRunCommand/
Not Found: /api/v1/router-command/routerRunCommand/
Internal Server Error: /api/v1/router-command/router_run_command/
Internal Server Error: /api/v1/router-command/router_run_command/
Internal Server Error: /api/v1/router-command/router_run_command/
Internal Server Error: /api/v1/router-command/router_run_command/
Internal Server Error: /api/v1/router-command/router_run_command/
Internal Server Error: /api/v1/router-command/router_run_command/
Internal Server Error: /api/v1/router-command/router_run_command/
Internal Server Error: /api/v1/router-command/router_run_command/
Internal Server Error: /api/v1/router-command/router_run_command/
Internal Server Error: /api/v1/router-command/router_run_command/
Internal Server Error: /api/v1/router-command/router_run_command/
Internal Server Error: /api/v1/router-command/router_run_command/
Internal Server Error: /api/v1/router-command/router_run_command/
Unauthorized: /api/v1/switch/get_backup_error_text/
Not Found: /api/v1/api/v1/router/
Bad Request: /api/v1/router/
Bad Request: /api/v1/router/
Internal Server Error: /api/v1/router/
Traceback (most recent call last):
  File "/home/mrtbadboy/PycharmProjects/PortmanV3/venv/lib/python3.8/site-packages/django/core/handlers/exception.py", line 47, in inner
    response = get_response(request)
  File "/home/mrtbadboy/PycharmProjects/PortmanV3/venv/lib/python3.8/site-packages/django/core/handlers/base.py", line 179, in _get_response
    response = wrapped_callback(request, *callback_args, **callback_kwargs)
  File "/home/mrtbadboy/PycharmProjects/PortmanV3/venv/lib/python3.8/site-packages/django/views/decorators/csrf.py", line 54, in wrapped_view
    return view_func(*args, **kwargs)
  File "/home/mrtbadboy/PycharmProjects/PortmanV3/venv/lib/python3.8/site-packages/rest_framework/viewsets.py", line 125, in view
    return self.dispatch(request, *args, **kwargs)
  File "/home/mrtbadboy/PycharmProjects/PortmanV3/venv/lib/python3.8/site-packages/rest_framework/views.py", line 509, in dispatch
    response = self.handle_exception(exc)
  File "/home/mrtbadboy/PycharmProjects/PortmanV3/venv/lib/python3.8/site-packages/rest_framework/views.py", line 469, in handle_exception
    self.raise_uncaught_exception(exc)
  File "/home/mrtbadboy/PycharmProjects/PortmanV3/venv/lib/python3.8/site-packages/rest_framework/views.py", line 480, in raise_uncaught_exception
    raise exc
  File "/home/mrtbadboy/PycharmProjects/PortmanV3/venv/lib/python3.8/site-packages/rest_framework/views.py", line 506, in dispatch
    response = handler(request, *args, **kwargs)
  File "/home/mrtbadboy/PycharmProjects/PortmanV3/venv/lib/python3.8/site-packages/rest_framework/mixins.py", line 40, in list
    page = self.paginate_queryset(queryset)
  File "/home/mrtbadboy/PycharmProjects/PortmanV3/venv/lib/python3.8/site-packages/rest_framework/generics.py", line 171, in paginate_queryset
    return self.paginator.paginate_queryset(queryset, self.request, view=self)
  File "/home/mrtbadboy/PycharmProjects/PortmanV3/venv/lib/python3.8/site-packages/rest_framework/pagination.py", line 196, in paginate_queryset
    page_size = self.get_page_size(request)
  File "/home/mrtbadboy/PycharmProjects/PortmanV3/venv/lib/python3.8/site-packages/rest_framework/pagination.py", line 257, in get_page_size
    return _positive_int(
  File "/home/mrtbadboy/PycharmProjects/PortmanV3/venv/lib/python3.8/site-packages/rest_framework/pagination.py", line 30, in _positive_int
    return min(ret, cutoff)
TypeError: '<' not supported between instances of 'builtin_function_or_method' and 'int'
Not Found: /api/v1/router/router/
Internal Server Error: /api/v1/router/
Traceback (most recent call last):
  File "/home/mrtbadboy/PycharmProjects/PortmanV3/venv/lib/python3.8/site-packages/django/core/handlers/exception.py", line 47, in inner
    response = get_response(request)
  File "/home/mrtbadboy/PycharmProjects/PortmanV3/venv/lib/python3.8/site-packages/django/core/handlers/base.py", line 179, in _get_response
    response = wrapped_callback(request, *callback_args, **callback_kwargs)
  File "/home/mrtbadboy/PycharmProjects/PortmanV3/venv/lib/python3.8/site-packages/django/views/decorators/csrf.py", line 54, in wrapped_view
    return view_func(*args, **kwargs)
  File "/home/mrtbadboy/PycharmProjects/PortmanV3/venv/lib/python3.8/site-packages/rest_framework/viewsets.py", line 125, in view
    return self.dispatch(request, *args, **kwargs)
  File "/home/mrtbadboy/PycharmProjects/PortmanV3/venv/lib/python3.8/site-packages/rest_framework/views.py", line 509, in dispatch
    response = self.handle_exception(exc)
  File "/home/mrtbadboy/PycharmProjects/PortmanV3/venv/lib/python3.8/site-packages/rest_framework/views.py", line 469, in handle_exception
    self.raise_uncaught_exception(exc)
  File "/home/mrtbadboy/PycharmProjects/PortmanV3/venv/lib/python3.8/site-packages/rest_framework/views.py", line 480, in raise_uncaught_exception
    raise exc
  File "/home/mrtbadboy/PycharmProjects/PortmanV3/venv/lib/python3.8/site-packages/rest_framework/views.py", line 506, in dispatch
    response = handler(request, *args, **kwargs)
  File "/home/mrtbadboy/PycharmProjects/PortmanV3/venv/lib/python3.8/site-packages/rest_framework/mixins.py", line 40, in list
    page = self.paginate_queryset(queryset)
  File "/home/mrtbadboy/PycharmProjects/PortmanV3/venv/lib/python3.8/site-packages/rest_framework/generics.py", line 171, in paginate_queryset
    return self.paginator.paginate_queryset(queryset, self.request, view=self)
  File "/home/mrtbadboy/PycharmProjects/PortmanV3/venv/lib/python3.8/site-packages/rest_framework/pagination.py", line 196, in paginate_queryset
    page_size = self.get_page_size(request)
  File "/home/mrtbadboy/PycharmProjects/PortmanV3/venv/lib/python3.8/site-packages/rest_framework/pagination.py", line 257, in get_page_size
    return _positive_int(
  File "/home/mrtbadboy/PycharmProjects/PortmanV3/venv/lib/python3.8/site-packages/rest_framework/pagination.py", line 30, in _positive_int
    return min(ret, cutoff)
TypeError: '<' not supported between instances of 'builtin_function_or_method' and 'int'
Internal Server Error: /api/v1/router
Traceback (most recent call last):
  File "/home/mrtbadboy/PycharmProjects/PortmanV3/venv/lib/python3.8/site-packages/django/core/handlers/exception.py", line 47, in inner
    response = get_response(request)
  File "/home/mrtbadboy/PycharmProjects/PortmanV3/venv/lib/python3.8/site-packages/django/utils/deprecation.py", line 113, in __call__
    response = self.process_request(request)
  File "/home/mrtbadboy/PycharmProjects/PortmanV3/venv/lib/python3.8/site-packages/django/middleware/common.py", line 54, in process_request
    path = self.get_full_path_with_slash(request)
  File "/home/mrtbadboy/PycharmProjects/PortmanV3/venv/lib/python3.8/site-packages/django/middleware/common.py", line 87, in get_full_path_with_slash
    raise RuntimeError(
RuntimeError: You called this URL via POST, but the URL doesn't end in a slash and you have APPEND_SLASH set. Django can't redirect to the slash URL while maintaining POST data. Change your form to point to localhost:2080/api/v1/router/?page=1&page_size=10 (note the trailing slash), or set APPEND_SLASH=False in your Django settings.
Bad Request: /api/v1/router/
Bad Request: /api/v1/router/
Bad Request: /api/v1/router/
Bad Request: /api/v1/router/
Bad Request: /api/v1/router/
Bad Request: /api/v1/router/
Bad Request: /api/v1/router/
Bad Request: /api/v1/router/
Bad Request: /api/v1/router/
Bad Request: /api/v1/switch/
Bad Request: /api/v1/switch/
Unauthorized: /api/v1/switch/get_backup_error_file/
Method Not Allowed: /api/v1/switch-command/
Unauthorized: /api/v1/switch/get_backup_error_file/
Method Not Allowed: /api/v1/switch/get_backup_error_file/
Method Not Allowed: /api/v1/switch-command/switch_run_command/
Not Found: /api/v1/switch-command/switch_run_command/
Not Found: /api/v1/api/v1/switch/switch_run_command/
Not Found: /favicon.ico
Internal Server Error: /admin/router/routercommand/
Traceback (most recent call last):
  File "/home/mrtbadboy/PycharmProjects/PortmanV3/venv/lib/python3.8/site-packages/django/core/handlers/exception.py", line 47, in inner
    response = get_response(request)
  File "/home/mrtbadboy/PycharmProjects/PortmanV3/venv/lib/python3.8/site-packages/django/core/handlers/base.py", line 179, in _get_response
    response = wrapped_callback(request, *callback_args, **callback_kwargs)
  File "/home/mrtbadboy/PycharmProjects/PortmanV3/venv/lib/python3.8/site-packages/django/contrib/admin/options.py", line 614, in wrapper
    return self.admin_site.admin_view(view)(*args, **kwargs)
  File "/home/mrtbadboy/PycharmProjects/PortmanV3/venv/lib/python3.8/site-packages/django/utils/decorators.py", line 130, in _wrapped_view
    response = view_func(request, *args, **kwargs)
  File "/home/mrtbadboy/PycharmProjects/PortmanV3/venv/lib/python3.8/site-packages/django/views/decorators/cache.py", line 44, in _wrapped_view_func
    response = view_func(request, *args, **kwargs)
  File "/home/mrtbadboy/PycharmProjects/PortmanV3/venv/lib/python3.8/site-packages/django/contrib/admin/sites.py", line 233, in inner
    return view(request, *args, **kwargs)
  File "/home/mrtbadboy/PycharmProjects/PortmanV3/venv/lib/python3.8/site-packages/django/utils/decorators.py", line 43, in _wrapper
    return bound_method(*args, **kwargs)
  File "/home/mrtbadboy/PycharmProjects/PortmanV3/venv/lib/python3.8/site-packages/django/utils/decorators.py", line 130, in _wrapped_view
    response = view_func(request, *args, **kwargs)
  File "/home/mrtbadboy/PycharmProjects/PortmanV3/venv/lib/python3.8/site-packages/django/contrib/admin/options.py", line 1693, in changelist_view
    cl = self.get_changelist_instance(request)
  File "/home/mrtbadboy/PycharmProjects/PortmanV3/venv/lib/python3.8/site-packages/django/contrib/admin/options.py", line 735, in get_changelist_instance
    return ChangeList(
  File "/home/mrtbadboy/PycharmProjects/PortmanV3/venv/lib/python3.8/site-packages/django/contrib/admin/views/main.py", line 99, in __init__
    self.queryset = self.get_queryset(request)
  File "/home/mrtbadboy/PycharmProjects/PortmanV3/venv/lib/python3.8/site-packages/django/contrib/admin/views/main.py", line 483, in get_queryset
    qs, search_use_distinct = self.model_admin.get_search_results(request, qs, self.query)
  File "/home/mrtbadboy/PycharmProjects/PortmanV3/venv/lib/python3.8/site-packages/django/contrib/admin/options.py", line 1028, in get_search_results
    queryset = queryset.filter(reduce(operator.or_, or_queries))
  File "/home/mrtbadboy/PycharmProjects/PortmanV3/venv/lib/python3.8/site-packages/django/db/models/query.py", line 942, in filter
    return self._filter_or_exclude(False, *args, **kwargs)
  File "/home/mrtbadboy/PycharmProjects/PortmanV3/venv/lib/python3.8/site-packages/django/db/models/query.py", line 962, in _filter_or_exclude
    clone._filter_or_exclude_inplace(negate, *args, **kwargs)
  File "/home/mrtbadboy/PycharmProjects/PortmanV3/venv/lib/python3.8/site-packages/django/db/models/query.py", line 969, in _filter_or_exclude_inplace
    self._query.add_q(Q(*args, **kwargs))
  File "/home/mrtbadboy/PycharmProjects/PortmanV3/venv/lib/python3.8/site-packages/django/db/models/sql/query.py", line 1358, in add_q
    clause, _ = self._add_q(q_object, self.used_aliases)
  File "/home/mrtbadboy/PycharmProjects/PortmanV3/venv/lib/python3.8/site-packages/django/db/models/sql/query.py", line 1377, in _add_q
    child_clause, needed_inner = self.build_filter(
  File "/home/mrtbadboy/PycharmProjects/PortmanV3/venv/lib/python3.8/site-packages/django/db/models/sql/query.py", line 1237, in build_filter
    return self._add_q(
  File "/home/mrtbadboy/PycharmProjects/PortmanV3/venv/lib/python3.8/site-packages/django/db/models/sql/query.py", line 1377, in _add_q
    child_clause, needed_inner = self.build_filter(
  File "/home/mrtbadboy/PycharmProjects/PortmanV3/venv/lib/python3.8/site-packages/django/db/models/sql/query.py", line 1319, in build_filter
    condition = self.build_lookup(lookups, col, value)
  File "/home/mrtbadboy/PycharmProjects/PortmanV3/venv/lib/python3.8/site-packages/django/db/models/sql/query.py", line 1156, in build_lookup
    raise FieldError('Related Field got invalid lookup: {}'.format(lookup_name))
django.core.exceptions.FieldError: Related Field got invalid lookup: icontains
Internal Server Error: /admin/router/routercommand/
Traceback (most recent call last):
  File "/home/mrtbadboy/PycharmProjects/PortmanV3/venv/lib/python3.8/site-packages/django/core/handlers/exception.py", line 47, in inner
    response = get_response(request)
  File "/home/mrtbadboy/PycharmProjects/PortmanV3/venv/lib/python3.8/site-packages/django/core/handlers/base.py", line 179, in _get_response
    response = wrapped_callback(request, *callback_args, **callback_kwargs)
  File "/home/mrtbadboy/PycharmProjects/PortmanV3/venv/lib/python3.8/site-packages/django/contrib/admin/options.py", line 614, in wrapper
    return self.admin_site.admin_view(view)(*args, **kwargs)
  File "/home/mrtbadboy/PycharmProjects/PortmanV3/venv/lib/python3.8/site-packages/django/utils/decorators.py", line 130, in _wrapped_view
    response = view_func(request, *args, **kwargs)
  File "/home/mrtbadboy/PycharmProjects/PortmanV3/venv/lib/python3.8/site-packages/django/views/decorators/cache.py", line 44, in _wrapped_view_func
    response = view_func(request, *args, **kwargs)
  File "/home/mrtbadboy/PycharmProjects/PortmanV3/venv/lib/python3.8/site-packages/django/contrib/admin/sites.py", line 233, in inner
    return view(request, *args, **kwargs)
  File "/home/mrtbadboy/PycharmProjects/PortmanV3/venv/lib/python3.8/site-packages/django/utils/decorators.py", line 43, in _wrapper
    return bound_method(*args, **kwargs)
  File "/home/mrtbadboy/PycharmProjects/PortmanV3/venv/lib/python3.8/site-packages/django/utils/decorators.py", line 130, in _wrapped_view
    response = view_func(request, *args, **kwargs)
  File "/home/mrtbadboy/PycharmProjects/PortmanV3/venv/lib/python3.8/site-packages/django/contrib/admin/options.py", line 1693, in changelist_view
    cl = self.get_changelist_instance(request)
  File "/home/mrtbadboy/PycharmProjects/PortmanV3/venv/lib/python3.8/site-packages/django/contrib/admin/options.py", line 735, in get_changelist_instance
    return ChangeList(
  File "/home/mrtbadboy/PycharmProjects/PortmanV3/venv/lib/python3.8/site-packages/django/contrib/admin/views/main.py", line 99, in __init__
    self.queryset = self.get_queryset(request)
  File "/home/mrtbadboy/PycharmProjects/PortmanV3/venv/lib/python3.8/site-packages/django/contrib/admin/views/main.py", line 483, in get_queryset
    qs, search_use_distinct = self.model_admin.get_search_results(request, qs, self.query)
  File "/home/mrtbadboy/PycharmProjects/PortmanV3/venv/lib/python3.8/site-packages/django/contrib/admin/options.py", line 1028, in get_search_results
    queryset = queryset.filter(reduce(operator.or_, or_queries))
  File "/home/mrtbadboy/PycharmProjects/PortmanV3/venv/lib/python3.8/site-packages/django/db/models/query.py", line 942, in filter
    return self._filter_or_exclude(False, *args, **kwargs)
  File "/home/mrtbadboy/PycharmProjects/PortmanV3/venv/lib/python3.8/site-packages/django/db/models/query.py", line 962, in _filter_or_exclude
    clone._filter_or_exclude_inplace(negate, *args, **kwargs)
  File "/home/mrtbadboy/PycharmProjects/PortmanV3/venv/lib/python3.8/site-packages/django/db/models/query.py", line 969, in _filter_or_exclude_inplace
    self._query.add_q(Q(*args, **kwargs))
  File "/home/mrtbadboy/PycharmProjects/PortmanV3/venv/lib/python3.8/site-packages/django/db/models/sql/query.py", line 1358, in add_q
    clause, _ = self._add_q(q_object, self.used_aliases)
  File "/home/mrtbadboy/PycharmProjects/PortmanV3/venv/lib/python3.8/site-packages/django/db/models/sql/query.py", line 1377, in _add_q
    child_clause, needed_inner = self.build_filter(
  File "/home/mrtbadboy/PycharmProjects/PortmanV3/venv/lib/python3.8/site-packages/django/db/models/sql/query.py", line 1237, in build_filter
    return self._add_q(
  File "/home/mrtbadboy/PycharmProjects/PortmanV3/venv/lib/python3.8/site-packages/django/db/models/sql/query.py", line 1377, in _add_q
    child_clause, needed_inner = self.build_filter(
  File "/home/mrtbadboy/PycharmProjects/PortmanV3/venv/lib/python3.8/site-packages/django/db/models/sql/query.py", line 1319, in build_filter
    condition = self.build_lookup(lookups, col, value)
  File "/home/mrtbadboy/PycharmProjects/PortmanV3/venv/lib/python3.8/site-packages/django/db/models/sql/query.py", line 1156, in build_lookup
    raise FieldError('Related Field got invalid lookup: {}'.format(lookup_name))
django.core.exceptions.FieldError: Related Field got invalid lookup: icontains
Internal Server Error: /admin/router/routercommand/
Traceback (most recent call last):
  File "/home/mrtbadboy/PycharmProjects/PortmanV3/venv/lib/python3.8/site-packages/django/core/handlers/exception.py", line 47, in inner
    response = get_response(request)
  File "/home/mrtbadboy/PycharmProjects/PortmanV3/venv/lib/python3.8/site-packages/django/core/handlers/base.py", line 179, in _get_response
    response = wrapped_callback(request, *callback_args, **callback_kwargs)
  File "/home/mrtbadboy/PycharmProjects/PortmanV3/venv/lib/python3.8/site-packages/django/contrib/admin/options.py", line 614, in wrapper
    return self.admin_site.admin_view(view)(*args, **kwargs)
  File "/home/mrtbadboy/PycharmProjects/PortmanV3/venv/lib/python3.8/site-packages/django/utils/decorators.py", line 130, in _wrapped_view
    response = view_func(request, *args, **kwargs)
  File "/home/mrtbadboy/PycharmProjects/PortmanV3/venv/lib/python3.8/site-packages/django/views/decorators/cache.py", line 44, in _wrapped_view_func
    response = view_func(request, *args, **kwargs)
  File "/home/mrtbadboy/PycharmProjects/PortmanV3/venv/lib/python3.8/site-packages/django/contrib/admin/sites.py", line 233, in inner
    return view(request, *args, **kwargs)
  File "/home/mrtbadboy/PycharmProjects/PortmanV3/venv/lib/python3.8/site-packages/django/utils/decorators.py", line 43, in _wrapper
    return bound_method(*args, **kwargs)
  File "/home/mrtbadboy/PycharmProjects/PortmanV3/venv/lib/python3.8/site-packages/django/utils/decorators.py", line 130, in _wrapped_view
    response = view_func(request, *args, **kwargs)
  File "/home/mrtbadboy/PycharmProjects/PortmanV3/venv/lib/python3.8/site-packages/django/contrib/admin/options.py", line 1693, in changelist_view
    cl = self.get_changelist_instance(request)
  File "/home/mrtbadboy/PycharmProjects/PortmanV3/venv/lib/python3.8/site-packages/django/contrib/admin/options.py", line 735, in get_changelist_instance
    return ChangeList(
  File "/home/mrtbadboy/PycharmProjects/PortmanV3/venv/lib/python3.8/site-packages/django/contrib/admin/views/main.py", line 99, in __init__
    self.queryset = self.get_queryset(request)
  File "/home/mrtbadboy/PycharmProjects/PortmanV3/venv/lib/python3.8/site-packages/django/contrib/admin/views/main.py", line 483, in get_queryset
    qs, search_use_distinct = self.model_admin.get_search_results(request, qs, self.query)
  File "/home/mrtbadboy/PycharmProjects/PortmanV3/venv/lib/python3.8/site-packages/django/contrib/admin/options.py", line 1028, in get_search_results
    queryset = queryset.filter(reduce(operator.or_, or_queries))
  File "/home/mrtbadboy/PycharmProjects/PortmanV3/venv/lib/python3.8/site-packages/django/db/models/query.py", line 942, in filter
    return self._filter_or_exclude(False, *args, **kwargs)
  File "/home/mrtbadboy/PycharmProjects/PortmanV3/venv/lib/python3.8/site-packages/django/db/models/query.py", line 962, in _filter_or_exclude
    clone._filter_or_exclude_inplace(negate, *args, **kwargs)
  File "/home/mrtbadboy/PycharmProjects/PortmanV3/venv/lib/python3.8/site-packages/django/db/models/query.py", line 969, in _filter_or_exclude_inplace
    self._query.add_q(Q(*args, **kwargs))
  File "/home/mrtbadboy/PycharmProjects/PortmanV3/venv/lib/python3.8/site-packages/django/db/models/sql/query.py", line 1358, in add_q
    clause, _ = self._add_q(q_object, self.used_aliases)
  File "/home/mrtbadboy/PycharmProjects/PortmanV3/venv/lib/python3.8/site-packages/django/db/models/sql/query.py", line 1377, in _add_q
    child_clause, needed_inner = self.build_filter(
  File "/home/mrtbadboy/PycharmProjects/PortmanV3/venv/lib/python3.8/site-packages/django/db/models/sql/query.py", line 1237, in build_filter
    return self._add_q(
  File "/home/mrtbadboy/PycharmProjects/PortmanV3/venv/lib/python3.8/site-packages/django/db/models/sql/query.py", line 1377, in _add_q
    child_clause, needed_inner = self.build_filter(
  File "/home/mrtbadboy/PycharmProjects/PortmanV3/venv/lib/python3.8/site-packages/django/db/models/sql/query.py", line 1319, in build_filter
    condition = self.build_lookup(lookups, col, value)
  File "/home/mrtbadboy/PycharmProjects/PortmanV3/venv/lib/python3.8/site-packages/django/db/models/sql/query.py", line 1156, in build_lookup
    raise FieldError('Related Field got invalid lookup: {}'.format(lookup_name))
django.core.exceptions.FieldError: Related Field got invalid lookup: icontains
Not Found: /
Internal Server Error: /api/v1/user/send_reset_password_link/
Internal Server Error: /api/v1/user/send_reset_password_link/
Internal Server Error: /api/v1/user/send_reset_password_link/
Unauthorized: /api/v1/user/send_reset_password_link/
Unauthorized: /api/v1/user/send_reset_password_link/
Unauthorized: /api/v1/user/send_reset_password_link/
Unauthorized: /api/v1/user/send_reset_password_link/
Unauthorized: /api/v1/users/send_reset_password_link/
Unauthorized: /api/v1/users/send_reset_password_link/
Unauthorized: /api/v1/users/send_reset_password_link/
Unauthorized: /api/v1/users/login/
Unauthorized: /api/v1/users/send_reset_password_link/
Method Not Allowed: /api/v1/users/send_reset_password_link/
Method Not Allowed: /api/v1/users/send_reset_password_link/
Method Not Allowed: /api/v1/users/send_reset_password_link/
Internal Server Error: /api/v1/dslamport/get_port_count/
Internal Server Error: /api/v1/router-command/router_run_command/
Internal Server Error: /api/v1/router-command/router_run_command/
Internal Server Error: /api/v1/router-command/router_run_command/
Internal Server Error: /api/v1/router-command/router_run_command/
Internal Server Error: /api/v1/router-command/router_run_command/
Internal Server Error: /api/v1/router-command/router_run_command/
Internal Server Error: /api/v1/router-command/router_run_command/
Internal Server Error: /api/v1/router-command/router_run_command/
Internal Server Error: /api/v1/router-command/router_run_command/
Internal Server Error: /api/v1/router-command/router_run_command/
Not Found: /favicon.ico
Internal Server Error: /api/v1/router-command/router_run_command/
Internal Server Error: /api/v1/router-command/router_run_command/
Internal Server Error: /api/v1/router-command/router_run_command/
Internal Server Error: /api/v1/router-command/router_run_command/
Internal Server Error: /api/v1/router-command/router_run_command/
Internal Server Error: /api/v1/router-command/router_run_command/
Internal Server Error: /api/v1/router-command/router_run_command/
Internal Server Error: /api/v1/router-command/router_run_command/
Internal Server Error: /api/v1/router-command/router_run_command/
Internal Server Error: /api/v1/router-command/router_run_command/
Not Found: /api/v1/router-comm/read_router_backup_error_files_name/
Method Not Allowed: /api/v1/router-command/read_router_backup_error_files_name/
Not Found: /favicon.ico
Not Found: /static/rest_framework/img/grid.png
<<<<<<< HEAD
Unauthorized: /api/v1/dslamport/fiberHomeCommand/
Unauthorized: /api/v1/dslamport/fiberHomeCommand/
Internal Server Error: /api/v1/dslamport/fiberHomeCommand/
Traceback (most recent call last):
  File "/home/sajad/.local/lib/python3.8/site-packages/django/core/handlers/exception.py", line 47, in inner
    response = get_response(request)
  File "/home/sajad/.local/lib/python3.8/site-packages/django/core/handlers/base.py", line 181, in _get_response
    response = wrapped_callback(request, *callback_args, **callback_kwargs)
  File "/home/sajad/.local/lib/python3.8/site-packages/django/views/decorators/csrf.py", line 54, in wrapped_view
    return view_func(*args, **kwargs)
  File "/home/sajad/.local/lib/python3.8/site-packages/django/views/generic/base.py", line 70, in view
    return self.dispatch(request, *args, **kwargs)
  File "/home/sajad/.local/lib/python3.8/site-packages/rest_framework/views.py", line 511, in dispatch
    self.response = self.finalize_response(request, response, *args, **kwargs)
  File "/home/sajad/.local/lib/python3.8/site-packages/rest_framework/views.py", line 423, in finalize_response
    assert isinstance(response, HttpResponseBase), (
AssertionError: Expected a `Response`, `HttpResponse` or `HttpStreamingResponse` to be returned from the view, but received a `<class 'NoneType'>`
Internal Server Error: /api/v1/dslamport/fiberHomeCommand/
Traceback (most recent call last):
  File "/home/sajad/.local/lib/python3.8/site-packages/django/core/handlers/exception.py", line 47, in inner
    response = get_response(request)
  File "/home/sajad/.local/lib/python3.8/site-packages/django/core/handlers/base.py", line 181, in _get_response
    response = wrapped_callback(request, *callback_args, **callback_kwargs)
  File "/home/sajad/.local/lib/python3.8/site-packages/django/views/decorators/csrf.py", line 54, in wrapped_view
    return view_func(*args, **kwargs)
  File "/home/sajad/.local/lib/python3.8/site-packages/django/views/generic/base.py", line 70, in view
    return self.dispatch(request, *args, **kwargs)
  File "/home/sajad/.local/lib/python3.8/site-packages/rest_framework/views.py", line 511, in dispatch
    self.response = self.finalize_response(request, response, *args, **kwargs)
  File "/home/sajad/.local/lib/python3.8/site-packages/rest_framework/views.py", line 423, in finalize_response
    assert isinstance(response, HttpResponseBase), (
AssertionError: Expected a `Response`, `HttpResponse` or `HttpStreamingResponse` to be returned from the view, but received a `<class 'NoneType'>`
=======
Unauthorized: /api/v1/router-command/read_router_backup_error_files_name/
Unauthorized: /api/v1/router-command/read_router_backup_error_files_name/
Method Not Allowed: /api/v1/router-command/read_switch_backup_error_files_name/
<<<<<<< HEAD
>>>>>>> a26ad516fe168ce1abe69c5b0cfe68a75d108bb2
Unauthorized: /api/v1/dslamport/fiberHomeCommand/
Unauthorized: /api/v1/dslamport/fiberHomeCommand/
Unauthorized: /api/v1/dslamport/fiberHomeCommand/
=======
Not Found: /static/rest_framework/css/bootstrap.min.css
Not Found: /static/rest_framework/css/bootstrap-tweaks.css
Not Found: /static/rest_framework/css/default.css
Not Found: /static/rest_framework/css/prettify.css
Not Found: /favicon.ico
Not Found: /static/admin-lte/dist/img/avatar5.png
Not Found: /static/admin-lte/dist/img/AdminLTELogo.png
Not Found: /static/admin-lte/plugins/fontawesome-free/css/all.min.css
Not Found: /static/admin-lte/plugins/icheck-bootstrap/icheck-bootstrap.min.css
Not Found: /static/admin/css/base.css
Not Found: /static/admin-lte/dist/css/adminlte.min.css
Not Found: /static/admin-lte/plugins/jquery/jquery.min.js
Not Found: /static/admin-lte/plugins/jquery-ui/jquery-ui.min.js
Not Found: /static/admin-lte/plugins/bootstrap/js/bootstrap.bundle.min.js
Not Found: /static/admin-lte/dist/js/adminlte.min.js
Not Found: /static/admin-lte/dist/js/demo.js
Not Found: /static/admin-lte/plugins/jquery-ui/jquery-ui.min.js
Not Found: /static/admin-lte/plugins/bootstrap/js/bootstrap.bundle.min.js
Not Found: /static/admin-lte/dist/js/adminlte.min.js
Not Found: /static/admin-lte/dist/js/demo.js
Not Found: /static/admin-lte/plugins/fontawesome-free/css/all.min.css
Not Found: /static/admin-lte/plugins/icheck-bootstrap/icheck-bootstrap.min.css
Not Found: /static/admin/css/base.css
Not Found: /static/admin-lte/dist/css/adminlte.min.css
Not Found: /static/admin-lte/plugins/jquery/jquery.min.js
Not Found: /static/admin-lte/dist/img/AdminLTELogo.png
Not Found: /static/admin-lte/plugins/bootstrap/js/bootstrap.bundle.min.js
Not Found: /static/admin-lte/dist/img/avatar5.png
Not Found: /static/admin-lte/plugins/jquery-ui/jquery-ui.min.js
Not Found: /static/admin-lte/dist/js/demo.js
Not Found: /static/admin-lte/dist/js/adminlte.min.js
Not Found: /static/admin-lte/dist/js/adminlte.min.js
Not Found: /static/admin-lte/dist/js/demo.js
Not Found: /static/admin-lte/plugins/fontawesome-free/css/all.min.css
Not Found: /static/admin/css/base.css
Not Found: /static/admin-lte/plugins/icheck-bootstrap/icheck-bootstrap.min.css
Not Found: /static/admin-lte/dist/css/adminlte.min.css
Not Found: /static/admin/css/changelists.css
Not Found: /static/admin/js/vendor/jquery/jquery.min.js
Not Found: /static/admin/js/jquery.init.js
Not Found: /static/admin/js/urlify.js
Not Found: /static/admin/js/core.js
Not Found: /static/admin/js/admin/RelatedObjectLookups.js
Not Found: /static/admin/js/actions.min.js
Not Found: /static/admin/js/prepopulate.min.js
Not Found: /static/admin/js/vendor/xregexp/xregexp.min.js
Not Found: /static/admin-lte/plugins/jquery/jquery.min.js
Not Found: /static/admin-lte/plugins/jquery-ui/jquery-ui.min.js
Not Found: /static/admin-lte/plugins/datatables-bs4/css/dataTables.bootstrap4.css
Not Found: /static/admin-lte/plugins/bootstrap/js/bootstrap.bundle.min.js
Not Found: /static/admin-lte/dist/js/adminlte.min.js
Not Found: /static/admin-lte/dist/js/demo.js
Not Found: /static/admin-lte/plugins/datatables-bs4/js/dataTables.bootstrap4.js
Not Found: /static/admin-lte/plugins/datatables/jquery.dataTables.js
Not Found: /static/admin-lte/dist/img/avatar5.png
Not Found: /static/admin-lte/dist/img/AdminLTELogo.png
Not Found: /static/admin/js/vendor/jquery/jquery.min.js
Not Found: /static/admin/js/jquery.init.js
Not Found: /static/admin/js/core.js
Not Found: /static/admin/js/admin/RelatedObjectLookups.js
Not Found: /static/admin/js/actions.min.js
Not Found: /static/admin/js/urlify.js
Not Found: /static/admin/js/prepopulate.min.js
Not Found: /static/admin/js/vendor/xregexp/xregexp.min.js
Not Found: /static/admin-lte/dist/img/avatar5.png
Not Found: /static/admin-lte/dist/img/AdminLTELogo.png
Not Found: /static/admin-lte/plugins/datatables-bs4/css/dataTables.bootstrap4.css
Not Found: /static/admin-lte/plugins/jquery/jquery.min.js
Not Found: /static/admin-lte/plugins/jquery-ui/jquery-ui.min.js
Not Found: /static/admin-lte/plugins/bootstrap/js/bootstrap.bundle.min.js
Not Found: /static/admin-lte/dist/js/adminlte.min.js
Not Found: /static/admin-lte/dist/js/demo.js
Not Found: /static/admin-lte/plugins/datatables/jquery.dataTables.js
Not Found: /static/admin-lte/plugins/datatables-bs4/js/dataTables.bootstrap4.js
Not Found: /static/rest_framework/css/bootstrap.min.css
Not Found: /static/rest_framework/css/prettify.css
Not Found: /static/rest_framework/css/bootstrap-tweaks.css
Not Found: /static/rest_framework/css/default.css
Not Found: /favicon.ico
Not Found: /static/admin-lte/dist/img/avatar5.png
Not Found: /static/admin-lte/dist/img/AdminLTELogo.png
Not Found: /static/admin-lte/plugins/fontawesome-free/css/all.min.css
Not Found: /static/admin-lte/dist/css/adminlte.min.css
Not Found: /static/admin-lte/plugins/jquery/jquery.min.js
Not Found: /static/admin-lte/plugins/icheck-bootstrap/icheck-bootstrap.min.css
Not Found: /static/admin-lte/dist/js/adminlte.min.js
Not Found: /static/admin/css/base.css
Not Found: /static/admin-lte/dist/js/demo.js
Not Found: /static/admin-lte/plugins/bootstrap/js/bootstrap.bundle.min.js
Not Found: /static/admin-lte/plugins/jquery-ui/jquery-ui.min.js
Not Found: /static/admin-lte/plugins/jquery-ui/jquery-ui.min.js
Not Found: /static/admin-lte/plugins/bootstrap/js/bootstrap.bundle.min.js
Not Found: /static/admin-lte/dist/js/adminlte.min.js
Not Found: /static/admin-lte/dist/js/demo.js
Not Found: /static/admin-lte/plugins/fontawesome-free/css/all.min.css
Not Found: /static/admin-lte/dist/css/adminlte.min.css
Not Found: /static/admin-lte/plugins/icheck-bootstrap/icheck-bootstrap.min.css
Not Found: /static/admin/css/base.css
Not Found: /static/admin/js/vendor/jquery/jquery.min.js
Not Found: /static/admin/js/actions.min.js
Not Found: /static/admin/js/vendor/xregexp/xregexp.min.js
Not Found: /static/admin/js/prepopulate.min.js
Not Found: /static/admin-lte/plugins/jquery/jquery.min.js
Not Found: /static/admin-lte/plugins/jquery-ui/jquery-ui.min.js
Not Found: /static/admin-lte/plugins/bootstrap/js/bootstrap.bundle.min.js
Not Found: /static/admin-lte/dist/js/adminlte.min.js
Not Found: /static/admin-lte/dist/js/demo.js
Not Found: /static/admin/js/jquery.init.js
Not Found: /static/admin/css/changelists.css
Not Found: /static/admin/js/core.js
Not Found: /static/admin/js/admin/RelatedObjectLookups.js
Not Found: /static/admin/js/urlify.js
Not Found: /static/admin-lte/plugins/datatables-bs4/css/dataTables.bootstrap4.css
Not Found: /static/admin-lte/plugins/datatables/jquery.dataTables.js
Not Found: /static/admin-lte/plugins/datatables-bs4/js/dataTables.bootstrap4.js
Not Found: /static/admin-lte/dist/img/avatar5.png
Not Found: /static/admin-lte/dist/img/AdminLTELogo.png
Not Found: /static/admin/js/vendor/jquery/jquery.min.js
Not Found: /static/admin/js/jquery.init.js
Not Found: /static/admin/js/core.js
Not Found: /static/admin/js/admin/RelatedObjectLookups.js
Not Found: /static/admin/js/actions.min.js
Not Found: /static/admin/js/urlify.js
Not Found: /static/admin/js/prepopulate.min.js
Not Found: /static/admin/js/vendor/xregexp/xregexp.min.js
Not Found: /static/admin-lte/dist/img/avatar5.png
Not Found: /static/admin-lte/dist/img/AdminLTELogo.png
Not Found: /static/admin-lte/plugins/datatables-bs4/css/dataTables.bootstrap4.css
Not Found: /static/admin-lte/plugins/jquery/jquery.min.js
Not Found: /static/admin-lte/plugins/jquery-ui/jquery-ui.min.js
Not Found: /static/admin-lte/plugins/bootstrap/js/bootstrap.bundle.min.js
Not Found: /static/admin-lte/dist/js/adminlte.min.js
Not Found: /static/admin-lte/dist/js/demo.js
Not Found: /static/admin-lte/plugins/datatables/jquery.dataTables.js
Not Found: /static/admin-lte/plugins/datatables-bs4/js/dataTables.bootstrap4.js
Not Found: /
Not Found: /
Not Found: /static/admin-lte/plugins/fontawesome-free/css/all.min.css
Not Found: /static/admin-lte/dist/css/adminlte.min.css
Not Found: /static/admin-lte/plugins/icheck-bootstrap/icheck-bootstrap.min.css
Not Found: /static/admin/css/base.css
Not Found: /static/admin-lte/plugins/jquery-ui/jquery-ui.min.js
Not Found: /static/admin-lte/plugins/bootstrap/js/bootstrap.bundle.min.js
Not Found: /static/admin-lte/plugins/jquery/jquery.min.js
Not Found: /static/admin-lte/dist/img/avatar5.png
Not Found: /static/admin-lte/dist/js/adminlte.min.js
Not Found: /static/admin-lte/dist/img/AdminLTELogo.png
Not Found: /static/admin-lte/dist/js/demo.js
Not Found: /static/admin-lte/plugins/bootstrap/js/bootstrap.bundle.min.js
Not Found: /static/admin-lte/dist/js/adminlte.min.js
Not Found: /static/admin-lte/dist/js/demo.js
Not Found: /
Unauthorized: /api/v1/router/get_router_backup_files_name/
Unauthorized: /api/v1/router/get_router_backup_files_name/
Internal Server Error: /api/v1/router/get_router_backup_files_name/
Traceback (most recent call last):
  File "/home/mrtbadboy/PycharmProjects/PortmanV3/venv/lib/python3.8/site-packages/django/core/handlers/exception.py", line 47, in inner
    response = get_response(request)
  File "/home/mrtbadboy/PycharmProjects/PortmanV3/venv/lib/python3.8/site-packages/django/core/handlers/base.py", line 179, in _get_response
    response = wrapped_callback(request, *callback_args, **callback_kwargs)
  File "/home/mrtbadboy/PycharmProjects/PortmanV3/venv/lib/python3.8/site-packages/django/views/decorators/csrf.py", line 54, in wrapped_view
    return view_func(*args, **kwargs)
  File "/home/mrtbadboy/PycharmProjects/PortmanV3/venv/lib/python3.8/site-packages/django/views/generic/base.py", line 70, in view
    return self.dispatch(request, *args, **kwargs)
  File "/home/mrtbadboy/PycharmProjects/PortmanV3/venv/lib/python3.8/site-packages/rest_framework/views.py", line 511, in dispatch
    self.response = self.finalize_response(request, response, *args, **kwargs)
  File "/home/mrtbadboy/PycharmProjects/PortmanV3/venv/lib/python3.8/site-packages/rest_framework/views.py", line 423, in finalize_response
    assert isinstance(response, HttpResponseBase), (
AssertionError: Expected a `Response`, `HttpResponse` or `HttpStreamingResponse` to be returned from the view, but received a `<class 'list'>`
Not Found: /favicon.ico
Internal Server Error: /api/v1/router/get_router_backup_files_name/
Traceback (most recent call last):
  File "/home/mrtbadboy/PycharmProjects/PortmanV3/venv/lib/python3.8/site-packages/django/core/handlers/exception.py", line 47, in inner
    response = get_response(request)
  File "/home/mrtbadboy/PycharmProjects/PortmanV3/venv/lib/python3.8/site-packages/django/core/handlers/base.py", line 179, in _get_response
    response = wrapped_callback(request, *callback_args, **callback_kwargs)
  File "/home/mrtbadboy/PycharmProjects/PortmanV3/venv/lib/python3.8/site-packages/django/views/decorators/csrf.py", line 54, in wrapped_view
    return view_func(*args, **kwargs)
  File "/home/mrtbadboy/PycharmProjects/PortmanV3/venv/lib/python3.8/site-packages/django/views/generic/base.py", line 70, in view
    return self.dispatch(request, *args, **kwargs)
  File "/home/mrtbadboy/PycharmProjects/PortmanV3/venv/lib/python3.8/site-packages/rest_framework/views.py", line 511, in dispatch
    self.response = self.finalize_response(request, response, *args, **kwargs)
  File "/home/mrtbadboy/PycharmProjects/PortmanV3/venv/lib/python3.8/site-packages/rest_framework/views.py", line 423, in finalize_response
    assert isinstance(response, HttpResponseBase), (
AssertionError: Expected a `Response`, `HttpResponse` or `HttpStreamingResponse` to be returned from the view, but received a `<class 'list'>`
Unauthorized: /api/v1/router/get_router_backup_files_name/
>>>>>>> c1cb61b5d9950c1faec31aeb22f26dcfd44c19be
Unauthorized: /api/v1/dslamport/fiberHomeCommand/
Unauthorized: /api/v1/dslamport/fiberHomeCommand/
<<<<<<< HEAD
Unauthorized: /api/v1/dslamport/fiberHomeCommand/
Unauthorized: /api/v1/dslamport/fiberHomeCommand/
Unauthorized: /api/v1/dslamport/fiberHomeCommand/
=======
Not Found: /favicon.ico
Internal Server Error: /admin/switch/switchgroup/add/
Traceback (most recent call last):
  File "/home/mrtbadboy/PycharmProjects/PortmanV3/venv/lib/python3.8/site-packages/django/db/backends/utils.py", line 84, in _execute
    return self.cursor.execute(sql, params)
psycopg2.errors.UndefinedColumn: column "switch_brand_id" of relation "switch_switchgroup" does not exist
LINE 1: INSERT INTO "switch_switchgroup" ("switch_brand_id", "title"...
                                          ^


The above exception was the direct cause of the following exception:

Traceback (most recent call last):
  File "/home/mrtbadboy/PycharmProjects/PortmanV3/venv/lib/python3.8/site-packages/django/core/handlers/exception.py", line 47, in inner
    response = get_response(request)
  File "/home/mrtbadboy/PycharmProjects/PortmanV3/venv/lib/python3.8/site-packages/django/core/handlers/base.py", line 179, in _get_response
    response = wrapped_callback(request, *callback_args, **callback_kwargs)
  File "/home/mrtbadboy/PycharmProjects/PortmanV3/venv/lib/python3.8/site-packages/django/contrib/admin/options.py", line 614, in wrapper
    return self.admin_site.admin_view(view)(*args, **kwargs)
  File "/home/mrtbadboy/PycharmProjects/PortmanV3/venv/lib/python3.8/site-packages/django/utils/decorators.py", line 130, in _wrapped_view
    response = view_func(request, *args, **kwargs)
  File "/home/mrtbadboy/PycharmProjects/PortmanV3/venv/lib/python3.8/site-packages/django/views/decorators/cache.py", line 44, in _wrapped_view_func
    response = view_func(request, *args, **kwargs)
  File "/home/mrtbadboy/PycharmProjects/PortmanV3/venv/lib/python3.8/site-packages/django/contrib/admin/sites.py", line 233, in inner
    return view(request, *args, **kwargs)
  File "/home/mrtbadboy/PycharmProjects/PortmanV3/venv/lib/python3.8/site-packages/django/contrib/admin/options.py", line 1653, in add_view
    return self.changeform_view(request, None, form_url, extra_context)
  File "/home/mrtbadboy/PycharmProjects/PortmanV3/venv/lib/python3.8/site-packages/django/utils/decorators.py", line 43, in _wrapper
    return bound_method(*args, **kwargs)
  File "/home/mrtbadboy/PycharmProjects/PortmanV3/venv/lib/python3.8/site-packages/django/utils/decorators.py", line 130, in _wrapped_view
    response = view_func(request, *args, **kwargs)
  File "/home/mrtbadboy/PycharmProjects/PortmanV3/venv/lib/python3.8/site-packages/django/contrib/admin/options.py", line 1534, in changeform_view
    return self._changeform_view(request, object_id, form_url, extra_context)
  File "/home/mrtbadboy/PycharmProjects/PortmanV3/venv/lib/python3.8/site-packages/django/contrib/admin/options.py", line 1580, in _changeform_view
    self.save_model(request, new_object, form, not add)
  File "/home/mrtbadboy/PycharmProjects/PortmanV3/venv/lib/python3.8/site-packages/django/contrib/admin/options.py", line 1093, in save_model
    obj.save()
  File "/home/mrtbadboy/PycharmProjects/PortmanV3/venv/lib/python3.8/site-packages/django/db/models/base.py", line 753, in save
    self.save_base(using=using, force_insert=force_insert,
  File "/home/mrtbadboy/PycharmProjects/PortmanV3/venv/lib/python3.8/site-packages/django/db/models/base.py", line 790, in save_base
    updated = self._save_table(
  File "/home/mrtbadboy/PycharmProjects/PortmanV3/venv/lib/python3.8/site-packages/django/db/models/base.py", line 895, in _save_table
    results = self._do_insert(cls._base_manager, using, fields, returning_fields, raw)
  File "/home/mrtbadboy/PycharmProjects/PortmanV3/venv/lib/python3.8/site-packages/django/db/models/base.py", line 933, in _do_insert
    return manager._insert(
  File "/home/mrtbadboy/PycharmProjects/PortmanV3/venv/lib/python3.8/site-packages/django/db/models/manager.py", line 85, in manager_method
    return getattr(self.get_queryset(), name)(*args, **kwargs)
  File "/home/mrtbadboy/PycharmProjects/PortmanV3/venv/lib/python3.8/site-packages/django/db/models/query.py", line 1254, in _insert
    return query.get_compiler(using=using).execute_sql(returning_fields)
  File "/home/mrtbadboy/PycharmProjects/PortmanV3/venv/lib/python3.8/site-packages/django/db/models/sql/compiler.py", line 1397, in execute_sql
    cursor.execute(sql, params)
  File "/home/mrtbadboy/PycharmProjects/PortmanV3/venv/lib/python3.8/site-packages/django/db/backends/utils.py", line 98, in execute
    return super().execute(sql, params)
  File "/home/mrtbadboy/PycharmProjects/PortmanV3/venv/lib/python3.8/site-packages/django/db/backends/utils.py", line 66, in execute
    return self._execute_with_wrappers(sql, params, many=False, executor=self._execute)
  File "/home/mrtbadboy/PycharmProjects/PortmanV3/venv/lib/python3.8/site-packages/django/db/backends/utils.py", line 75, in _execute_with_wrappers
    return executor(sql, params, many, context)
  File "/home/mrtbadboy/PycharmProjects/PortmanV3/venv/lib/python3.8/site-packages/django/db/backends/utils.py", line 84, in _execute
    return self.cursor.execute(sql, params)
  File "/home/mrtbadboy/PycharmProjects/PortmanV3/venv/lib/python3.8/site-packages/django/db/utils.py", line 90, in __exit__
    raise dj_exc_value.with_traceback(traceback) from exc_value
  File "/home/mrtbadboy/PycharmProjects/PortmanV3/venv/lib/python3.8/site-packages/django/db/backends/utils.py", line 84, in _execute
    return self.cursor.execute(sql, params)
django.db.utils.ProgrammingError: column "switch_brand_id" of relation "switch_switchgroup" does not exist
LINE 1: INSERT INTO "switch_switchgroup" ("switch_brand_id", "title"...
                                          ^

Not Found: /favicon.ico
>>>>>>> 5918992b7370b39b7f0d09856258265ad497a122
Unauthorized: /api/v1/dslamport/fiberHomeCommand/
Unauthorized: /api/v1/dslamport/fiberHomeCommand/
