Unauthorized: /api/v1/dslamport/search_fqdns/
Not Found: /api/v1/dslamport/get_partak_dslam_list_by_telecom_id/
Internal Server Error: /api/v1/dslamport/register-port/
Internal Server Error: /api/v1/dslamport/register-port/
Internal Server Error: /api/v1/dslamport/register-port/
Internal Server Error: /api/v1/contact/get_ddr_info_exportExcel/
Traceback (most recent call last):
  File "/home/mrtbadboy/.local/lib/python3.9/site-packages/django/core/handlers/exception.py", line 47, in inner
    response = get_response(request)
  File "/home/mrtbadboy/.local/lib/python3.9/site-packages/django/core/handlers/base.py", line 204, in _get_response
    response = response.render()
  File "/home/mrtbadboy/.local/lib/python3.9/site-packages/django/template/response.py", line 105, in render
    self.content = self.rendered_content
  File "/home/mrtbadboy/.local/lib/python3.9/site-packages/rest_framework/response.py", line 70, in rendered_content
    ret = renderer.render(self.data, accepted_media_type, context)
  File "/home/mrtbadboy/.local/lib/python3.9/site-packages/rest_framework/renderers.py", line 100, in render
    ret = json.dumps(
  File "/home/mrtbadboy/.local/lib/python3.9/site-packages/rest_framework/utils/json.py", line 25, in dumps
    return json.dumps(*args, **kwargs)
  File "/usr/lib/python3.9/json/__init__.py", line 234, in dumps
    return cls(
  File "/usr/lib/python3.9/json/encoder.py", line 199, in encode
    chunks = self.iterencode(o, _one_shot=True)
  File "/usr/lib/python3.9/json/encoder.py", line 257, in iterencode
    return _iterencode(o, 0)
  File "/home/mrtbadboy/.local/lib/python3.9/site-packages/rest_framework/utils/encoders.py", line 67, in default
    return super().default(obj)
  File "/usr/lib/python3.9/json/encoder.py", line 179, in default
    raise TypeError(f'Object of type {o.__class__.__name__} '
TypeError: Object of type FarzaneganTDLTE is not JSON serializable
Internal Server Error: /api/v1/user/get_user_permission_profile_objects/
Traceback (most recent call last):
  File "/home/mrtbadboy/.local/lib/python3.9/site-packages/django/core/handlers/exception.py", line 47, in inner
    response = get_response(request)
  File "/home/mrtbadboy/.local/lib/python3.9/site-packages/django/core/handlers/base.py", line 181, in _get_response
    response = wrapped_callback(request, *callback_args, **callback_kwargs)
  File "/home/mrtbadboy/.local/lib/python3.9/site-packages/django/views/decorators/csrf.py", line 54, in wrapped_view
    return view_func(*args, **kwargs)
  File "/home/mrtbadboy/.local/lib/python3.9/site-packages/django/views/generic/base.py", line 70, in view
    return self.dispatch(request, *args, **kwargs)
  File "/home/mrtbadboy/.local/lib/python3.9/site-packages/rest_framework/views.py", line 511, in dispatch
    self.response = self.finalize_response(request, response, *args, **kwargs)
  File "/home/mrtbadboy/.local/lib/python3.9/site-packages/rest_framework/views.py", line 423, in finalize_response
    assert isinstance(response, HttpResponseBase), (
AssertionError: Expected a `Response`, `HttpResponse` or `HttpStreamingResponse` to be returned from the view, but received a `<class 'NoneType'>`
Internal Server Error: /api/v1/user/get_user_permission_profile_objects/
Traceback (most recent call last):
  File "/home/mrtbadboy/.local/lib/python3.9/site-packages/django/core/handlers/exception.py", line 47, in inner
    response = get_response(request)
  File "/home/mrtbadboy/.local/lib/python3.9/site-packages/django/core/handlers/base.py", line 181, in _get_response
    response = wrapped_callback(request, *callback_args, **callback_kwargs)
  File "/home/mrtbadboy/.local/lib/python3.9/site-packages/django/views/decorators/csrf.py", line 54, in wrapped_view
    return view_func(*args, **kwargs)
  File "/home/mrtbadboy/.local/lib/python3.9/site-packages/django/views/generic/base.py", line 70, in view
    return self.dispatch(request, *args, **kwargs)
  File "/home/mrtbadboy/.local/lib/python3.9/site-packages/rest_framework/views.py", line 511, in dispatch
    self.response = self.finalize_response(request, response, *args, **kwargs)
  File "/home/mrtbadboy/.local/lib/python3.9/site-packages/rest_framework/views.py", line 423, in finalize_response
    assert isinstance(response, HttpResponseBase), (
AssertionError: Expected a `Response`, `HttpResponse` or `HttpStreamingResponse` to be returned from the view, but received a `<class 'NoneType'>`
Internal Server Error: /api/v1/user/get_user_permission_profile_objects/
Traceback (most recent call last):
  File "/home/mrtbadboy/.local/lib/python3.9/site-packages/django/core/handlers/exception.py", line 47, in inner
    response = get_response(request)
  File "/home/mrtbadboy/.local/lib/python3.9/site-packages/django/core/handlers/base.py", line 181, in _get_response
    response = wrapped_callback(request, *callback_args, **callback_kwargs)
  File "/home/mrtbadboy/.local/lib/python3.9/site-packages/django/views/decorators/csrf.py", line 54, in wrapped_view
    return view_func(*args, **kwargs)
  File "/home/mrtbadboy/.local/lib/python3.9/site-packages/django/views/generic/base.py", line 70, in view
    return self.dispatch(request, *args, **kwargs)
  File "/home/mrtbadboy/.local/lib/python3.9/site-packages/rest_framework/views.py", line 511, in dispatch
    self.response = self.finalize_response(request, response, *args, **kwargs)
  File "/home/mrtbadboy/.local/lib/python3.9/site-packages/rest_framework/views.py", line 423, in finalize_response
    assert isinstance(response, HttpResponseBase), (
AssertionError: Expected a `Response`, `HttpResponse` or `HttpStreamingResponse` to be returned from the view, but received a `<class 'NoneType'>`
Internal Server Error: /api/v1/user/get_user_permission_profile_objects/
Traceback (most recent call last):
  File "/home/mrtbadboy/.local/lib/python3.9/site-packages/django/core/handlers/exception.py", line 47, in inner
    response = get_response(request)
  File "/home/mrtbadboy/.local/lib/python3.9/site-packages/django/core/handlers/base.py", line 181, in _get_response
    response = wrapped_callback(request, *callback_args, **callback_kwargs)
  File "/home/mrtbadboy/.local/lib/python3.9/site-packages/django/views/decorators/csrf.py", line 54, in wrapped_view
    return view_func(*args, **kwargs)
  File "/home/mrtbadboy/.local/lib/python3.9/site-packages/django/views/generic/base.py", line 70, in view
    return self.dispatch(request, *args, **kwargs)
  File "/home/mrtbadboy/.local/lib/python3.9/site-packages/rest_framework/views.py", line 511, in dispatch
    self.response = self.finalize_response(request, response, *args, **kwargs)
  File "/home/mrtbadboy/.local/lib/python3.9/site-packages/rest_framework/views.py", line 423, in finalize_response
    assert isinstance(response, HttpResponseBase), (
AssertionError: Expected a `Response`, `HttpResponse` or `HttpStreamingResponse` to be returned from the view, but received a `<class 'NoneType'>`
Internal Server Error: /api/v1/user/get_user_permission_profile_objects/
Traceback (most recent call last):
  File "/home/mrtbadboy/.local/lib/python3.9/site-packages/django/core/handlers/exception.py", line 47, in inner
    response = get_response(request)
  File "/home/mrtbadboy/.local/lib/python3.9/site-packages/django/core/handlers/base.py", line 181, in _get_response
    response = wrapped_callback(request, *callback_args, **callback_kwargs)
  File "/home/mrtbadboy/.local/lib/python3.9/site-packages/django/views/decorators/csrf.py", line 54, in wrapped_view
    return view_func(*args, **kwargs)
  File "/home/mrtbadboy/.local/lib/python3.9/site-packages/django/views/generic/base.py", line 70, in view
    return self.dispatch(request, *args, **kwargs)
  File "/home/mrtbadboy/.local/lib/python3.9/site-packages/rest_framework/views.py", line 511, in dispatch
    self.response = self.finalize_response(request, response, *args, **kwargs)
  File "/home/mrtbadboy/.local/lib/python3.9/site-packages/rest_framework/views.py", line 423, in finalize_response
    assert isinstance(response, HttpResponseBase), (
AssertionError: Expected a `Response`, `HttpResponse` or `HttpStreamingResponse` to be returned from the view, but received a `<class 'NoneType'>`
Internal Server Error: /api/v1/user/get_user_permission_profile_objects/
Traceback (most recent call last):
  File "/home/mrtbadboy/.local/lib/python3.9/site-packages/django/core/handlers/exception.py", line 47, in inner
    response = get_response(request)
  File "/home/mrtbadboy/.local/lib/python3.9/site-packages/django/core/handlers/base.py", line 181, in _get_response
    response = wrapped_callback(request, *callback_args, **callback_kwargs)
  File "/home/mrtbadboy/.local/lib/python3.9/site-packages/django/views/decorators/csrf.py", line 54, in wrapped_view
    return view_func(*args, **kwargs)
  File "/home/mrtbadboy/.local/lib/python3.9/site-packages/django/views/generic/base.py", line 70, in view
    return self.dispatch(request, *args, **kwargs)
  File "/home/mrtbadboy/.local/lib/python3.9/site-packages/rest_framework/views.py", line 511, in dispatch
    self.response = self.finalize_response(request, response, *args, **kwargs)
  File "/home/mrtbadboy/.local/lib/python3.9/site-packages/rest_framework/views.py", line 423, in finalize_response
    assert isinstance(response, HttpResponseBase), (
AssertionError: Expected a `Response`, `HttpResponse` or `HttpStreamingResponse` to be returned from the view, but received a `<class 'NoneType'>`
Internal Server Error: /api/v1/user/get_user_permission_profile_objects/
Traceback (most recent call last):
  File "/home/mrtbadboy/.local/lib/python3.9/site-packages/django/core/handlers/exception.py", line 47, in inner
    response = get_response(request)
  File "/home/mrtbadboy/.local/lib/python3.9/site-packages/django/core/handlers/base.py", line 181, in _get_response
    response = wrapped_callback(request, *callback_args, **callback_kwargs)
  File "/home/mrtbadboy/.local/lib/python3.9/site-packages/django/views/decorators/csrf.py", line 54, in wrapped_view
    return view_func(*args, **kwargs)
  File "/home/mrtbadboy/.local/lib/python3.9/site-packages/django/views/generic/base.py", line 70, in view
    return self.dispatch(request, *args, **kwargs)
  File "/home/mrtbadboy/.local/lib/python3.9/site-packages/rest_framework/views.py", line 511, in dispatch
    self.response = self.finalize_response(request, response, *args, **kwargs)
  File "/home/mrtbadboy/.local/lib/python3.9/site-packages/rest_framework/views.py", line 423, in finalize_response
    assert isinstance(response, HttpResponseBase), (
AssertionError: Expected a `Response`, `HttpResponse` or `HttpStreamingResponse` to be returned from the view, but received a `<class 'NoneType'>`
Internal Server Error: /api/v1/user/get_user_permission_profile_objects/
Traceback (most recent call last):
  File "/home/mrtbadboy/.local/lib/python3.9/site-packages/django/core/handlers/exception.py", line 47, in inner
    response = get_response(request)
  File "/home/mrtbadboy/.local/lib/python3.9/site-packages/django/core/handlers/base.py", line 181, in _get_response
    response = wrapped_callback(request, *callback_args, **callback_kwargs)
  File "/home/mrtbadboy/.local/lib/python3.9/site-packages/django/views/decorators/csrf.py", line 54, in wrapped_view
    return view_func(*args, **kwargs)
  File "/home/mrtbadboy/.local/lib/python3.9/site-packages/django/views/generic/base.py", line 70, in view
    return self.dispatch(request, *args, **kwargs)
  File "/home/mrtbadboy/.local/lib/python3.9/site-packages/rest_framework/views.py", line 511, in dispatch
    self.response = self.finalize_response(request, response, *args, **kwargs)
  File "/home/mrtbadboy/.local/lib/python3.9/site-packages/rest_framework/views.py", line 423, in finalize_response
    assert isinstance(response, HttpResponseBase), (
AssertionError: Expected a `Response`, `HttpResponse` or `HttpStreamingResponse` to be returned from the view, but received a `<class 'NoneType'>`
Internal Server Error: /api/v1/user/get_user_permission_profile_objects/
Traceback (most recent call last):
  File "/home/mrtbadboy/.local/lib/python3.9/site-packages/django/core/handlers/exception.py", line 47, in inner
    response = get_response(request)
  File "/home/mrtbadboy/.local/lib/python3.9/site-packages/django/core/handlers/base.py", line 181, in _get_response
    response = wrapped_callback(request, *callback_args, **callback_kwargs)
  File "/home/mrtbadboy/.local/lib/python3.9/site-packages/django/views/decorators/csrf.py", line 54, in wrapped_view
    return view_func(*args, **kwargs)
  File "/home/mrtbadboy/.local/lib/python3.9/site-packages/django/views/generic/base.py", line 70, in view
    return self.dispatch(request, *args, **kwargs)
  File "/home/mrtbadboy/.local/lib/python3.9/site-packages/rest_framework/views.py", line 511, in dispatch
    self.response = self.finalize_response(request, response, *args, **kwargs)
  File "/home/mrtbadboy/.local/lib/python3.9/site-packages/rest_framework/views.py", line 423, in finalize_response
    assert isinstance(response, HttpResponseBase), (
AssertionError: Expected a `Response`, `HttpResponse` or `HttpStreamingResponse` to be returned from the view, but received a `<class 'NoneType'>`
Internal Server Error: /api/v1/user/get_user_permission_profile_objects/
Traceback (most recent call last):
  File "/home/mrtbadboy/.local/lib/python3.9/site-packages/django/core/handlers/exception.py", line 47, in inner
    response = get_response(request)
  File "/home/mrtbadboy/.local/lib/python3.9/site-packages/django/core/handlers/base.py", line 204, in _get_response
    response = response.render()
  File "/home/mrtbadboy/.local/lib/python3.9/site-packages/django/template/response.py", line 105, in render
    self.content = self.rendered_content
  File "/home/mrtbadboy/.local/lib/python3.9/site-packages/rest_framework/response.py", line 70, in rendered_content
    ret = renderer.render(self.data, accepted_media_type, context)
  File "/home/mrtbadboy/.local/lib/python3.9/site-packages/rest_framework/renderers.py", line 100, in render
    ret = json.dumps(
  File "/home/mrtbadboy/.local/lib/python3.9/site-packages/rest_framework/utils/json.py", line 25, in dumps
    return json.dumps(*args, **kwargs)
  File "/usr/lib/python3.9/json/__init__.py", line 234, in dumps
    return cls(
  File "/usr/lib/python3.9/json/encoder.py", line 199, in encode
    chunks = self.iterencode(o, _one_shot=True)
  File "/usr/lib/python3.9/json/encoder.py", line 257, in iterencode
    return _iterencode(o, 0)
  File "/home/mrtbadboy/.local/lib/python3.9/site-packages/rest_framework/utils/encoders.py", line 67, in default
    return super().default(obj)
  File "/usr/lib/python3.9/json/encoder.py", line 179, in default
    raise TypeError(f'Object of type {o.__class__.__name__} '
TypeError: Object of type UserPermissionProfileObject is not JSON serializable
Internal Server Error: /api/v1/user/get_user_permission_profile_objects/
Traceback (most recent call last):
  File "/home/mrtbadboy/.local/lib/python3.9/site-packages/django/core/handlers/exception.py", line 47, in inner
    response = get_response(request)
  File "/home/mrtbadboy/.local/lib/python3.9/site-packages/django/core/handlers/base.py", line 204, in _get_response
    response = response.render()
  File "/home/mrtbadboy/.local/lib/python3.9/site-packages/django/template/response.py", line 105, in render
    self.content = self.rendered_content
  File "/home/mrtbadboy/.local/lib/python3.9/site-packages/rest_framework/response.py", line 70, in rendered_content
    ret = renderer.render(self.data, accepted_media_type, context)
  File "/home/mrtbadboy/.local/lib/python3.9/site-packages/rest_framework/renderers.py", line 100, in render
    ret = json.dumps(
  File "/home/mrtbadboy/.local/lib/python3.9/site-packages/rest_framework/utils/json.py", line 25, in dumps
    return json.dumps(*args, **kwargs)
  File "/usr/lib/python3.9/json/__init__.py", line 234, in dumps
    return cls(
  File "/usr/lib/python3.9/json/encoder.py", line 199, in encode
    chunks = self.iterencode(o, _one_shot=True)
  File "/usr/lib/python3.9/json/encoder.py", line 257, in iterencode
    return _iterencode(o, 0)
  File "/home/mrtbadboy/.local/lib/python3.9/site-packages/rest_framework/utils/encoders.py", line 67, in default
    return super().default(obj)
  File "/usr/lib/python3.9/json/encoder.py", line 179, in default
    raise TypeError(f'Object of type {o.__class__.__name__} '
TypeError: Object of type UserPermissionProfileObject is not JSON serializable
Internal Server Error: /api/v1/user/get_user_permission_profile_objects/
Traceback (most recent call last):
  File "/home/mrtbadboy/.local/lib/python3.9/site-packages/django/core/handlers/exception.py", line 47, in inner
    response = get_response(request)
  File "/home/mrtbadboy/.local/lib/python3.9/site-packages/django/core/handlers/base.py", line 204, in _get_response
    response = response.render()
  File "/home/mrtbadboy/.local/lib/python3.9/site-packages/django/template/response.py", line 105, in render
    self.content = self.rendered_content
  File "/home/mrtbadboy/.local/lib/python3.9/site-packages/rest_framework/response.py", line 70, in rendered_content
    ret = renderer.render(self.data, accepted_media_type, context)
  File "/home/mrtbadboy/.local/lib/python3.9/site-packages/rest_framework/renderers.py", line 100, in render
    ret = json.dumps(
  File "/home/mrtbadboy/.local/lib/python3.9/site-packages/rest_framework/utils/json.py", line 25, in dumps
    return json.dumps(*args, **kwargs)
  File "/usr/lib/python3.9/json/__init__.py", line 234, in dumps
    return cls(
  File "/usr/lib/python3.9/json/encoder.py", line 199, in encode
    chunks = self.iterencode(o, _one_shot=True)
  File "/usr/lib/python3.9/json/encoder.py", line 257, in iterencode
    return _iterencode(o, 0)
  File "/home/mrtbadboy/.local/lib/python3.9/site-packages/rest_framework/utils/encoders.py", line 67, in default
    return super().default(obj)
  File "/usr/lib/python3.9/json/encoder.py", line 179, in default
    raise TypeError(f'Object of type {o.__class__.__name__} '
TypeError: Object of type UserPermissionProfileObject is not JSON serializable
Internal Server Error: /api/v1/user/get_user_permission_profile_objects/
Traceback (most recent call last):
  File "/home/mrtbadboy/.local/lib/python3.9/site-packages/django/core/handlers/exception.py", line 47, in inner
    response = get_response(request)
  File "/home/mrtbadboy/.local/lib/python3.9/site-packages/django/core/handlers/base.py", line 204, in _get_response
    response = response.render()
  File "/home/mrtbadboy/.local/lib/python3.9/site-packages/django/template/response.py", line 105, in render
    self.content = self.rendered_content
  File "/home/mrtbadboy/.local/lib/python3.9/site-packages/rest_framework/response.py", line 70, in rendered_content
    ret = renderer.render(self.data, accepted_media_type, context)
  File "/home/mrtbadboy/.local/lib/python3.9/site-packages/rest_framework/renderers.py", line 100, in render
    ret = json.dumps(
  File "/home/mrtbadboy/.local/lib/python3.9/site-packages/rest_framework/utils/json.py", line 25, in dumps
    return json.dumps(*args, **kwargs)
  File "/usr/lib/python3.9/json/__init__.py", line 234, in dumps
    return cls(
  File "/usr/lib/python3.9/json/encoder.py", line 199, in encode
    chunks = self.iterencode(o, _one_shot=True)
  File "/usr/lib/python3.9/json/encoder.py", line 257, in iterencode
    return _iterencode(o, 0)
  File "/home/mrtbadboy/.local/lib/python3.9/site-packages/rest_framework/utils/encoders.py", line 67, in default
    return super().default(obj)
  File "/usr/lib/python3.9/json/encoder.py", line 179, in default
    raise TypeError(f'Object of type {o.__class__.__name__} '
TypeError: Object of type UserPermissionProfileObject is not JSON serializable
Internal Server Error: /api/v1/user/get_user_permission_profile_objects/
Traceback (most recent call last):
  File "/home/mrtbadboy/.local/lib/python3.9/site-packages/django/core/handlers/exception.py", line 47, in inner
    response = get_response(request)
  File "/home/mrtbadboy/.local/lib/python3.9/site-packages/django/core/handlers/base.py", line 204, in _get_response
    response = response.render()
  File "/home/mrtbadboy/.local/lib/python3.9/site-packages/django/template/response.py", line 105, in render
    self.content = self.rendered_content
  File "/home/mrtbadboy/.local/lib/python3.9/site-packages/rest_framework/response.py", line 70, in rendered_content
    ret = renderer.render(self.data, accepted_media_type, context)
  File "/home/mrtbadboy/.local/lib/python3.9/site-packages/rest_framework/renderers.py", line 100, in render
    ret = json.dumps(
  File "/home/mrtbadboy/.local/lib/python3.9/site-packages/rest_framework/utils/json.py", line 25, in dumps
    return json.dumps(*args, **kwargs)
  File "/usr/lib/python3.9/json/__init__.py", line 234, in dumps
    return cls(
  File "/usr/lib/python3.9/json/encoder.py", line 199, in encode
    chunks = self.iterencode(o, _one_shot=True)
  File "/usr/lib/python3.9/json/encoder.py", line 257, in iterencode
    return _iterencode(o, 0)
  File "/home/mrtbadboy/.local/lib/python3.9/site-packages/rest_framework/utils/encoders.py", line 67, in default
    return super().default(obj)
  File "/usr/lib/python3.9/json/encoder.py", line 179, in default
    raise TypeError(f'Object of type {o.__class__.__name__} '
TypeError: Object of type UserPermissionProfileObject is not JSON serializable
Internal Server Error: /api/v1/user/get_user_permission_profile_objects/
Traceback (most recent call last):
  File "/home/mrtbadboy/.local/lib/python3.9/site-packages/django/core/handlers/exception.py", line 47, in inner
    response = get_response(request)
  File "/home/mrtbadboy/.local/lib/python3.9/site-packages/django/core/handlers/base.py", line 181, in _get_response
    response = wrapped_callback(request, *callback_args, **callback_kwargs)
  File "/home/mrtbadboy/.local/lib/python3.9/site-packages/django/views/decorators/csrf.py", line 54, in wrapped_view
    return view_func(*args, **kwargs)
  File "/home/mrtbadboy/.local/lib/python3.9/site-packages/django/views/generic/base.py", line 70, in view
    return self.dispatch(request, *args, **kwargs)
  File "/home/mrtbadboy/.local/lib/python3.9/site-packages/rest_framework/views.py", line 511, in dispatch
    self.response = self.finalize_response(request, response, *args, **kwargs)
  File "/home/mrtbadboy/.local/lib/python3.9/site-packages/rest_framework/views.py", line 423, in finalize_response
    assert isinstance(response, HttpResponseBase), (
AssertionError: Expected a `Response`, `HttpResponse` or `HttpStreamingResponse` to be returned from the view, but received a `<class 'list'>`
Internal Server Error: /api/v1/user/get_user_permission_profile_objects/
Traceback (most recent call last):
  File "/home/mrtbadboy/.local/lib/python3.9/site-packages/django/core/handlers/exception.py", line 47, in inner
    response = get_response(request)
  File "/home/mrtbadboy/.local/lib/python3.9/site-packages/django/core/handlers/base.py", line 181, in _get_response
    response = wrapped_callback(request, *callback_args, **callback_kwargs)
  File "/home/mrtbadboy/.local/lib/python3.9/site-packages/django/views/decorators/csrf.py", line 54, in wrapped_view
    return view_func(*args, **kwargs)
  File "/home/mrtbadboy/.local/lib/python3.9/site-packages/django/views/generic/base.py", line 70, in view
    return self.dispatch(request, *args, **kwargs)
  File "/home/mrtbadboy/.local/lib/python3.9/site-packages/rest_framework/views.py", line 511, in dispatch
    self.response = self.finalize_response(request, response, *args, **kwargs)
  File "/home/mrtbadboy/.local/lib/python3.9/site-packages/rest_framework/views.py", line 423, in finalize_response
    assert isinstance(response, HttpResponseBase), (
AssertionError: Expected a `Response`, `HttpResponse` or `HttpStreamingResponse` to be returned from the view, but received a `<class 'django.db.models.query.QuerySet'>`
Internal Server Error: /api/v1/command/
Traceback (most recent call last):
  File "/home/mrtbadboy/.local/lib/python3.9/site-packages/django/core/handlers/exception.py", line 47, in inner
    response = get_response(request)
  File "/home/mrtbadboy/.local/lib/python3.9/site-packages/django/core/handlers/base.py", line 181, in _get_response
    response = wrapped_callback(request, *callback_args, **callback_kwargs)
  File "/home/mrtbadboy/.local/lib/python3.9/site-packages/django/views/decorators/csrf.py", line 54, in wrapped_view
    return view_func(*args, **kwargs)
  File "/home/mrtbadboy/.local/lib/python3.9/site-packages/rest_framework/viewsets.py", line 125, in view
    return self.dispatch(request, *args, **kwargs)
  File "/home/mrtbadboy/.local/lib/python3.9/site-packages/rest_framework/views.py", line 509, in dispatch
    response = self.handle_exception(exc)
  File "/home/mrtbadboy/.local/lib/python3.9/site-packages/rest_framework/views.py", line 469, in handle_exception
    self.raise_uncaught_exception(exc)
  File "/home/mrtbadboy/.local/lib/python3.9/site-packages/rest_framework/views.py", line 480, in raise_uncaught_exception
    raise exc
  File "/home/mrtbadboy/.local/lib/python3.9/site-packages/rest_framework/views.py", line 506, in dispatch
    response = handler(request, *args, **kwargs)
  File "/home/mrtbadboy/.local/lib/python3.9/site-packages/rest_framework/mixins.py", line 38, in list
    queryset = self.filter_queryset(self.get_queryset())
  File "/opt/portmanv3/portman_web/dslam/views.py", line 1456, in get_queryset
    allowed_commands = User.allowed_commands()
TypeError: 'property' object is not callable
Internal Server Error: /api/v1/command/
Traceback (most recent call last):
  File "/home/mrtbadboy/.local/lib/python3.9/site-packages/django/core/handlers/exception.py", line 47, in inner
    response = get_response(request)
  File "/home/mrtbadboy/.local/lib/python3.9/site-packages/django/core/handlers/base.py", line 181, in _get_response
    response = wrapped_callback(request, *callback_args, **callback_kwargs)
  File "/home/mrtbadboy/.local/lib/python3.9/site-packages/django/views/decorators/csrf.py", line 54, in wrapped_view
    return view_func(*args, **kwargs)
  File "/home/mrtbadboy/.local/lib/python3.9/site-packages/rest_framework/viewsets.py", line 125, in view
    return self.dispatch(request, *args, **kwargs)
  File "/home/mrtbadboy/.local/lib/python3.9/site-packages/rest_framework/views.py", line 509, in dispatch
    response = self.handle_exception(exc)
  File "/home/mrtbadboy/.local/lib/python3.9/site-packages/rest_framework/views.py", line 469, in handle_exception
    self.raise_uncaught_exception(exc)
  File "/home/mrtbadboy/.local/lib/python3.9/site-packages/rest_framework/views.py", line 480, in raise_uncaught_exception
    raise exc
  File "/home/mrtbadboy/.local/lib/python3.9/site-packages/rest_framework/views.py", line 506, in dispatch
    response = handler(request, *args, **kwargs)
  File "/home/mrtbadboy/.local/lib/python3.9/site-packages/rest_framework/mixins.py", line 38, in list
    queryset = self.filter_queryset(self.get_queryset())
  File "/opt/portmanv3/portman_web/dslam/views.py", line 1456, in get_queryset
    allowed_commands = User.get_allowed_commands()
TypeError: get_allowed_commands() missing 1 required positional argument: 'self'
Internal Server Error: /api/v1/command/
Traceback (most recent call last):
  File "/home/mrtbadboy/.local/lib/python3.9/site-packages/django/core/handlers/exception.py", line 47, in inner
    response = get_response(request)
  File "/home/mrtbadboy/.local/lib/python3.9/site-packages/django/core/handlers/base.py", line 181, in _get_response
    response = wrapped_callback(request, *callback_args, **callback_kwargs)
  File "/home/mrtbadboy/.local/lib/python3.9/site-packages/django/views/decorators/csrf.py", line 54, in wrapped_view
    return view_func(*args, **kwargs)
  File "/home/mrtbadboy/.local/lib/python3.9/site-packages/rest_framework/viewsets.py", line 125, in view
    return self.dispatch(request, *args, **kwargs)
  File "/home/mrtbadboy/.local/lib/python3.9/site-packages/rest_framework/views.py", line 509, in dispatch
    response = self.handle_exception(exc)
  File "/home/mrtbadboy/.local/lib/python3.9/site-packages/rest_framework/views.py", line 469, in handle_exception
    self.raise_uncaught_exception(exc)
  File "/home/mrtbadboy/.local/lib/python3.9/site-packages/rest_framework/views.py", line 480, in raise_uncaught_exception
    raise exc
  File "/home/mrtbadboy/.local/lib/python3.9/site-packages/rest_framework/views.py", line 506, in dispatch
    response = handler(request, *args, **kwargs)
  File "/home/mrtbadboy/.local/lib/python3.9/site-packages/rest_framework/mixins.py", line 38, in list
    queryset = self.filter_queryset(self.get_queryset())
  File "/opt/portmanv3/portman_web/dslam/views.py", line 1456, in get_queryset
    allowed_commands = User.get_allowed_commands(self)
  File "/opt/portmanv3/portman_web/users/models.py", line 218, in get_allowed_commands
    return self.allowed_commands(self)
AttributeError: 'CommandViewSet' object has no attribute 'allowed_commands'
Internal Server Error: /api/v1/command/
Traceback (most recent call last):
  File "/home/mrtbadboy/.local/lib/python3.9/site-packages/django/core/handlers/exception.py", line 47, in inner
    response = get_response(request)
  File "/home/mrtbadboy/.local/lib/python3.9/site-packages/django/core/handlers/base.py", line 181, in _get_response
    response = wrapped_callback(request, *callback_args, **callback_kwargs)
  File "/home/mrtbadboy/.local/lib/python3.9/site-packages/django/views/decorators/csrf.py", line 54, in wrapped_view
    return view_func(*args, **kwargs)
  File "/home/mrtbadboy/.local/lib/python3.9/site-packages/rest_framework/viewsets.py", line 125, in view
    return self.dispatch(request, *args, **kwargs)
  File "/home/mrtbadboy/.local/lib/python3.9/site-packages/rest_framework/views.py", line 509, in dispatch
    response = self.handle_exception(exc)
  File "/home/mrtbadboy/.local/lib/python3.9/site-packages/rest_framework/views.py", line 469, in handle_exception
    self.raise_uncaught_exception(exc)
  File "/home/mrtbadboy/.local/lib/python3.9/site-packages/rest_framework/views.py", line 480, in raise_uncaught_exception
    raise exc
  File "/home/mrtbadboy/.local/lib/python3.9/site-packages/rest_framework/views.py", line 506, in dispatch
    response = handler(request, *args, **kwargs)
  File "/home/mrtbadboy/.local/lib/python3.9/site-packages/rest_framework/mixins.py", line 38, in list
    queryset = self.filter_queryset(self.get_queryset())
  File "/opt/portmanv3/portman_web/dslam/views.py", line 1456, in get_queryset
    allowed_commands = User.get_allowed_commands(self)
  File "/opt/portmanv3/portman_web/users/models.py", line 218, in get_allowed_commands
    return self.allowed_commands(self)
AttributeError: 'CommandViewSet' object has no attribute 'allowed_commands'
Internal Server Error: /api/v1/command/
Traceback (most recent call last):
  File "/home/mrtbadboy/.local/lib/python3.9/site-packages/django/core/handlers/exception.py", line 47, in inner
    response = get_response(request)
  File "/home/mrtbadboy/.local/lib/python3.9/site-packages/django/core/handlers/base.py", line 181, in _get_response
    response = wrapped_callback(request, *callback_args, **callback_kwargs)
  File "/home/mrtbadboy/.local/lib/python3.9/site-packages/django/views/decorators/csrf.py", line 54, in wrapped_view
    return view_func(*args, **kwargs)
  File "/home/mrtbadboy/.local/lib/python3.9/site-packages/rest_framework/viewsets.py", line 125, in view
    return self.dispatch(request, *args, **kwargs)
  File "/home/mrtbadboy/.local/lib/python3.9/site-packages/rest_framework/views.py", line 509, in dispatch
    response = self.handle_exception(exc)
  File "/home/mrtbadboy/.local/lib/python3.9/site-packages/rest_framework/views.py", line 469, in handle_exception
    self.raise_uncaught_exception(exc)
  File "/home/mrtbadboy/.local/lib/python3.9/site-packages/rest_framework/views.py", line 480, in raise_uncaught_exception
    raise exc
  File "/home/mrtbadboy/.local/lib/python3.9/site-packages/rest_framework/views.py", line 506, in dispatch
    response = handler(request, *args, **kwargs)
  File "/home/mrtbadboy/.local/lib/python3.9/site-packages/rest_framework/mixins.py", line 38, in list
    queryset = self.filter_queryset(self.get_queryset())
  File "/opt/portmanv3/portman_web/dslam/views.py", line 1456, in get_queryset
    allowed_commands = User.get_allowed_commands()
TypeError: get_allowed_commands() missing 1 required positional argument: 'self'
Internal Server Error: /api/v1/command/
Traceback (most recent call last):
  File "/home/mrtbadboy/.local/lib/python3.9/site-packages/django/core/handlers/exception.py", line 47, in inner
    response = get_response(request)
  File "/home/mrtbadboy/.local/lib/python3.9/site-packages/django/core/handlers/base.py", line 181, in _get_response
    response = wrapped_callback(request, *callback_args, **callback_kwargs)
  File "/home/mrtbadboy/.local/lib/python3.9/site-packages/django/views/decorators/csrf.py", line 54, in wrapped_view
    return view_func(*args, **kwargs)
  File "/home/mrtbadboy/.local/lib/python3.9/site-packages/rest_framework/viewsets.py", line 125, in view
    return self.dispatch(request, *args, **kwargs)
  File "/home/mrtbadboy/.local/lib/python3.9/site-packages/rest_framework/views.py", line 509, in dispatch
    response = self.handle_exception(exc)
  File "/home/mrtbadboy/.local/lib/python3.9/site-packages/rest_framework/views.py", line 469, in handle_exception
    self.raise_uncaught_exception(exc)
  File "/home/mrtbadboy/.local/lib/python3.9/site-packages/rest_framework/views.py", line 480, in raise_uncaught_exception
    raise exc
  File "/home/mrtbadboy/.local/lib/python3.9/site-packages/rest_framework/views.py", line 506, in dispatch
    response = handler(request, *args, **kwargs)
  File "/home/mrtbadboy/.local/lib/python3.9/site-packages/rest_framework/mixins.py", line 38, in list
    queryset = self.filter_queryset(self.get_queryset())
  File "/opt/portmanv3/portman_web/dslam/views.py", line 1456, in get_queryset
    allowed_commands = User.get_allowed_commands(None)
  File "/opt/portmanv3/portman_web/users/models.py", line 218, in get_allowed_commands
    return self.allowed_commands(self)
AttributeError: 'NoneType' object has no attribute 'allowed_commands'
Internal Server Error: /api/v1/command/
Traceback (most recent call last):
  File "/home/mrtbadboy/.local/lib/python3.9/site-packages/django/core/handlers/exception.py", line 47, in inner
    response = get_response(request)
  File "/home/mrtbadboy/.local/lib/python3.9/site-packages/django/core/handlers/base.py", line 181, in _get_response
    response = wrapped_callback(request, *callback_args, **callback_kwargs)
  File "/home/mrtbadboy/.local/lib/python3.9/site-packages/django/views/decorators/csrf.py", line 54, in wrapped_view
    return view_func(*args, **kwargs)
  File "/home/mrtbadboy/.local/lib/python3.9/site-packages/rest_framework/viewsets.py", line 125, in view
    return self.dispatch(request, *args, **kwargs)
  File "/home/mrtbadboy/.local/lib/python3.9/site-packages/rest_framework/views.py", line 509, in dispatch
    response = self.handle_exception(exc)
  File "/home/mrtbadboy/.local/lib/python3.9/site-packages/rest_framework/views.py", line 469, in handle_exception
    self.raise_uncaught_exception(exc)
  File "/home/mrtbadboy/.local/lib/python3.9/site-packages/rest_framework/views.py", line 480, in raise_uncaught_exception
    raise exc
  File "/home/mrtbadboy/.local/lib/python3.9/site-packages/rest_framework/views.py", line 506, in dispatch
    response = handler(request, *args, **kwargs)
  File "/home/mrtbadboy/.local/lib/python3.9/site-packages/rest_framework/mixins.py", line 38, in list
    queryset = self.filter_queryset(self.get_queryset())
  File "/opt/portmanv3/portman_web/dslam/views.py", line 1456, in get_queryset
    allowed_commands = User.get_allowed_commands(User)
  File "/opt/portmanv3/portman_web/users/models.py", line 218, in get_allowed_commands
    return self.allowed_commands(self)
TypeError: 'property' object is not callable
Internal Server Error: /api/v1/command/
Traceback (most recent call last):
  File "/home/mrtbadboy/.local/lib/python3.9/site-packages/django/core/handlers/exception.py", line 47, in inner
    response = get_response(request)
  File "/home/mrtbadboy/.local/lib/python3.9/site-packages/django/core/handlers/base.py", line 181, in _get_response
    response = wrapped_callback(request, *callback_args, **callback_kwargs)
  File "/home/mrtbadboy/.local/lib/python3.9/site-packages/django/views/decorators/csrf.py", line 54, in wrapped_view
    return view_func(*args, **kwargs)
  File "/home/mrtbadboy/.local/lib/python3.9/site-packages/rest_framework/viewsets.py", line 125, in view
    return self.dispatch(request, *args, **kwargs)
  File "/home/mrtbadboy/.local/lib/python3.9/site-packages/rest_framework/views.py", line 509, in dispatch
    response = self.handle_exception(exc)
  File "/home/mrtbadboy/.local/lib/python3.9/site-packages/rest_framework/views.py", line 469, in handle_exception
    self.raise_uncaught_exception(exc)
  File "/home/mrtbadboy/.local/lib/python3.9/site-packages/rest_framework/views.py", line 480, in raise_uncaught_exception
    raise exc
  File "/home/mrtbadboy/.local/lib/python3.9/site-packages/rest_framework/views.py", line 506, in dispatch
    response = handler(request, *args, **kwargs)
  File "/home/mrtbadboy/.local/lib/python3.9/site-packages/rest_framework/mixins.py", line 38, in list
    queryset = self.filter_queryset(self.get_queryset())
  File "/opt/portmanv3/portman_web/dslam/views.py", line 1457, in get_queryset
    allowed_commands = user.get_allowed_commands()
  File "/opt/portmanv3/portman_web/users/models.py", line 218, in get_allowed_commands
    return self.allowed_commands(self)
TypeError: 'dict' object is not callable
Internal Server Error: /api/v1/command/
Traceback (most recent call last):
  File "/home/mrtbadboy/.local/lib/python3.9/site-packages/django/core/handlers/exception.py", line 47, in inner
    response = get_response(request)
  File "/home/mrtbadboy/.local/lib/python3.9/site-packages/django/core/handlers/base.py", line 181, in _get_response
    response = wrapped_callback(request, *callback_args, **callback_kwargs)
  File "/home/mrtbadboy/.local/lib/python3.9/site-packages/django/views/decorators/csrf.py", line 54, in wrapped_view
    return view_func(*args, **kwargs)
  File "/home/mrtbadboy/.local/lib/python3.9/site-packages/rest_framework/viewsets.py", line 125, in view
    return self.dispatch(request, *args, **kwargs)
  File "/home/mrtbadboy/.local/lib/python3.9/site-packages/rest_framework/views.py", line 509, in dispatch
    response = self.handle_exception(exc)
  File "/home/mrtbadboy/.local/lib/python3.9/site-packages/rest_framework/views.py", line 469, in handle_exception
    self.raise_uncaught_exception(exc)
  File "/home/mrtbadboy/.local/lib/python3.9/site-packages/rest_framework/views.py", line 480, in raise_uncaught_exception
    raise exc
  File "/home/mrtbadboy/.local/lib/python3.9/site-packages/rest_framework/views.py", line 506, in dispatch
    response = handler(request, *args, **kwargs)
  File "/home/mrtbadboy/.local/lib/python3.9/site-packages/rest_framework/mixins.py", line 38, in list
    queryset = self.filter_queryset(self.get_queryset())
  File "/opt/portmanv3/portman_web/dslam/views.py", line 1460, in get_queryset
    super(User, self).username = username
TypeError: super(type, obj): obj must be an instance or subtype of type
Internal Server Error: /api/v1/command/
Traceback (most recent call last):
  File "/home/mrtbadboy/.local/lib/python3.9/site-packages/django/core/handlers/exception.py", line 47, in inner
    response = get_response(request)
  File "/home/mrtbadboy/.local/lib/python3.9/site-packages/django/core/handlers/base.py", line 181, in _get_response
    response = wrapped_callback(request, *callback_args, **callback_kwargs)
  File "/home/mrtbadboy/.local/lib/python3.9/site-packages/django/views/decorators/csrf.py", line 54, in wrapped_view
    return view_func(*args, **kwargs)
  File "/home/mrtbadboy/.local/lib/python3.9/site-packages/rest_framework/viewsets.py", line 125, in view
    return self.dispatch(request, *args, **kwargs)
  File "/home/mrtbadboy/.local/lib/python3.9/site-packages/rest_framework/views.py", line 509, in dispatch
    response = self.handle_exception(exc)
  File "/home/mrtbadboy/.local/lib/python3.9/site-packages/rest_framework/views.py", line 469, in handle_exception
    self.raise_uncaught_exception(exc)
  File "/home/mrtbadboy/.local/lib/python3.9/site-packages/rest_framework/views.py", line 480, in raise_uncaught_exception
    raise exc
  File "/home/mrtbadboy/.local/lib/python3.9/site-packages/rest_framework/views.py", line 506, in dispatch
    response = handler(request, *args, **kwargs)
  File "/home/mrtbadboy/.local/lib/python3.9/site-packages/rest_framework/mixins.py", line 38, in list
    queryset = self.filter_queryset(self.get_queryset())
  File "/opt/portmanv3/portman_web/dslam/views.py", line 1460, in get_queryset
    super(User, self).username = username
TypeError: super(type, obj): obj must be an instance or subtype of type
Internal Server Error: /api/v1/command/
Traceback (most recent call last):
  File "/home/mrtbadboy/.local/lib/python3.9/site-packages/django/db/models/fields/__init__.py", line 1823, in get_prep_value
    return int(value)
ValueError: invalid literal for int() with base 10: 'Iran-ava'

The above exception was the direct cause of the following exception:

Traceback (most recent call last):
  File "/home/mrtbadboy/.local/lib/python3.9/site-packages/django/core/handlers/exception.py", line 47, in inner
    response = get_response(request)
  File "/home/mrtbadboy/.local/lib/python3.9/site-packages/django/core/handlers/base.py", line 181, in _get_response
    response = wrapped_callback(request, *callback_args, **callback_kwargs)
  File "/home/mrtbadboy/.local/lib/python3.9/site-packages/django/views/decorators/csrf.py", line 54, in wrapped_view
    return view_func(*args, **kwargs)
  File "/home/mrtbadboy/.local/lib/python3.9/site-packages/rest_framework/viewsets.py", line 125, in view
    return self.dispatch(request, *args, **kwargs)
  File "/home/mrtbadboy/.local/lib/python3.9/site-packages/rest_framework/views.py", line 509, in dispatch
    response = self.handle_exception(exc)
  File "/home/mrtbadboy/.local/lib/python3.9/site-packages/rest_framework/views.py", line 469, in handle_exception
    self.raise_uncaught_exception(exc)
  File "/home/mrtbadboy/.local/lib/python3.9/site-packages/rest_framework/views.py", line 480, in raise_uncaught_exception
    raise exc
  File "/home/mrtbadboy/.local/lib/python3.9/site-packages/rest_framework/views.py", line 506, in dispatch
    response = handler(request, *args, **kwargs)
  File "/home/mrtbadboy/.local/lib/python3.9/site-packages/rest_framework/mixins.py", line 38, in list
    queryset = self.filter_queryset(self.get_queryset())
  File "/opt/portmanv3/portman_web/dslam/views.py", line 1461, in get_queryset
    allowed_commands = model_user.get_allowed_commands()
  File "/opt/portmanv3/portman_web/users/models.py", line 227, in get_allowed_commands
    return self.allowed_commands
  File "/opt/portmanv3/portman_web/users/models.py", line 192, in allowed_commands
    command_permission_ids = UserPermissionProfileObject.objects.filter(
  File "/home/mrtbadboy/.local/lib/python3.9/site-packages/django/db/models/manager.py", line 85, in manager_method
    return getattr(self.get_queryset(), name)(*args, **kwargs)
  File "/home/mrtbadboy/.local/lib/python3.9/site-packages/django/db/models/query.py", line 941, in filter
    return self._filter_or_exclude(False, args, kwargs)
  File "/home/mrtbadboy/.local/lib/python3.9/site-packages/django/db/models/query.py", line 961, in _filter_or_exclude
    clone._filter_or_exclude_inplace(negate, args, kwargs)
  File "/home/mrtbadboy/.local/lib/python3.9/site-packages/django/db/models/query.py", line 968, in _filter_or_exclude_inplace
    self._query.add_q(Q(*args, **kwargs))
  File "/home/mrtbadboy/.local/lib/python3.9/site-packages/django/db/models/sql/query.py", line 1393, in add_q
    clause, _ = self._add_q(q_object, self.used_aliases)
  File "/home/mrtbadboy/.local/lib/python3.9/site-packages/django/db/models/sql/query.py", line 1412, in _add_q
    child_clause, needed_inner = self.build_filter(
  File "/home/mrtbadboy/.local/lib/python3.9/site-packages/django/db/models/sql/query.py", line 1347, in build_filter
    condition = self.build_lookup(lookups, col, value)
  File "/home/mrtbadboy/.local/lib/python3.9/site-packages/django/db/models/sql/query.py", line 1193, in build_lookup
    lookup = lookup_class(lhs, rhs)
  File "/home/mrtbadboy/.local/lib/python3.9/site-packages/django/db/models/lookups.py", line 25, in __init__
    self.rhs = self.get_prep_lookup()
  File "/home/mrtbadboy/.local/lib/python3.9/site-packages/django/db/models/fields/related_lookups.py", line 117, in get_prep_lookup
    self.rhs = target_field.get_prep_value(self.rhs)
  File "/home/mrtbadboy/.local/lib/python3.9/site-packages/django/db/models/fields/__init__.py", line 1825, in get_prep_value
    raise e.__class__(
ValueError: Field 'id' expected a number but got 'Iran-ava'.
Internal Server Error: /api/v1/command/
Traceback (most recent call last):
  File "/home/mrtbadboy/.local/lib/python3.9/site-packages/django/core/handlers/exception.py", line 47, in inner
    response = get_response(request)
  File "/home/mrtbadboy/.local/lib/python3.9/site-packages/django/core/handlers/base.py", line 181, in _get_response
    response = wrapped_callback(request, *callback_args, **callback_kwargs)
  File "/home/mrtbadboy/.local/lib/python3.9/site-packages/django/views/decorators/csrf.py", line 54, in wrapped_view
    return view_func(*args, **kwargs)
  File "/home/mrtbadboy/.local/lib/python3.9/site-packages/rest_framework/viewsets.py", line 125, in view
    return self.dispatch(request, *args, **kwargs)
  File "/home/mrtbadboy/.local/lib/python3.9/site-packages/rest_framework/views.py", line 509, in dispatch
    response = self.handle_exception(exc)
  File "/home/mrtbadboy/.local/lib/python3.9/site-packages/rest_framework/views.py", line 469, in handle_exception
    self.raise_uncaught_exception(exc)
  File "/home/mrtbadboy/.local/lib/python3.9/site-packages/rest_framework/views.py", line 480, in raise_uncaught_exception
    raise exc
  File "/home/mrtbadboy/.local/lib/python3.9/site-packages/rest_framework/views.py", line 506, in dispatch
    response = handler(request, *args, **kwargs)
  File "/home/mrtbadboy/.local/lib/python3.9/site-packages/rest_framework/mixins.py", line 38, in list
    queryset = self.filter_queryset(self.get_queryset())
  File "/opt/portmanv3/portman_web/dslam/views.py", line 1457, in get_queryset
    user_type = User.objects.get(username=username).type
  File "/home/mrtbadboy/.local/lib/python3.9/site-packages/django/db/models/manager.py", line 85, in manager_method
    return getattr(self.get_queryset(), name)(*args, **kwargs)
  File "/home/mrtbadboy/.local/lib/python3.9/site-packages/django/db/models/query.py", line 435, in get
    raise self.model.DoesNotExist(
users.models.User.DoesNotExist: User matching query does not exist.
Internal Server Error: /api/v1/command/
Traceback (most recent call last):
  File "/home/mrtbadboy/.local/lib/python3.9/site-packages/django/core/handlers/exception.py", line 47, in inner
    response = get_response(request)
  File "/home/mrtbadboy/.local/lib/python3.9/site-packages/django/core/handlers/base.py", line 181, in _get_response
    response = wrapped_callback(request, *callback_args, **callback_kwargs)
  File "/home/mrtbadboy/.local/lib/python3.9/site-packages/django/views/decorators/csrf.py", line 54, in wrapped_view
    return view_func(*args, **kwargs)
  File "/home/mrtbadboy/.local/lib/python3.9/site-packages/rest_framework/viewsets.py", line 125, in view
    return self.dispatch(request, *args, **kwargs)
  File "/home/mrtbadboy/.local/lib/python3.9/site-packages/rest_framework/views.py", line 509, in dispatch
    response = self.handle_exception(exc)
  File "/home/mrtbadboy/.local/lib/python3.9/site-packages/rest_framework/views.py", line 469, in handle_exception
    self.raise_uncaught_exception(exc)
  File "/home/mrtbadboy/.local/lib/python3.9/site-packages/rest_framework/views.py", line 480, in raise_uncaught_exception
    raise exc
  File "/home/mrtbadboy/.local/lib/python3.9/site-packages/rest_framework/views.py", line 506, in dispatch
    response = handler(request, *args, **kwargs)
  File "/home/mrtbadboy/.local/lib/python3.9/site-packages/rest_framework/mixins.py", line 38, in list
    queryset = self.filter_queryset(self.get_queryset())
  File "/opt/portmanv3/portman_web/dslam/views.py", line 1466, in get_queryset
    if user_type == 'RESELLER':
UnboundLocalError: local variable 'user_type' referenced before assignment
Internal Server Error: /api/v1/command/
Traceback (most recent call last):
  File "/home/mrtbadboy/.local/lib/python3.9/site-packages/django/core/handlers/exception.py", line 47, in inner
    response = get_response(request)
  File "/home/mrtbadboy/.local/lib/python3.9/site-packages/django/core/handlers/base.py", line 181, in _get_response
    response = wrapped_callback(request, *callback_args, **callback_kwargs)
  File "/home/mrtbadboy/.local/lib/python3.9/site-packages/django/views/decorators/csrf.py", line 54, in wrapped_view
    return view_func(*args, **kwargs)
  File "/home/mrtbadboy/.local/lib/python3.9/site-packages/rest_framework/viewsets.py", line 125, in view
    return self.dispatch(request, *args, **kwargs)
  File "/home/mrtbadboy/.local/lib/python3.9/site-packages/rest_framework/views.py", line 509, in dispatch
    response = self.handle_exception(exc)
  File "/home/mrtbadboy/.local/lib/python3.9/site-packages/rest_framework/views.py", line 469, in handle_exception
    self.raise_uncaught_exception(exc)
  File "/home/mrtbadboy/.local/lib/python3.9/site-packages/rest_framework/views.py", line 480, in raise_uncaught_exception
    raise exc
  File "/home/mrtbadboy/.local/lib/python3.9/site-packages/rest_framework/views.py", line 506, in dispatch
    response = handler(request, *args, **kwargs)
  File "/home/mrtbadboy/.local/lib/python3.9/site-packages/rest_framework/mixins.py", line 38, in list
    queryset = self.filter_queryset(self.get_queryset())
  File "/opt/portmanv3/portman_web/dslam/views.py", line 1466, in get_queryset
    if user_type == 'RESELLER':
UnboundLocalError: local variable 'user_type' referenced before assignment
Internal Server Error: /api/v1/command/
Traceback (most recent call last):
  File "/home/mrtbadboy/.local/lib/python3.9/site-packages/django/core/handlers/exception.py", line 47, in inner
    response = get_response(request)
  File "/home/mrtbadboy/.local/lib/python3.9/site-packages/django/core/handlers/base.py", line 181, in _get_response
    response = wrapped_callback(request, *callback_args, **callback_kwargs)
  File "/home/mrtbadboy/.local/lib/python3.9/site-packages/django/views/decorators/csrf.py", line 54, in wrapped_view
    return view_func(*args, **kwargs)
  File "/home/mrtbadboy/.local/lib/python3.9/site-packages/rest_framework/viewsets.py", line 125, in view
    return self.dispatch(request, *args, **kwargs)
  File "/home/mrtbadboy/.local/lib/python3.9/site-packages/rest_framework/views.py", line 509, in dispatch
    response = self.handle_exception(exc)
  File "/home/mrtbadboy/.local/lib/python3.9/site-packages/rest_framework/views.py", line 469, in handle_exception
    self.raise_uncaught_exception(exc)
  File "/home/mrtbadboy/.local/lib/python3.9/site-packages/rest_framework/views.py", line 480, in raise_uncaught_exception
    raise exc
  File "/home/mrtbadboy/.local/lib/python3.9/site-packages/rest_framework/views.py", line 506, in dispatch
    response = handler(request, *args, **kwargs)
  File "/home/mrtbadboy/.local/lib/python3.9/site-packages/rest_framework/mixins.py", line 38, in list
    queryset = self.filter_queryset(self.get_queryset())
  File "/opt/portmanv3/portman_web/dslam/views.py", line 1460, in get_queryset
    user_type = User.objects.get(username=username).type
  File "/home/mrtbadboy/.local/lib/python3.9/site-packages/django/db/models/manager.py", line 85, in manager_method
    return getattr(self.get_queryset(), name)(*args, **kwargs)
  File "/home/mrtbadboy/.local/lib/python3.9/site-packages/django/db/models/query.py", line 435, in get
    raise self.model.DoesNotExist(
users.models.User.DoesNotExist: User matching query does not exist.
Unauthorized: /api/v1/command/
Internal Server Error: /api/v1/command/
Traceback (most recent call last):
  File "/home/mrtbadboy/.local/lib/python3.9/site-packages/django/core/handlers/exception.py", line 47, in inner
    response = get_response(request)
  File "/home/mrtbadboy/.local/lib/python3.9/site-packages/django/core/handlers/base.py", line 181, in _get_response
    response = wrapped_callback(request, *callback_args, **callback_kwargs)
  File "/home/mrtbadboy/.local/lib/python3.9/site-packages/django/views/decorators/csrf.py", line 54, in wrapped_view
    return view_func(*args, **kwargs)
  File "/home/mrtbadboy/.local/lib/python3.9/site-packages/rest_framework/viewsets.py", line 125, in view
    return self.dispatch(request, *args, **kwargs)
  File "/home/mrtbadboy/.local/lib/python3.9/site-packages/rest_framework/views.py", line 509, in dispatch
    response = self.handle_exception(exc)
  File "/home/mrtbadboy/.local/lib/python3.9/site-packages/rest_framework/views.py", line 469, in handle_exception
    self.raise_uncaught_exception(exc)
  File "/home/mrtbadboy/.local/lib/python3.9/site-packages/rest_framework/views.py", line 480, in raise_uncaught_exception
    raise exc
  File "/home/mrtbadboy/.local/lib/python3.9/site-packages/rest_framework/views.py", line 506, in dispatch
    response = handler(request, *args, **kwargs)
  File "/home/mrtbadboy/.local/lib/python3.9/site-packages/rest_framework/mixins.py", line 38, in list
    queryset = self.filter_queryset(self.get_queryset())
  File "/opt/portmanv3/portman_web/dslam/views.py", line 1461, in get_queryset
    user_type = User.objects.get(username=username).type
  File "/home/mrtbadboy/.local/lib/python3.9/site-packages/django/db/models/manager.py", line 85, in manager_method
    return getattr(self.get_queryset(), name)(*args, **kwargs)
  File "/home/mrtbadboy/.local/lib/python3.9/site-packages/django/db/models/query.py", line 435, in get
    raise self.model.DoesNotExist(
users.models.User.DoesNotExist: User matching query does not exist.
Internal Server Error: /api/v1/command/
Traceback (most recent call last):
  File "/home/mrtbadboy/.local/lib/python3.9/site-packages/django/core/handlers/exception.py", line 47, in inner
    response = get_response(request)
  File "/home/mrtbadboy/.local/lib/python3.9/site-packages/django/core/handlers/base.py", line 181, in _get_response
    response = wrapped_callback(request, *callback_args, **callback_kwargs)
  File "/home/mrtbadboy/.local/lib/python3.9/site-packages/django/views/decorators/csrf.py", line 54, in wrapped_view
    return view_func(*args, **kwargs)
  File "/home/mrtbadboy/.local/lib/python3.9/site-packages/rest_framework/viewsets.py", line 125, in view
    return self.dispatch(request, *args, **kwargs)
  File "/home/mrtbadboy/.local/lib/python3.9/site-packages/rest_framework/views.py", line 509, in dispatch
    response = self.handle_exception(exc)
  File "/home/mrtbadboy/.local/lib/python3.9/site-packages/rest_framework/views.py", line 469, in handle_exception
    self.raise_uncaught_exception(exc)
  File "/home/mrtbadboy/.local/lib/python3.9/site-packages/rest_framework/views.py", line 480, in raise_uncaught_exception
    raise exc
  File "/home/mrtbadboy/.local/lib/python3.9/site-packages/rest_framework/views.py", line 506, in dispatch
    response = handler(request, *args, **kwargs)
  File "/home/mrtbadboy/.local/lib/python3.9/site-packages/rest_framework/mixins.py", line 38, in list
    queryset = self.filter_queryset(self.get_queryset())
  File "/opt/portmanv3/portman_web/dslam/views.py", line 1463, in get_queryset
    user_type = User.objects.get(username=username).type
  File "/home/mrtbadboy/.local/lib/python3.9/site-packages/django/db/models/manager.py", line 85, in manager_method
    return getattr(self.get_queryset(), name)(*args, **kwargs)
  File "/home/mrtbadboy/.local/lib/python3.9/site-packages/django/db/models/query.py", line 435, in get
    raise self.model.DoesNotExist(
users.models.User.DoesNotExist: User matching query does not exist.
Internal Server Error: /api/v1/command/
Traceback (most recent call last):
  File "/home/mrtbadboy/.local/lib/python3.9/site-packages/django/core/handlers/exception.py", line 47, in inner
    response = get_response(request)
  File "/home/mrtbadboy/.local/lib/python3.9/site-packages/django/core/handlers/base.py", line 181, in _get_response
    response = wrapped_callback(request, *callback_args, **callback_kwargs)
  File "/home/mrtbadboy/.local/lib/python3.9/site-packages/django/views/decorators/csrf.py", line 54, in wrapped_view
    return view_func(*args, **kwargs)
  File "/home/mrtbadboy/.local/lib/python3.9/site-packages/rest_framework/viewsets.py", line 125, in view
    return self.dispatch(request, *args, **kwargs)
  File "/home/mrtbadboy/.local/lib/python3.9/site-packages/rest_framework/views.py", line 509, in dispatch
    response = self.handle_exception(exc)
  File "/home/mrtbadboy/.local/lib/python3.9/site-packages/rest_framework/views.py", line 469, in handle_exception
    self.raise_uncaught_exception(exc)
  File "/home/mrtbadboy/.local/lib/python3.9/site-packages/rest_framework/views.py", line 480, in raise_uncaught_exception
    raise exc
  File "/home/mrtbadboy/.local/lib/python3.9/site-packages/rest_framework/views.py", line 506, in dispatch
    response = handler(request, *args, **kwargs)
  File "/home/mrtbadboy/.local/lib/python3.9/site-packages/rest_framework/mixins.py", line 38, in list
    queryset = self.filter_queryset(self.get_queryset())
  File "/opt/portmanv3/portman_web/dslam/views.py", line 1464, in get_queryset
    user_type = User.objects.get(username=username).type
  File "/home/mrtbadboy/.local/lib/python3.9/site-packages/django/db/models/manager.py", line 85, in manager_method
    return getattr(self.get_queryset(), name)(*args, **kwargs)
  File "/home/mrtbadboy/.local/lib/python3.9/site-packages/django/db/models/query.py", line 435, in get
    raise self.model.DoesNotExist(
users.models.User.DoesNotExist: User matching query does not exist.
Internal Server Error: /api/v1/command/
Traceback (most recent call last):
  File "/home/mrtbadboy/.local/lib/python3.9/site-packages/django/core/handlers/exception.py", line 47, in inner
    response = get_response(request)
  File "/home/mrtbadboy/.local/lib/python3.9/site-packages/django/core/handlers/base.py", line 181, in _get_response
    response = wrapped_callback(request, *callback_args, **callback_kwargs)
  File "/home/mrtbadboy/.local/lib/python3.9/site-packages/django/views/decorators/csrf.py", line 54, in wrapped_view
    return view_func(*args, **kwargs)
  File "/home/mrtbadboy/.local/lib/python3.9/site-packages/rest_framework/viewsets.py", line 125, in view
    return self.dispatch(request, *args, **kwargs)
  File "/home/mrtbadboy/.local/lib/python3.9/site-packages/rest_framework/views.py", line 509, in dispatch
    response = self.handle_exception(exc)
  File "/home/mrtbadboy/.local/lib/python3.9/site-packages/rest_framework/views.py", line 469, in handle_exception
    self.raise_uncaught_exception(exc)
  File "/home/mrtbadboy/.local/lib/python3.9/site-packages/rest_framework/views.py", line 480, in raise_uncaught_exception
    raise exc
  File "/home/mrtbadboy/.local/lib/python3.9/site-packages/rest_framework/views.py", line 506, in dispatch
    response = handler(request, *args, **kwargs)
  File "/home/mrtbadboy/.local/lib/python3.9/site-packages/rest_framework/mixins.py", line 38, in list
    queryset = self.filter_queryset(self.get_queryset())
  File "/opt/portmanv3/portman_web/dslam/views.py", line 1481, in get_queryset
    user_type = User.objects.get(email=ldap_email).type
  File "/home/mrtbadboy/.local/lib/python3.9/site-packages/django/db/models/manager.py", line 85, in manager_method
    return getattr(self.get_queryset(), name)(*args, **kwargs)
  File "/home/mrtbadboy/.local/lib/python3.9/site-packages/django/db/models/query.py", line 435, in get
    raise self.model.DoesNotExist(
users.models.User.DoesNotExist: User matching query does not exist.
Internal Server Error: /api/v1/command/
Traceback (most recent call last):
  File "/home/mrtbadboy/.local/lib/python3.9/site-packages/django/core/handlers/exception.py", line 47, in inner
    response = get_response(request)
  File "/home/mrtbadboy/.local/lib/python3.9/site-packages/django/core/handlers/base.py", line 181, in _get_response
    response = wrapped_callback(request, *callback_args, **callback_kwargs)
  File "/home/mrtbadboy/.local/lib/python3.9/site-packages/django/views/decorators/csrf.py", line 54, in wrapped_view
    return view_func(*args, **kwargs)
  File "/home/mrtbadboy/.local/lib/python3.9/site-packages/rest_framework/viewsets.py", line 125, in view
    return self.dispatch(request, *args, **kwargs)
  File "/home/mrtbadboy/.local/lib/python3.9/site-packages/rest_framework/views.py", line 509, in dispatch
    response = self.handle_exception(exc)
  File "/home/mrtbadboy/.local/lib/python3.9/site-packages/rest_framework/views.py", line 469, in handle_exception
    self.raise_uncaught_exception(exc)
  File "/home/mrtbadboy/.local/lib/python3.9/site-packages/rest_framework/views.py", line 480, in raise_uncaught_exception
    raise exc
  File "/home/mrtbadboy/.local/lib/python3.9/site-packages/rest_framework/views.py", line 506, in dispatch
    response = handler(request, *args, **kwargs)
  File "/home/mrtbadboy/.local/lib/python3.9/site-packages/rest_framework/mixins.py", line 38, in list
    queryset = self.filter_queryset(self.get_queryset())
  File "/opt/portmanv3/portman_web/dslam/views.py", line 1481, in get_queryset
    user_type = User.objects.get(email=ldap_email).type
  File "/home/mrtbadboy/.local/lib/python3.9/site-packages/django/db/models/manager.py", line 85, in manager_method
    return getattr(self.get_queryset(), name)(*args, **kwargs)
  File "/home/mrtbadboy/.local/lib/python3.9/site-packages/django/db/models/query.py", line 435, in get
    raise self.model.DoesNotExist(
users.models.User.DoesNotExist: User matching query does not exist.
Internal Server Error: /api/v1/command/
Traceback (most recent call last):
  File "/home/mrtbadboy/.local/lib/python3.9/site-packages/django/core/handlers/exception.py", line 47, in inner
    response = get_response(request)
  File "/home/mrtbadboy/.local/lib/python3.9/site-packages/django/core/handlers/base.py", line 181, in _get_response
    response = wrapped_callback(request, *callback_args, **callback_kwargs)
  File "/home/mrtbadboy/.local/lib/python3.9/site-packages/django/views/decorators/csrf.py", line 54, in wrapped_view
    return view_func(*args, **kwargs)
  File "/home/mrtbadboy/.local/lib/python3.9/site-packages/rest_framework/viewsets.py", line 125, in view
    return self.dispatch(request, *args, **kwargs)
  File "/home/mrtbadboy/.local/lib/python3.9/site-packages/rest_framework/views.py", line 509, in dispatch
    response = self.handle_exception(exc)
  File "/home/mrtbadboy/.local/lib/python3.9/site-packages/rest_framework/views.py", line 469, in handle_exception
    self.raise_uncaught_exception(exc)
  File "/home/mrtbadboy/.local/lib/python3.9/site-packages/rest_framework/views.py", line 480, in raise_uncaught_exception
    raise exc
  File "/home/mrtbadboy/.local/lib/python3.9/site-packages/rest_framework/views.py", line 506, in dispatch
    response = handler(request, *args, **kwargs)
  File "/home/mrtbadboy/.local/lib/python3.9/site-packages/rest_framework/mixins.py", line 38, in list
    queryset = self.filter_queryset(self.get_queryset())
  File "/opt/portmanv3/portman_web/dslam/views.py", line 1463, in get_queryset
    user_type = User.objects.get(username=username).type
  File "/home/mrtbadboy/.local/lib/python3.9/site-packages/django/db/models/manager.py", line 85, in manager_method
    return getattr(self.get_queryset(), name)(*args, **kwargs)
  File "/home/mrtbadboy/.local/lib/python3.9/site-packages/django/db/models/query.py", line 435, in get
    raise self.model.DoesNotExist(
users.models.User.DoesNotExist: User matching query does not exist.
Unauthorized: /api/v1/command/
