Not Found: /favicon.ico
Method Not Allowed: /api/v1/router-command/router_run_command/
Unauthorized: /api/v1/users/login/
Unauthorized: /api/v1/users/login/
Unauthorized: /api/v1/users/login/
Internal Server Error: /api/v1/router-command/router_run_command/
Internal Server Error: /api/v1/router-command/router_run_command/
Internal Server Error: /api/v1/router-command/router_run_command/
<<<<<<< HEAD
=======
Unauthorized: /api/v1/switch/get_backup_error_text/
Not Found: /api/v1/api/v1/router/
Bad Request: /api/v1/router/
Bad Request: /api/v1/router/
Internal Server Error: /api/v1/router/
Traceback (most recent call last):
  File "/home/mrtbadboy/PycharmProjects/PortmanV3/venv/lib/python3.8/site-packages/django/core/handlers/exception.py", line 47, in inner
    response = get_response(request)
  File "/home/mrtbadboy/PycharmProjects/PortmanV3/venv/lib/python3.8/site-packages/django/core/handlers/base.py", line 179, in _get_response
    response = wrapped_callback(request, *callback_args, **callback_kwargs)
  File "/home/mrtbadboy/PycharmProjects/PortmanV3/venv/lib/python3.8/site-packages/django/views/decorators/csrf.py", line 54, in wrapped_view
    return view_func(*args, **kwargs)
  File "/home/mrtbadboy/PycharmProjects/PortmanV3/venv/lib/python3.8/site-packages/rest_framework/viewsets.py", line 125, in view
    return self.dispatch(request, *args, **kwargs)
  File "/home/mrtbadboy/PycharmProjects/PortmanV3/venv/lib/python3.8/site-packages/rest_framework/views.py", line 509, in dispatch
    response = self.handle_exception(exc)
  File "/home/mrtbadboy/PycharmProjects/PortmanV3/venv/lib/python3.8/site-packages/rest_framework/views.py", line 469, in handle_exception
    self.raise_uncaught_exception(exc)
  File "/home/mrtbadboy/PycharmProjects/PortmanV3/venv/lib/python3.8/site-packages/rest_framework/views.py", line 480, in raise_uncaught_exception
    raise exc
  File "/home/mrtbadboy/PycharmProjects/PortmanV3/venv/lib/python3.8/site-packages/rest_framework/views.py", line 506, in dispatch
    response = handler(request, *args, **kwargs)
  File "/home/mrtbadboy/PycharmProjects/PortmanV3/venv/lib/python3.8/site-packages/rest_framework/mixins.py", line 40, in list
    page = self.paginate_queryset(queryset)
  File "/home/mrtbadboy/PycharmProjects/PortmanV3/venv/lib/python3.8/site-packages/rest_framework/generics.py", line 171, in paginate_queryset
    return self.paginator.paginate_queryset(queryset, self.request, view=self)
  File "/home/mrtbadboy/PycharmProjects/PortmanV3/venv/lib/python3.8/site-packages/rest_framework/pagination.py", line 196, in paginate_queryset
    page_size = self.get_page_size(request)
  File "/home/mrtbadboy/PycharmProjects/PortmanV3/venv/lib/python3.8/site-packages/rest_framework/pagination.py", line 257, in get_page_size
    return _positive_int(
  File "/home/mrtbadboy/PycharmProjects/PortmanV3/venv/lib/python3.8/site-packages/rest_framework/pagination.py", line 30, in _positive_int
    return min(ret, cutoff)
TypeError: '<' not supported between instances of 'builtin_function_or_method' and 'int'
Not Found: /api/v1/router/router/
Internal Server Error: /api/v1/router/
Traceback (most recent call last):
  File "/home/mrtbadboy/PycharmProjects/PortmanV3/venv/lib/python3.8/site-packages/django/core/handlers/exception.py", line 47, in inner
    response = get_response(request)
  File "/home/mrtbadboy/PycharmProjects/PortmanV3/venv/lib/python3.8/site-packages/django/core/handlers/base.py", line 179, in _get_response
    response = wrapped_callback(request, *callback_args, **callback_kwargs)
  File "/home/mrtbadboy/PycharmProjects/PortmanV3/venv/lib/python3.8/site-packages/django/views/decorators/csrf.py", line 54, in wrapped_view
    return view_func(*args, **kwargs)
  File "/home/mrtbadboy/PycharmProjects/PortmanV3/venv/lib/python3.8/site-packages/rest_framework/viewsets.py", line 125, in view
    return self.dispatch(request, *args, **kwargs)
  File "/home/mrtbadboy/PycharmProjects/PortmanV3/venv/lib/python3.8/site-packages/rest_framework/views.py", line 509, in dispatch
    response = self.handle_exception(exc)
  File "/home/mrtbadboy/PycharmProjects/PortmanV3/venv/lib/python3.8/site-packages/rest_framework/views.py", line 469, in handle_exception
    self.raise_uncaught_exception(exc)
  File "/home/mrtbadboy/PycharmProjects/PortmanV3/venv/lib/python3.8/site-packages/rest_framework/views.py", line 480, in raise_uncaught_exception
    raise exc
  File "/home/mrtbadboy/PycharmProjects/PortmanV3/venv/lib/python3.8/site-packages/rest_framework/views.py", line 506, in dispatch
    response = handler(request, *args, **kwargs)
  File "/home/mrtbadboy/PycharmProjects/PortmanV3/venv/lib/python3.8/site-packages/rest_framework/mixins.py", line 40, in list
    page = self.paginate_queryset(queryset)
  File "/home/mrtbadboy/PycharmProjects/PortmanV3/venv/lib/python3.8/site-packages/rest_framework/generics.py", line 171, in paginate_queryset
    return self.paginator.paginate_queryset(queryset, self.request, view=self)
  File "/home/mrtbadboy/PycharmProjects/PortmanV3/venv/lib/python3.8/site-packages/rest_framework/pagination.py", line 196, in paginate_queryset
    page_size = self.get_page_size(request)
  File "/home/mrtbadboy/PycharmProjects/PortmanV3/venv/lib/python3.8/site-packages/rest_framework/pagination.py", line 257, in get_page_size
    return _positive_int(
  File "/home/mrtbadboy/PycharmProjects/PortmanV3/venv/lib/python3.8/site-packages/rest_framework/pagination.py", line 30, in _positive_int
    return min(ret, cutoff)
TypeError: '<' not supported between instances of 'builtin_function_or_method' and 'int'
Internal Server Error: /api/v1/router
Traceback (most recent call last):
  File "/home/mrtbadboy/PycharmProjects/PortmanV3/venv/lib/python3.8/site-packages/django/core/handlers/exception.py", line 47, in inner
    response = get_response(request)
  File "/home/mrtbadboy/PycharmProjects/PortmanV3/venv/lib/python3.8/site-packages/django/utils/deprecation.py", line 113, in __call__
    response = self.process_request(request)
  File "/home/mrtbadboy/PycharmProjects/PortmanV3/venv/lib/python3.8/site-packages/django/middleware/common.py", line 54, in process_request
    path = self.get_full_path_with_slash(request)
  File "/home/mrtbadboy/PycharmProjects/PortmanV3/venv/lib/python3.8/site-packages/django/middleware/common.py", line 87, in get_full_path_with_slash
    raise RuntimeError(
RuntimeError: You called this URL via POST, but the URL doesn't end in a slash and you have APPEND_SLASH set. Django can't redirect to the slash URL while maintaining POST data. Change your form to point to localhost:2080/api/v1/router/?page=1&page_size=10 (note the trailing slash), or set APPEND_SLASH=False in your Django settings.
Bad Request: /api/v1/router/
Bad Request: /api/v1/router/
Bad Request: /api/v1/router/
Bad Request: /api/v1/router/
Bad Request: /api/v1/router/
Bad Request: /api/v1/router/
Bad Request: /api/v1/router/
Bad Request: /api/v1/router/
Bad Request: /api/v1/router/
Bad Request: /api/v1/switch/
Bad Request: /api/v1/switch/
Unauthorized: /api/v1/switch/get_backup_error_file/
Method Not Allowed: /api/v1/switch-command/
Unauthorized: /api/v1/switch/get_backup_error_file/
Method Not Allowed: /api/v1/switch/get_backup_error_file/
Method Not Allowed: /api/v1/switch-command/switch_run_command/
Not Found: /api/v1/switch-command/switch_run_command/
Not Found: /api/v1/api/v1/switch/switch_run_command/
>>>>>>> 03b2e1e562ff913571df53ca421528529f79c1b1
Internal Server Error: /api/v1/router-command/router_run_command/
Internal Server Error: /api/v1/router-command/router_run_command/
Unauthorized: /api/v1/switch/get_backup_error_file/
Unauthorized: /api/v1/router/
Unauthorized: /api/v1/switch/
Unauthorized: /api/v1/switch/
Unauthorized: /api/v1/switch/
Unauthorized: /api/v1/switch/
Not Found: /favicon.ico
Unauthorized: /api/v1/switch/get_backup_error_file/
Unauthorized: /api/v1/router/
Forbidden: /api/v1/dslamport/events/
Forbidden: /api/v1/dslam/events/
Forbidden: /api/v1/dslamport/events/
Forbidden: /api/v1/dslam/events/
Forbidden: /api/v1/dslamport/events/
Forbidden: /api/v1/dslam/events/
Internal Server Error: /api/v1/dslam/get_interface_traffic_input/
Internal Server Error: /api/v1/dslam/get_interface_traffic_input/
Internal Server Error: /api/v1/dslam/get_interface_traffic_input/
Not Found: /favicon.ico
Internal Server Error: /api/v1/contact/portmap/
Traceback (most recent call last):
  File "/usr/local/lib/python3.8/dist-packages/django/core/handlers/exception.py", line 47, in inner
    response = get_response(request)
  File "/usr/local/lib/python3.8/dist-packages/django/core/handlers/base.py", line 179, in _get_response
    response = wrapped_callback(request, *callback_args, **callback_kwargs)
  File "/usr/local/lib/python3.8/dist-packages/django/views/decorators/csrf.py", line 54, in wrapped_view
    return view_func(*args, **kwargs)
  File "/usr/local/lib/python3.8/dist-packages/rest_framework/viewsets.py", line 125, in view
    return self.dispatch(request, *args, **kwargs)
  File "/usr/local/lib/python3.8/dist-packages/rest_framework/views.py", line 509, in dispatch
    response = self.handle_exception(exc)
  File "/usr/local/lib/python3.8/dist-packages/rest_framework/views.py", line 469, in handle_exception
    self.raise_uncaught_exception(exc)
  File "/usr/local/lib/python3.8/dist-packages/rest_framework/views.py", line 480, in raise_uncaught_exception
    raise exc
  File "/usr/local/lib/python3.8/dist-packages/rest_framework/views.py", line 506, in dispatch
    response = handler(request, *args, **kwargs)
  File "/usr/local/lib/python3.8/dist-packages/rest_framework/mixins.py", line 42, in list
    serializer = self.get_serializer(page, many=True)
  File "/opt/portmanv3/portman_web/contact/views.py", line 44, in get_serializer
    return OrderSerializer(request=self.request, remove_fields=_fields, *args, **kwargs)
  File "/usr/local/lib/python3.8/dist-packages/rest_framework/serializers.py", line 121, in __new__
    return cls.many_init(*args, **kwargs)
  File "/usr/local/lib/python3.8/dist-packages/rest_framework/serializers.py", line 146, in many_init
    child_serializer = cls(*args, **kwargs)
  File "/opt/portmanv3/portman_web/contact/serializers.py", line 18, in __init__
    self.fields.pop(field_name)
  File "/usr/lib/python3.8/_collections_abc.py", line 795, in pop
    value = self[key]
  File "/usr/local/lib/python3.8/dist-packages/rest_framework/utils/serializer_helpers.py", line 148, in __getitem__
    return self.fields[key]
KeyError: 'telnet_password'
Internal Server Error: /api/v1/dslam/get_interface_traffic_input/
Internal Server Error: /api/v1/dslam/get_interface_traffic_input/
Internal Server Error: /api/v1/dslam/get_interface_traffic_input/
Internal Server Error: /api/v1/dslam/get_interface_traffic_input/
