Bad Request: /
Bad Request: /favicon.ico
Not Found: /
Not Found: /
Method Not Allowed: /users/get-token
Method Not Allowed: /users/get-token
Bad Request: /
Bad Request: /favicon.ico
Not Found: /
Bad Request: /users/get-token
Bad Request: /users/get-token
Bad Request: /users/get-token
Unauthorized: /api/v1/dslamport/run-command/
Internal Server Error: /api/v1/dslamport/register-port/
Traceback (most recent call last):
  File "/home/mrtbadboy/PycharmProjects/PortmanV3/venv/lib/python3.8/site-packages/django/core/handlers/exception.py", line 47, in inner
    response = get_response(request)
  File "/home/mrtbadboy/PycharmProjects/PortmanV3/venv/lib/python3.8/site-packages/django/core/handlers/base.py", line 179, in _get_response
    response = wrapped_callback(request, *callback_args, **callback_kwargs)
  File "/home/mrtbadboy/PycharmProjects/PortmanV3/venv/lib/python3.8/site-packages/django/views/decorators/csrf.py", line 54, in wrapped_view
    return view_func(*args, **kwargs)
  File "/home/mrtbadboy/PycharmProjects/PortmanV3/venv/lib/python3.8/site-packages/django/views/generic/base.py", line 70, in view
    return self.dispatch(request, *args, **kwargs)
  File "/home/mrtbadboy/PycharmProjects/PortmanV3/venv/lib/python3.8/site-packages/rest_framework/views.py", line 509, in dispatch
    response = self.handle_exception(exc)
  File "/home/mrtbadboy/PycharmProjects/PortmanV3/venv/lib/python3.8/site-packages/rest_framework/views.py", line 469, in handle_exception
    self.raise_uncaught_exception(exc)
  File "/home/mrtbadboy/PycharmProjects/PortmanV3/venv/lib/python3.8/site-packages/rest_framework/views.py", line 480, in raise_uncaught_exception
    raise exc
  File "/home/mrtbadboy/PycharmProjects/PortmanV3/venv/lib/python3.8/site-packages/rest_framework/views.py", line 506, in dispatch
    response = handler(request, *args, **kwargs)
  File "/opt/portmanv3/portman_web/dslam/views.py", line 3335, in post
    print(request.body)
  File "/home/mrtbadboy/PycharmProjects/PortmanV3/venv/lib/python3.8/site-packages/rest_framework/request.py", line 416, in __getattr__
    return getattr(self._request, attr)
  File "/home/mrtbadboy/PycharmProjects/PortmanV3/venv/lib/python3.8/site-packages/django/http/request.py", line 320, in body
    int(self.META.get('CONTENT_LENGTH') or 0) > settings.DATA_UPLOAD_MAX_MEMORY_SIZE):
ValueError: invalid literal for int() with base 10: 'application/json'
Unauthorized: /api/v1/dslamport/run-command/
Not Found: /
Not Found: /favicon.ico
Not Found: /
Not Found: /favicon.ico
Unauthorized: /api/v1/modem/getModemInfo/
Not Found: /
Not Found: /favicon.ico
Bad Request: /admin
Bad Request: /favicon.ico
Bad Request: /admin
Bad Request: /admin
Not Found: /favicon.ico
Not Found: /favicon.ico
Internal Server Error: /admin/dslam/capacitytype/
Traceback (most recent call last):
  File "/home/mrtbadboy/PycharmProjects/PortmanV3/venv/lib/python3.8/site-packages/django/db/backends/utils.py", line 84, in _execute
    return self.cursor.execute(sql, params)
psycopg2.errors.UndefinedTable: relation "dslam_capacitytype" does not exist
LINE 1: SELECT COUNT(*) AS "__count" FROM "dslam_capacitytype"
                                          ^


The above exception was the direct cause of the following exception:

Traceback (most recent call last):
  File "/home/mrtbadboy/PycharmProjects/PortmanV3/venv/lib/python3.8/site-packages/django/core/handlers/exception.py", line 47, in inner
    response = get_response(request)
  File "/home/mrtbadboy/PycharmProjects/PortmanV3/venv/lib/python3.8/site-packages/django/core/handlers/base.py", line 179, in _get_response
    response = wrapped_callback(request, *callback_args, **callback_kwargs)
  File "/home/mrtbadboy/PycharmProjects/PortmanV3/venv/lib/python3.8/site-packages/django/contrib/admin/options.py", line 614, in wrapper
    return self.admin_site.admin_view(view)(*args, **kwargs)
  File "/home/mrtbadboy/PycharmProjects/PortmanV3/venv/lib/python3.8/site-packages/django/utils/decorators.py", line 130, in _wrapped_view
    response = view_func(request, *args, **kwargs)
  File "/home/mrtbadboy/PycharmProjects/PortmanV3/venv/lib/python3.8/site-packages/django/views/decorators/cache.py", line 44, in _wrapped_view_func
    response = view_func(request, *args, **kwargs)
  File "/home/mrtbadboy/PycharmProjects/PortmanV3/venv/lib/python3.8/site-packages/django/contrib/admin/sites.py", line 233, in inner
    return view(request, *args, **kwargs)
  File "/home/mrtbadboy/PycharmProjects/PortmanV3/venv/lib/python3.8/site-packages/django/utils/decorators.py", line 43, in _wrapper
    return bound_method(*args, **kwargs)
  File "/home/mrtbadboy/PycharmProjects/PortmanV3/venv/lib/python3.8/site-packages/django/utils/decorators.py", line 130, in _wrapped_view
    response = view_func(request, *args, **kwargs)
  File "/home/mrtbadboy/PycharmProjects/PortmanV3/venv/lib/python3.8/site-packages/django/contrib/admin/options.py", line 1693, in changelist_view
    cl = self.get_changelist_instance(request)
  File "/home/mrtbadboy/PycharmProjects/PortmanV3/venv/lib/python3.8/site-packages/django/contrib/admin/options.py", line 735, in get_changelist_instance
    return ChangeList(
  File "/home/mrtbadboy/PycharmProjects/PortmanV3/venv/lib/python3.8/site-packages/django/contrib/admin/views/main.py", line 100, in __init__
    self.get_results(request)
  File "/home/mrtbadboy/PycharmProjects/PortmanV3/venv/lib/python3.8/site-packages/django/contrib/admin/views/main.py", line 235, in get_results
    result_count = paginator.count
  File "/home/mrtbadboy/PycharmProjects/PortmanV3/venv/lib/python3.8/site-packages/django/utils/functional.py", line 48, in __get__
    res = instance.__dict__[self.name] = self.func(instance)
  File "/home/mrtbadboy/PycharmProjects/PortmanV3/venv/lib/python3.8/site-packages/django/core/paginator.py", line 94, in count
    return c()
  File "/home/mrtbadboy/PycharmProjects/PortmanV3/venv/lib/python3.8/site-packages/django/db/models/query.py", line 411, in count
    return self.query.get_count(using=self.db)
  File "/home/mrtbadboy/PycharmProjects/PortmanV3/venv/lib/python3.8/site-packages/django/db/models/sql/query.py", line 515, in get_count
    number = obj.get_aggregation(using, ['__count'])['__count']
  File "/home/mrtbadboy/PycharmProjects/PortmanV3/venv/lib/python3.8/site-packages/django/db/models/sql/query.py", line 500, in get_aggregation
    result = compiler.execute_sql(SINGLE)
  File "/home/mrtbadboy/PycharmProjects/PortmanV3/venv/lib/python3.8/site-packages/django/db/models/sql/compiler.py", line 1156, in execute_sql
    cursor.execute(sql, params)
  File "/home/mrtbadboy/PycharmProjects/PortmanV3/venv/lib/python3.8/site-packages/django/db/backends/utils.py", line 98, in execute
    return super().execute(sql, params)
  File "/home/mrtbadboy/PycharmProjects/PortmanV3/venv/lib/python3.8/site-packages/django/db/backends/utils.py", line 66, in execute
    return self._execute_with_wrappers(sql, params, many=False, executor=self._execute)
  File "/home/mrtbadboy/PycharmProjects/PortmanV3/venv/lib/python3.8/site-packages/django/db/backends/utils.py", line 75, in _execute_with_wrappers
    return executor(sql, params, many, context)
  File "/home/mrtbadboy/PycharmProjects/PortmanV3/venv/lib/python3.8/site-packages/django/db/backends/utils.py", line 84, in _execute
    return self.cursor.execute(sql, params)
  File "/home/mrtbadboy/PycharmProjects/PortmanV3/venv/lib/python3.8/site-packages/django/db/utils.py", line 90, in __exit__
    raise dj_exc_value.with_traceback(traceback) from exc_value
  File "/home/mrtbadboy/PycharmProjects/PortmanV3/venv/lib/python3.8/site-packages/django/db/backends/utils.py", line 84, in _execute
    return self.cursor.execute(sql, params)
django.db.utils.ProgrammingError: relation "dslam_capacitytype" does not exist
LINE 1: SELECT COUNT(*) AS "__count" FROM "dslam_capacitytype"
                                          ^

Internal Server Error: /admin/dslam/capacitytype/
Traceback (most recent call last):
  File "/home/mrtbadboy/PycharmProjects/PortmanV3/venv/lib/python3.8/site-packages/django/db/backends/utils.py", line 84, in _execute
    return self.cursor.execute(sql, params)
psycopg2.errors.UndefinedTable: relation "dslam_capacitytype" does not exist
LINE 1: SELECT COUNT(*) AS "__count" FROM "dslam_capacitytype"
                                          ^


The above exception was the direct cause of the following exception:

Traceback (most recent call last):
  File "/home/mrtbadboy/PycharmProjects/PortmanV3/venv/lib/python3.8/site-packages/django/core/handlers/exception.py", line 47, in inner
    response = get_response(request)
  File "/home/mrtbadboy/PycharmProjects/PortmanV3/venv/lib/python3.8/site-packages/django/core/handlers/base.py", line 179, in _get_response
    response = wrapped_callback(request, *callback_args, **callback_kwargs)
  File "/home/mrtbadboy/PycharmProjects/PortmanV3/venv/lib/python3.8/site-packages/django/contrib/admin/options.py", line 614, in wrapper
    return self.admin_site.admin_view(view)(*args, **kwargs)
  File "/home/mrtbadboy/PycharmProjects/PortmanV3/venv/lib/python3.8/site-packages/django/utils/decorators.py", line 130, in _wrapped_view
    response = view_func(request, *args, **kwargs)
  File "/home/mrtbadboy/PycharmProjects/PortmanV3/venv/lib/python3.8/site-packages/django/views/decorators/cache.py", line 44, in _wrapped_view_func
    response = view_func(request, *args, **kwargs)
  File "/home/mrtbadboy/PycharmProjects/PortmanV3/venv/lib/python3.8/site-packages/django/contrib/admin/sites.py", line 233, in inner
    return view(request, *args, **kwargs)
  File "/home/mrtbadboy/PycharmProjects/PortmanV3/venv/lib/python3.8/site-packages/django/utils/decorators.py", line 43, in _wrapper
    return bound_method(*args, **kwargs)
  File "/home/mrtbadboy/PycharmProjects/PortmanV3/venv/lib/python3.8/site-packages/django/utils/decorators.py", line 130, in _wrapped_view
    response = view_func(request, *args, **kwargs)
  File "/home/mrtbadboy/PycharmProjects/PortmanV3/venv/lib/python3.8/site-packages/django/contrib/admin/options.py", line 1693, in changelist_view
    cl = self.get_changelist_instance(request)
  File "/home/mrtbadboy/PycharmProjects/PortmanV3/venv/lib/python3.8/site-packages/django/contrib/admin/options.py", line 735, in get_changelist_instance
    return ChangeList(
  File "/home/mrtbadboy/PycharmProjects/PortmanV3/venv/lib/python3.8/site-packages/django/contrib/admin/views/main.py", line 100, in __init__
    self.get_results(request)
  File "/home/mrtbadboy/PycharmProjects/PortmanV3/venv/lib/python3.8/site-packages/django/contrib/admin/views/main.py", line 235, in get_results
    result_count = paginator.count
  File "/home/mrtbadboy/PycharmProjects/PortmanV3/venv/lib/python3.8/site-packages/django/utils/functional.py", line 48, in __get__
    res = instance.__dict__[self.name] = self.func(instance)
  File "/home/mrtbadboy/PycharmProjects/PortmanV3/venv/lib/python3.8/site-packages/django/core/paginator.py", line 94, in count
    return c()
  File "/home/mrtbadboy/PycharmProjects/PortmanV3/venv/lib/python3.8/site-packages/django/db/models/query.py", line 411, in count
    return self.query.get_count(using=self.db)
  File "/home/mrtbadboy/PycharmProjects/PortmanV3/venv/lib/python3.8/site-packages/django/db/models/sql/query.py", line 515, in get_count
    number = obj.get_aggregation(using, ['__count'])['__count']
  File "/home/mrtbadboy/PycharmProjects/PortmanV3/venv/lib/python3.8/site-packages/django/db/models/sql/query.py", line 500, in get_aggregation
    result = compiler.execute_sql(SINGLE)
  File "/home/mrtbadboy/PycharmProjects/PortmanV3/venv/lib/python3.8/site-packages/django/db/models/sql/compiler.py", line 1156, in execute_sql
    cursor.execute(sql, params)
  File "/home/mrtbadboy/PycharmProjects/PortmanV3/venv/lib/python3.8/site-packages/django/db/backends/utils.py", line 98, in execute
    return super().execute(sql, params)
  File "/home/mrtbadboy/PycharmProjects/PortmanV3/venv/lib/python3.8/site-packages/django/db/backends/utils.py", line 66, in execute
    return self._execute_with_wrappers(sql, params, many=False, executor=self._execute)
  File "/home/mrtbadboy/PycharmProjects/PortmanV3/venv/lib/python3.8/site-packages/django/db/backends/utils.py", line 75, in _execute_with_wrappers
    return executor(sql, params, many, context)
  File "/home/mrtbadboy/PycharmProjects/PortmanV3/venv/lib/python3.8/site-packages/django/db/backends/utils.py", line 84, in _execute
    return self.cursor.execute(sql, params)
  File "/home/mrtbadboy/PycharmProjects/PortmanV3/venv/lib/python3.8/site-packages/django/db/utils.py", line 90, in __exit__
    raise dj_exc_value.with_traceback(traceback) from exc_value
  File "/home/mrtbadboy/PycharmProjects/PortmanV3/venv/lib/python3.8/site-packages/django/db/backends/utils.py", line 84, in _execute
    return self.cursor.execute(sql, params)
django.db.utils.ProgrammingError: relation "dslam_capacitytype" does not exist
LINE 1: SELECT COUNT(*) AS "__count" FROM "dslam_capacitytype"
                                          ^

Internal Server Error: /admin/dslam/capacitytype/
Traceback (most recent call last):
  File "/home/mrtbadboy/PycharmProjects/PortmanV3/venv/lib/python3.8/site-packages/django/db/backends/utils.py", line 84, in _execute
    return self.cursor.execute(sql, params)
psycopg2.errors.UndefinedTable: relation "dslam_capacitytype" does not exist
LINE 1: SELECT COUNT(*) AS "__count" FROM "dslam_capacitytype"
                                          ^


The above exception was the direct cause of the following exception:

Traceback (most recent call last):
  File "/home/mrtbadboy/PycharmProjects/PortmanV3/venv/lib/python3.8/site-packages/django/core/handlers/exception.py", line 47, in inner
    response = get_response(request)
  File "/home/mrtbadboy/PycharmProjects/PortmanV3/venv/lib/python3.8/site-packages/django/core/handlers/base.py", line 179, in _get_response
    response = wrapped_callback(request, *callback_args, **callback_kwargs)
  File "/home/mrtbadboy/PycharmProjects/PortmanV3/venv/lib/python3.8/site-packages/django/contrib/admin/options.py", line 614, in wrapper
    return self.admin_site.admin_view(view)(*args, **kwargs)
  File "/home/mrtbadboy/PycharmProjects/PortmanV3/venv/lib/python3.8/site-packages/django/utils/decorators.py", line 130, in _wrapped_view
    response = view_func(request, *args, **kwargs)
  File "/home/mrtbadboy/PycharmProjects/PortmanV3/venv/lib/python3.8/site-packages/django/views/decorators/cache.py", line 44, in _wrapped_view_func
    response = view_func(request, *args, **kwargs)
  File "/home/mrtbadboy/PycharmProjects/PortmanV3/venv/lib/python3.8/site-packages/django/contrib/admin/sites.py", line 233, in inner
    return view(request, *args, **kwargs)
  File "/home/mrtbadboy/PycharmProjects/PortmanV3/venv/lib/python3.8/site-packages/django/utils/decorators.py", line 43, in _wrapper
    return bound_method(*args, **kwargs)
  File "/home/mrtbadboy/PycharmProjects/PortmanV3/venv/lib/python3.8/site-packages/django/utils/decorators.py", line 130, in _wrapped_view
    response = view_func(request, *args, **kwargs)
  File "/home/mrtbadboy/PycharmProjects/PortmanV3/venv/lib/python3.8/site-packages/django/contrib/admin/options.py", line 1693, in changelist_view
    cl = self.get_changelist_instance(request)
  File "/home/mrtbadboy/PycharmProjects/PortmanV3/venv/lib/python3.8/site-packages/django/contrib/admin/options.py", line 735, in get_changelist_instance
    return ChangeList(
  File "/home/mrtbadboy/PycharmProjects/PortmanV3/venv/lib/python3.8/site-packages/django/contrib/admin/views/main.py", line 100, in __init__
    self.get_results(request)
  File "/home/mrtbadboy/PycharmProjects/PortmanV3/venv/lib/python3.8/site-packages/django/contrib/admin/views/main.py", line 235, in get_results
    result_count = paginator.count
  File "/home/mrtbadboy/PycharmProjects/PortmanV3/venv/lib/python3.8/site-packages/django/utils/functional.py", line 48, in __get__
    res = instance.__dict__[self.name] = self.func(instance)
  File "/home/mrtbadboy/PycharmProjects/PortmanV3/venv/lib/python3.8/site-packages/django/core/paginator.py", line 94, in count
    return c()
  File "/home/mrtbadboy/PycharmProjects/PortmanV3/venv/lib/python3.8/site-packages/django/db/models/query.py", line 411, in count
    return self.query.get_count(using=self.db)
  File "/home/mrtbadboy/PycharmProjects/PortmanV3/venv/lib/python3.8/site-packages/django/db/models/sql/query.py", line 515, in get_count
    number = obj.get_aggregation(using, ['__count'])['__count']
  File "/home/mrtbadboy/PycharmProjects/PortmanV3/venv/lib/python3.8/site-packages/django/db/models/sql/query.py", line 500, in get_aggregation
    result = compiler.execute_sql(SINGLE)
  File "/home/mrtbadboy/PycharmProjects/PortmanV3/venv/lib/python3.8/site-packages/django/db/models/sql/compiler.py", line 1156, in execute_sql
    cursor.execute(sql, params)
  File "/home/mrtbadboy/PycharmProjects/PortmanV3/venv/lib/python3.8/site-packages/django/db/backends/utils.py", line 98, in execute
    return super().execute(sql, params)
  File "/home/mrtbadboy/PycharmProjects/PortmanV3/venv/lib/python3.8/site-packages/django/db/backends/utils.py", line 66, in execute
    return self._execute_with_wrappers(sql, params, many=False, executor=self._execute)
  File "/home/mrtbadboy/PycharmProjects/PortmanV3/venv/lib/python3.8/site-packages/django/db/backends/utils.py", line 75, in _execute_with_wrappers
    return executor(sql, params, many, context)
  File "/home/mrtbadboy/PycharmProjects/PortmanV3/venv/lib/python3.8/site-packages/django/db/backends/utils.py", line 84, in _execute
    return self.cursor.execute(sql, params)
  File "/home/mrtbadboy/PycharmProjects/PortmanV3/venv/lib/python3.8/site-packages/django/db/utils.py", line 90, in __exit__
    raise dj_exc_value.with_traceback(traceback) from exc_value
  File "/home/mrtbadboy/PycharmProjects/PortmanV3/venv/lib/python3.8/site-packages/django/db/backends/utils.py", line 84, in _execute
    return self.cursor.execute(sql, params)
django.db.utils.ProgrammingError: relation "dslam_capacitytype" does not exist
LINE 1: SELECT COUNT(*) AS "__count" FROM "dslam_capacitytype"
                                          ^

Internal Server Error: /admin/router/routerbrand/
Traceback (most recent call last):
  File "/home/mrtbadboy/PycharmProjects/PortmanV3/venv/lib/python3.8/site-packages/django/db/backends/utils.py", line 84, in _execute
    return self.cursor.execute(sql, params)
psycopg2.errors.UndefinedTable: relation "router_routerbrand" does not exist
LINE 1: SELECT COUNT(*) AS "__count" FROM "router_routerbrand"
                                          ^


The above exception was the direct cause of the following exception:

Traceback (most recent call last):
  File "/home/mrtbadboy/PycharmProjects/PortmanV3/venv/lib/python3.8/site-packages/django/core/handlers/exception.py", line 47, in inner
    response = get_response(request)
  File "/home/mrtbadboy/PycharmProjects/PortmanV3/venv/lib/python3.8/site-packages/django/core/handlers/base.py", line 179, in _get_response
    response = wrapped_callback(request, *callback_args, **callback_kwargs)
  File "/home/mrtbadboy/PycharmProjects/PortmanV3/venv/lib/python3.8/site-packages/django/contrib/admin/options.py", line 614, in wrapper
    return self.admin_site.admin_view(view)(*args, **kwargs)
  File "/home/mrtbadboy/PycharmProjects/PortmanV3/venv/lib/python3.8/site-packages/django/utils/decorators.py", line 130, in _wrapped_view
    response = view_func(request, *args, **kwargs)
  File "/home/mrtbadboy/PycharmProjects/PortmanV3/venv/lib/python3.8/site-packages/django/views/decorators/cache.py", line 44, in _wrapped_view_func
    response = view_func(request, *args, **kwargs)
  File "/home/mrtbadboy/PycharmProjects/PortmanV3/venv/lib/python3.8/site-packages/django/contrib/admin/sites.py", line 233, in inner
    return view(request, *args, **kwargs)
  File "/home/mrtbadboy/PycharmProjects/PortmanV3/venv/lib/python3.8/site-packages/django/utils/decorators.py", line 43, in _wrapper
    return bound_method(*args, **kwargs)
  File "/home/mrtbadboy/PycharmProjects/PortmanV3/venv/lib/python3.8/site-packages/django/utils/decorators.py", line 130, in _wrapped_view
    response = view_func(request, *args, **kwargs)
  File "/home/mrtbadboy/PycharmProjects/PortmanV3/venv/lib/python3.8/site-packages/django/contrib/admin/options.py", line 1693, in changelist_view
    cl = self.get_changelist_instance(request)
  File "/home/mrtbadboy/PycharmProjects/PortmanV3/venv/lib/python3.8/site-packages/django/contrib/admin/options.py", line 735, in get_changelist_instance
    return ChangeList(
  File "/home/mrtbadboy/PycharmProjects/PortmanV3/venv/lib/python3.8/site-packages/django/contrib/admin/views/main.py", line 100, in __init__
    self.get_results(request)
  File "/home/mrtbadboy/PycharmProjects/PortmanV3/venv/lib/python3.8/site-packages/django/contrib/admin/views/main.py", line 235, in get_results
    result_count = paginator.count
  File "/home/mrtbadboy/PycharmProjects/PortmanV3/venv/lib/python3.8/site-packages/django/utils/functional.py", line 48, in __get__
    res = instance.__dict__[self.name] = self.func(instance)
  File "/home/mrtbadboy/PycharmProjects/PortmanV3/venv/lib/python3.8/site-packages/django/core/paginator.py", line 94, in count
    return c()
  File "/home/mrtbadboy/PycharmProjects/PortmanV3/venv/lib/python3.8/site-packages/django/db/models/query.py", line 411, in count
    return self.query.get_count(using=self.db)
  File "/home/mrtbadboy/PycharmProjects/PortmanV3/venv/lib/python3.8/site-packages/django/db/models/sql/query.py", line 515, in get_count
    number = obj.get_aggregation(using, ['__count'])['__count']
  File "/home/mrtbadboy/PycharmProjects/PortmanV3/venv/lib/python3.8/site-packages/django/db/models/sql/query.py", line 500, in get_aggregation
    result = compiler.execute_sql(SINGLE)
  File "/home/mrtbadboy/PycharmProjects/PortmanV3/venv/lib/python3.8/site-packages/django/db/models/sql/compiler.py", line 1156, in execute_sql
    cursor.execute(sql, params)
  File "/home/mrtbadboy/PycharmProjects/PortmanV3/venv/lib/python3.8/site-packages/django/db/backends/utils.py", line 98, in execute
    return super().execute(sql, params)
  File "/home/mrtbadboy/PycharmProjects/PortmanV3/venv/lib/python3.8/site-packages/django/db/backends/utils.py", line 66, in execute
    return self._execute_with_wrappers(sql, params, many=False, executor=self._execute)
  File "/home/mrtbadboy/PycharmProjects/PortmanV3/venv/lib/python3.8/site-packages/django/db/backends/utils.py", line 75, in _execute_with_wrappers
    return executor(sql, params, many, context)
  File "/home/mrtbadboy/PycharmProjects/PortmanV3/venv/lib/python3.8/site-packages/django/db/backends/utils.py", line 84, in _execute
    return self.cursor.execute(sql, params)
  File "/home/mrtbadboy/PycharmProjects/PortmanV3/venv/lib/python3.8/site-packages/django/db/utils.py", line 90, in __exit__
    raise dj_exc_value.with_traceback(traceback) from exc_value
  File "/home/mrtbadboy/PycharmProjects/PortmanV3/venv/lib/python3.8/site-packages/django/db/backends/utils.py", line 84, in _execute
    return self.cursor.execute(sql, params)
django.db.utils.ProgrammingError: relation "router_routerbrand" does not exist
LINE 1: SELECT COUNT(*) AS "__count" FROM "router_routerbrand"
                                          ^

Not Found: /favicon.ico
Unauthorized: /api/v1/router/router-runCommand/
Unauthorized: /api/v1/router/router-runCommand/
Unauthorized: /api/v1/router/router-runCommand/
Unauthorized: /api/v1/router/router-runCommand/
Unauthorized: /api/v1/router/router-runCommand/
Unauthorized: /api/v1/router/router-runCommand/
Unauthorized: /api/v1/router/router-runCommand/
Unauthorized: /api/v1/router/router-runCommand/
Unauthorized: /api/v1/router/router-runCommand/
Not Found: /favicon.ico
Not Found: /favicon.ico
Not Found: /favicon.ico
