Unauthorized: /api/v1/command/
Internal Server Error: /api/v1/command/
Traceback (most recent call last):
  File "/home/mrtbadboy/.local/lib/python3.9/site-packages/django/db/backends/utils.py", line 84, in _execute
    return self.cursor.execute(sql, params)
psycopg2.errors.SyntaxError: subquery has too many columns
LINE 1: ... FROM "dslam_command" WHERE ("dslam_command"."id" IN (SELECT...
                                                             ^


The above exception was the direct cause of the following exception:

Traceback (most recent call last):
  File "/home/mrtbadboy/.local/lib/python3.9/site-packages/django/core/handlers/exception.py", line 47, in inner
    response = get_response(request)
  File "/home/mrtbadboy/.local/lib/python3.9/site-packages/django/core/handlers/base.py", line 181, in _get_response
    response = wrapped_callback(request, *callback_args, **callback_kwargs)
  File "/home/mrtbadboy/.local/lib/python3.9/site-packages/django/views/decorators/csrf.py", line 54, in wrapped_view
    return view_func(*args, **kwargs)
  File "/home/mrtbadboy/.local/lib/python3.9/site-packages/rest_framework/viewsets.py", line 125, in view
    return self.dispatch(request, *args, **kwargs)
  File "/home/mrtbadboy/.local/lib/python3.9/site-packages/rest_framework/views.py", line 509, in dispatch
    response = self.handle_exception(exc)
  File "/home/mrtbadboy/.local/lib/python3.9/site-packages/rest_framework/views.py", line 469, in handle_exception
    self.raise_uncaught_exception(exc)
  File "/home/mrtbadboy/.local/lib/python3.9/site-packages/rest_framework/views.py", line 480, in raise_uncaught_exception
    raise exc
  File "/home/mrtbadboy/.local/lib/python3.9/site-packages/rest_framework/views.py", line 506, in dispatch
    response = handler(request, *args, **kwargs)
  File "/home/mrtbadboy/.local/lib/python3.9/site-packages/rest_framework/mixins.py", line 46, in list
    return Response(serializer.data)
  File "/home/mrtbadboy/.local/lib/python3.9/site-packages/rest_framework/serializers.py", line 745, in data
    ret = super().data
  File "/home/mrtbadboy/.local/lib/python3.9/site-packages/rest_framework/serializers.py", line 246, in data
    self._data = self.to_representation(self.instance)
  File "/home/mrtbadboy/.local/lib/python3.9/site-packages/rest_framework/serializers.py", line 663, in to_representation
    return [
  File "/home/mrtbadboy/.local/lib/python3.9/site-packages/django/db/models/query.py", line 280, in __iter__
    self._fetch_all()
  File "/home/mrtbadboy/.local/lib/python3.9/site-packages/django/db/models/query.py", line 1324, in _fetch_all
    self._result_cache = list(self._iterable_class(self))
  File "/home/mrtbadboy/.local/lib/python3.9/site-packages/django/db/models/query.py", line 51, in __iter__
    results = compiler.execute_sql(chunked_fetch=self.chunked_fetch, chunk_size=self.chunk_size)
  File "/home/mrtbadboy/.local/lib/python3.9/site-packages/django/db/models/sql/compiler.py", line 1175, in execute_sql
    cursor.execute(sql, params)
  File "/home/mrtbadboy/.local/lib/python3.9/site-packages/django/db/backends/utils.py", line 98, in execute
    return super().execute(sql, params)
  File "/home/mrtbadboy/.local/lib/python3.9/site-packages/django/db/backends/utils.py", line 66, in execute
    return self._execute_with_wrappers(sql, params, many=False, executor=self._execute)
  File "/home/mrtbadboy/.local/lib/python3.9/site-packages/django/db/backends/utils.py", line 75, in _execute_with_wrappers
    return executor(sql, params, many, context)
  File "/home/mrtbadboy/.local/lib/python3.9/site-packages/django/db/backends/utils.py", line 84, in _execute
    return self.cursor.execute(sql, params)
  File "/home/mrtbadboy/.local/lib/python3.9/site-packages/django/db/utils.py", line 90, in __exit__
    raise dj_exc_value.with_traceback(traceback) from exc_value
  File "/home/mrtbadboy/.local/lib/python3.9/site-packages/django/db/backends/utils.py", line 84, in _execute
    return self.cursor.execute(sql, params)
django.db.utils.ProgrammingError: subquery has too many columns
LINE 1: ... FROM "dslam_command" WHERE ("dslam_command"."id" IN (SELECT...
                                                             ^

Internal Server Error: /api/v1/command/
Traceback (most recent call last):
  File "/home/mrtbadboy/.local/lib/python3.9/site-packages/django/db/backends/utils.py", line 84, in _execute
    return self.cursor.execute(sql, params)
psycopg2.errors.SyntaxError: subquery has too many columns
LINE 1: ... FROM "dslam_command" WHERE ("dslam_command"."id" IN (SELECT...
                                                             ^


The above exception was the direct cause of the following exception:

Traceback (most recent call last):
  File "/home/mrtbadboy/.local/lib/python3.9/site-packages/django/core/handlers/exception.py", line 47, in inner
    response = get_response(request)
  File "/home/mrtbadboy/.local/lib/python3.9/site-packages/django/core/handlers/base.py", line 181, in _get_response
    response = wrapped_callback(request, *callback_args, **callback_kwargs)
  File "/home/mrtbadboy/.local/lib/python3.9/site-packages/django/views/decorators/csrf.py", line 54, in wrapped_view
    return view_func(*args, **kwargs)
  File "/home/mrtbadboy/.local/lib/python3.9/site-packages/rest_framework/viewsets.py", line 125, in view
    return self.dispatch(request, *args, **kwargs)
  File "/home/mrtbadboy/.local/lib/python3.9/site-packages/rest_framework/views.py", line 509, in dispatch
    response = self.handle_exception(exc)
  File "/home/mrtbadboy/.local/lib/python3.9/site-packages/rest_framework/views.py", line 469, in handle_exception
    self.raise_uncaught_exception(exc)
  File "/home/mrtbadboy/.local/lib/python3.9/site-packages/rest_framework/views.py", line 480, in raise_uncaught_exception
    raise exc
  File "/home/mrtbadboy/.local/lib/python3.9/site-packages/rest_framework/views.py", line 506, in dispatch
    response = handler(request, *args, **kwargs)
  File "/home/mrtbadboy/.local/lib/python3.9/site-packages/rest_framework/mixins.py", line 46, in list
    return Response(serializer.data)
  File "/home/mrtbadboy/.local/lib/python3.9/site-packages/rest_framework/serializers.py", line 745, in data
    ret = super().data
  File "/home/mrtbadboy/.local/lib/python3.9/site-packages/rest_framework/serializers.py", line 246, in data
    self._data = self.to_representation(self.instance)
  File "/home/mrtbadboy/.local/lib/python3.9/site-packages/rest_framework/serializers.py", line 663, in to_representation
    return [
  File "/home/mrtbadboy/.local/lib/python3.9/site-packages/django/db/models/query.py", line 280, in __iter__
    self._fetch_all()
  File "/home/mrtbadboy/.local/lib/python3.9/site-packages/django/db/models/query.py", line 1324, in _fetch_all
    self._result_cache = list(self._iterable_class(self))
  File "/home/mrtbadboy/.local/lib/python3.9/site-packages/django/db/models/query.py", line 51, in __iter__
    results = compiler.execute_sql(chunked_fetch=self.chunked_fetch, chunk_size=self.chunk_size)
  File "/home/mrtbadboy/.local/lib/python3.9/site-packages/django/db/models/sql/compiler.py", line 1175, in execute_sql
    cursor.execute(sql, params)
  File "/home/mrtbadboy/.local/lib/python3.9/site-packages/django/db/backends/utils.py", line 98, in execute
    return super().execute(sql, params)
  File "/home/mrtbadboy/.local/lib/python3.9/site-packages/django/db/backends/utils.py", line 66, in execute
    return self._execute_with_wrappers(sql, params, many=False, executor=self._execute)
  File "/home/mrtbadboy/.local/lib/python3.9/site-packages/django/db/backends/utils.py", line 75, in _execute_with_wrappers
    return executor(sql, params, many, context)
  File "/home/mrtbadboy/.local/lib/python3.9/site-packages/django/db/backends/utils.py", line 84, in _execute
    return self.cursor.execute(sql, params)
  File "/home/mrtbadboy/.local/lib/python3.9/site-packages/django/db/utils.py", line 90, in __exit__
    raise dj_exc_value.with_traceback(traceback) from exc_value
  File "/home/mrtbadboy/.local/lib/python3.9/site-packages/django/db/backends/utils.py", line 84, in _execute
    return self.cursor.execute(sql, params)
django.db.utils.ProgrammingError: subquery has too many columns
LINE 1: ... FROM "dslam_command" WHERE ("dslam_command"."id" IN (SELECT...
                                                             ^

Internal Server Error: /api/v1/command/
Traceback (most recent call last):
  File "/home/mrtbadboy/.local/lib/python3.9/site-packages/django/db/backends/utils.py", line 84, in _execute
    return self.cursor.execute(sql, params)
psycopg2.errors.SyntaxError: subquery has too many columns
LINE 1: ... FROM "dslam_command" WHERE ("dslam_command"."id" IN (SELECT...
                                                             ^


The above exception was the direct cause of the following exception:

Traceback (most recent call last):
  File "/home/mrtbadboy/.local/lib/python3.9/site-packages/django/core/handlers/exception.py", line 47, in inner
    response = get_response(request)
  File "/home/mrtbadboy/.local/lib/python3.9/site-packages/django/core/handlers/base.py", line 181, in _get_response
    response = wrapped_callback(request, *callback_args, **callback_kwargs)
  File "/home/mrtbadboy/.local/lib/python3.9/site-packages/django/views/decorators/csrf.py", line 54, in wrapped_view
    return view_func(*args, **kwargs)
  File "/home/mrtbadboy/.local/lib/python3.9/site-packages/rest_framework/viewsets.py", line 125, in view
    return self.dispatch(request, *args, **kwargs)
  File "/home/mrtbadboy/.local/lib/python3.9/site-packages/rest_framework/views.py", line 509, in dispatch
    response = self.handle_exception(exc)
  File "/home/mrtbadboy/.local/lib/python3.9/site-packages/rest_framework/views.py", line 469, in handle_exception
    self.raise_uncaught_exception(exc)
  File "/home/mrtbadboy/.local/lib/python3.9/site-packages/rest_framework/views.py", line 480, in raise_uncaught_exception
    raise exc
  File "/home/mrtbadboy/.local/lib/python3.9/site-packages/rest_framework/views.py", line 506, in dispatch
    response = handler(request, *args, **kwargs)
  File "/home/mrtbadboy/.local/lib/python3.9/site-packages/rest_framework/mixins.py", line 46, in list
    return Response(serializer.data)
  File "/home/mrtbadboy/.local/lib/python3.9/site-packages/rest_framework/serializers.py", line 745, in data
    ret = super().data
  File "/home/mrtbadboy/.local/lib/python3.9/site-packages/rest_framework/serializers.py", line 246, in data
    self._data = self.to_representation(self.instance)
  File "/home/mrtbadboy/.local/lib/python3.9/site-packages/rest_framework/serializers.py", line 663, in to_representation
    return [
  File "/home/mrtbadboy/.local/lib/python3.9/site-packages/django/db/models/query.py", line 280, in __iter__
    self._fetch_all()
  File "/home/mrtbadboy/.local/lib/python3.9/site-packages/django/db/models/query.py", line 1324, in _fetch_all
    self._result_cache = list(self._iterable_class(self))
  File "/home/mrtbadboy/.local/lib/python3.9/site-packages/django/db/models/query.py", line 51, in __iter__
    results = compiler.execute_sql(chunked_fetch=self.chunked_fetch, chunk_size=self.chunk_size)
  File "/home/mrtbadboy/.local/lib/python3.9/site-packages/django/db/models/sql/compiler.py", line 1175, in execute_sql
    cursor.execute(sql, params)
  File "/home/mrtbadboy/.local/lib/python3.9/site-packages/django/db/backends/utils.py", line 98, in execute
    return super().execute(sql, params)
  File "/home/mrtbadboy/.local/lib/python3.9/site-packages/django/db/backends/utils.py", line 66, in execute
    return self._execute_with_wrappers(sql, params, many=False, executor=self._execute)
  File "/home/mrtbadboy/.local/lib/python3.9/site-packages/django/db/backends/utils.py", line 75, in _execute_with_wrappers
    return executor(sql, params, many, context)
  File "/home/mrtbadboy/.local/lib/python3.9/site-packages/django/db/backends/utils.py", line 84, in _execute
    return self.cursor.execute(sql, params)
  File "/home/mrtbadboy/.local/lib/python3.9/site-packages/django/db/utils.py", line 90, in __exit__
    raise dj_exc_value.with_traceback(traceback) from exc_value
  File "/home/mrtbadboy/.local/lib/python3.9/site-packages/django/db/backends/utils.py", line 84, in _execute
    return self.cursor.execute(sql, params)
django.db.utils.ProgrammingError: subquery has too many columns
LINE 1: ... FROM "dslam_command" WHERE ("dslam_command"."id" IN (SELECT...
                                                             ^

Internal Server Error: /api/v1/command/
Traceback (most recent call last):
  File "/home/mrtbadboy/.local/lib/python3.9/site-packages/django/db/backends/utils.py", line 84, in _execute
    return self.cursor.execute(sql, params)
psycopg2.errors.SyntaxError: subquery has too many columns
LINE 1: ... FROM "dslam_command" WHERE ("dslam_command"."id" IN (SELECT...
                                                             ^


The above exception was the direct cause of the following exception:

Traceback (most recent call last):
  File "/home/mrtbadboy/.local/lib/python3.9/site-packages/django/core/handlers/exception.py", line 47, in inner
    response = get_response(request)
  File "/home/mrtbadboy/.local/lib/python3.9/site-packages/django/core/handlers/base.py", line 181, in _get_response
    response = wrapped_callback(request, *callback_args, **callback_kwargs)
  File "/home/mrtbadboy/.local/lib/python3.9/site-packages/django/views/decorators/csrf.py", line 54, in wrapped_view
    return view_func(*args, **kwargs)
  File "/home/mrtbadboy/.local/lib/python3.9/site-packages/rest_framework/viewsets.py", line 125, in view
    return self.dispatch(request, *args, **kwargs)
  File "/home/mrtbadboy/.local/lib/python3.9/site-packages/rest_framework/views.py", line 509, in dispatch
    response = self.handle_exception(exc)
  File "/home/mrtbadboy/.local/lib/python3.9/site-packages/rest_framework/views.py", line 469, in handle_exception
    self.raise_uncaught_exception(exc)
  File "/home/mrtbadboy/.local/lib/python3.9/site-packages/rest_framework/views.py", line 480, in raise_uncaught_exception
    raise exc
  File "/home/mrtbadboy/.local/lib/python3.9/site-packages/rest_framework/views.py", line 506, in dispatch
    response = handler(request, *args, **kwargs)
  File "/home/mrtbadboy/.local/lib/python3.9/site-packages/rest_framework/mixins.py", line 46, in list
    return Response(serializer.data)
  File "/home/mrtbadboy/.local/lib/python3.9/site-packages/rest_framework/serializers.py", line 745, in data
    ret = super().data
  File "/home/mrtbadboy/.local/lib/python3.9/site-packages/rest_framework/serializers.py", line 246, in data
    self._data = self.to_representation(self.instance)
  File "/home/mrtbadboy/.local/lib/python3.9/site-packages/rest_framework/serializers.py", line 663, in to_representation
    return [
  File "/home/mrtbadboy/.local/lib/python3.9/site-packages/django/db/models/query.py", line 280, in __iter__
    self._fetch_all()
  File "/home/mrtbadboy/.local/lib/python3.9/site-packages/django/db/models/query.py", line 1324, in _fetch_all
    self._result_cache = list(self._iterable_class(self))
  File "/home/mrtbadboy/.local/lib/python3.9/site-packages/django/db/models/query.py", line 51, in __iter__
    results = compiler.execute_sql(chunked_fetch=self.chunked_fetch, chunk_size=self.chunk_size)
  File "/home/mrtbadboy/.local/lib/python3.9/site-packages/django/db/models/sql/compiler.py", line 1175, in execute_sql
    cursor.execute(sql, params)
  File "/home/mrtbadboy/.local/lib/python3.9/site-packages/django/db/backends/utils.py", line 98, in execute
    return super().execute(sql, params)
  File "/home/mrtbadboy/.local/lib/python3.9/site-packages/django/db/backends/utils.py", line 66, in execute
    return self._execute_with_wrappers(sql, params, many=False, executor=self._execute)
  File "/home/mrtbadboy/.local/lib/python3.9/site-packages/django/db/backends/utils.py", line 75, in _execute_with_wrappers
    return executor(sql, params, many, context)
  File "/home/mrtbadboy/.local/lib/python3.9/site-packages/django/db/backends/utils.py", line 84, in _execute
    return self.cursor.execute(sql, params)
  File "/home/mrtbadboy/.local/lib/python3.9/site-packages/django/db/utils.py", line 90, in __exit__
    raise dj_exc_value.with_traceback(traceback) from exc_value
  File "/home/mrtbadboy/.local/lib/python3.9/site-packages/django/db/backends/utils.py", line 84, in _execute
    return self.cursor.execute(sql, params)
django.db.utils.ProgrammingError: subquery has too many columns
LINE 1: ... FROM "dslam_command" WHERE ("dslam_command"."id" IN (SELECT...
                                                             ^

Internal Server Error: /api/v1/command/
Traceback (most recent call last):
  File "/home/mrtbadboy/.local/lib/python3.9/site-packages/django/db/backends/utils.py", line 84, in _execute
    return self.cursor.execute(sql, params)
psycopg2.errors.SyntaxError: subquery has too many columns
LINE 1: ... FROM "dslam_command" WHERE ("dslam_command"."id" IN (SELECT...
                                                             ^


The above exception was the direct cause of the following exception:

Traceback (most recent call last):
  File "/home/mrtbadboy/.local/lib/python3.9/site-packages/django/core/handlers/exception.py", line 47, in inner
    response = get_response(request)
  File "/home/mrtbadboy/.local/lib/python3.9/site-packages/django/core/handlers/base.py", line 181, in _get_response
    response = wrapped_callback(request, *callback_args, **callback_kwargs)
  File "/home/mrtbadboy/.local/lib/python3.9/site-packages/django/views/decorators/csrf.py", line 54, in wrapped_view
    return view_func(*args, **kwargs)
  File "/home/mrtbadboy/.local/lib/python3.9/site-packages/rest_framework/viewsets.py", line 125, in view
    return self.dispatch(request, *args, **kwargs)
  File "/home/mrtbadboy/.local/lib/python3.9/site-packages/rest_framework/views.py", line 509, in dispatch
    response = self.handle_exception(exc)
  File "/home/mrtbadboy/.local/lib/python3.9/site-packages/rest_framework/views.py", line 469, in handle_exception
    self.raise_uncaught_exception(exc)
  File "/home/mrtbadboy/.local/lib/python3.9/site-packages/rest_framework/views.py", line 480, in raise_uncaught_exception
    raise exc
  File "/home/mrtbadboy/.local/lib/python3.9/site-packages/rest_framework/views.py", line 506, in dispatch
    response = handler(request, *args, **kwargs)
  File "/home/mrtbadboy/.local/lib/python3.9/site-packages/rest_framework/mixins.py", line 46, in list
    return Response(serializer.data)
  File "/home/mrtbadboy/.local/lib/python3.9/site-packages/rest_framework/serializers.py", line 745, in data
    ret = super().data
  File "/home/mrtbadboy/.local/lib/python3.9/site-packages/rest_framework/serializers.py", line 246, in data
    self._data = self.to_representation(self.instance)
  File "/home/mrtbadboy/.local/lib/python3.9/site-packages/rest_framework/serializers.py", line 663, in to_representation
    return [
  File "/home/mrtbadboy/.local/lib/python3.9/site-packages/django/db/models/query.py", line 280, in __iter__
    self._fetch_all()
  File "/home/mrtbadboy/.local/lib/python3.9/site-packages/django/db/models/query.py", line 1324, in _fetch_all
    self._result_cache = list(self._iterable_class(self))
  File "/home/mrtbadboy/.local/lib/python3.9/site-packages/django/db/models/query.py", line 51, in __iter__
    results = compiler.execute_sql(chunked_fetch=self.chunked_fetch, chunk_size=self.chunk_size)
  File "/home/mrtbadboy/.local/lib/python3.9/site-packages/django/db/models/sql/compiler.py", line 1175, in execute_sql
    cursor.execute(sql, params)
  File "/home/mrtbadboy/.local/lib/python3.9/site-packages/django/db/backends/utils.py", line 98, in execute
    return super().execute(sql, params)
  File "/home/mrtbadboy/.local/lib/python3.9/site-packages/django/db/backends/utils.py", line 66, in execute
    return self._execute_with_wrappers(sql, params, many=False, executor=self._execute)
  File "/home/mrtbadboy/.local/lib/python3.9/site-packages/django/db/backends/utils.py", line 75, in _execute_with_wrappers
    return executor(sql, params, many, context)
  File "/home/mrtbadboy/.local/lib/python3.9/site-packages/django/db/backends/utils.py", line 84, in _execute
    return self.cursor.execute(sql, params)
  File "/home/mrtbadboy/.local/lib/python3.9/site-packages/django/db/utils.py", line 90, in __exit__
    raise dj_exc_value.with_traceback(traceback) from exc_value
  File "/home/mrtbadboy/.local/lib/python3.9/site-packages/django/db/backends/utils.py", line 84, in _execute
    return self.cursor.execute(sql, params)
django.db.utils.ProgrammingError: subquery has too many columns
LINE 1: ... FROM "dslam_command" WHERE ("dslam_command"."id" IN (SELECT...
                                                             ^

Internal Server Error: /api/v1/command/
Traceback (most recent call last):
  File "/home/mrtbadboy/.local/lib/python3.9/site-packages/django/db/backends/utils.py", line 84, in _execute
    return self.cursor.execute(sql, params)
psycopg2.errors.SyntaxError: subquery has too many columns
LINE 1: ... FROM "dslam_command" WHERE ("dslam_command"."id" IN (SELECT...
                                                             ^


The above exception was the direct cause of the following exception:

Traceback (most recent call last):
  File "/home/mrtbadboy/.local/lib/python3.9/site-packages/django/core/handlers/exception.py", line 47, in inner
    response = get_response(request)
  File "/home/mrtbadboy/.local/lib/python3.9/site-packages/django/core/handlers/base.py", line 181, in _get_response
    response = wrapped_callback(request, *callback_args, **callback_kwargs)
  File "/home/mrtbadboy/.local/lib/python3.9/site-packages/django/views/decorators/csrf.py", line 54, in wrapped_view
    return view_func(*args, **kwargs)
  File "/home/mrtbadboy/.local/lib/python3.9/site-packages/rest_framework/viewsets.py", line 125, in view
    return self.dispatch(request, *args, **kwargs)
  File "/home/mrtbadboy/.local/lib/python3.9/site-packages/rest_framework/views.py", line 509, in dispatch
    response = self.handle_exception(exc)
  File "/home/mrtbadboy/.local/lib/python3.9/site-packages/rest_framework/views.py", line 469, in handle_exception
    self.raise_uncaught_exception(exc)
  File "/home/mrtbadboy/.local/lib/python3.9/site-packages/rest_framework/views.py", line 480, in raise_uncaught_exception
    raise exc
  File "/home/mrtbadboy/.local/lib/python3.9/site-packages/rest_framework/views.py", line 506, in dispatch
    response = handler(request, *args, **kwargs)
  File "/home/mrtbadboy/.local/lib/python3.9/site-packages/rest_framework/mixins.py", line 46, in list
    return Response(serializer.data)
  File "/home/mrtbadboy/.local/lib/python3.9/site-packages/rest_framework/serializers.py", line 745, in data
    ret = super().data
  File "/home/mrtbadboy/.local/lib/python3.9/site-packages/rest_framework/serializers.py", line 246, in data
    self._data = self.to_representation(self.instance)
  File "/home/mrtbadboy/.local/lib/python3.9/site-packages/rest_framework/serializers.py", line 663, in to_representation
    return [
  File "/home/mrtbadboy/.local/lib/python3.9/site-packages/django/db/models/query.py", line 280, in __iter__
    self._fetch_all()
  File "/home/mrtbadboy/.local/lib/python3.9/site-packages/django/db/models/query.py", line 1324, in _fetch_all
    self._result_cache = list(self._iterable_class(self))
  File "/home/mrtbadboy/.local/lib/python3.9/site-packages/django/db/models/query.py", line 51, in __iter__
    results = compiler.execute_sql(chunked_fetch=self.chunked_fetch, chunk_size=self.chunk_size)
  File "/home/mrtbadboy/.local/lib/python3.9/site-packages/django/db/models/sql/compiler.py", line 1175, in execute_sql
    cursor.execute(sql, params)
  File "/home/mrtbadboy/.local/lib/python3.9/site-packages/django/db/backends/utils.py", line 98, in execute
    return super().execute(sql, params)
  File "/home/mrtbadboy/.local/lib/python3.9/site-packages/django/db/backends/utils.py", line 66, in execute
    return self._execute_with_wrappers(sql, params, many=False, executor=self._execute)
  File "/home/mrtbadboy/.local/lib/python3.9/site-packages/django/db/backends/utils.py", line 75, in _execute_with_wrappers
    return executor(sql, params, many, context)
  File "/home/mrtbadboy/.local/lib/python3.9/site-packages/django/db/backends/utils.py", line 84, in _execute
    return self.cursor.execute(sql, params)
  File "/home/mrtbadboy/.local/lib/python3.9/site-packages/django/db/utils.py", line 90, in __exit__
    raise dj_exc_value.with_traceback(traceback) from exc_value
  File "/home/mrtbadboy/.local/lib/python3.9/site-packages/django/db/backends/utils.py", line 84, in _execute
    return self.cursor.execute(sql, params)
django.db.utils.ProgrammingError: subquery has too many columns
LINE 1: ... FROM "dslam_command" WHERE ("dslam_command"."id" IN (SELECT...
                                                             ^

Internal Server Error: /api/v1/command/
Traceback (most recent call last):
  File "/home/mrtbadboy/.local/lib/python3.9/site-packages/django/db/backends/utils.py", line 84, in _execute
    return self.cursor.execute(sql, params)
psycopg2.errors.SyntaxError: subquery has too many columns
LINE 1: ... FROM "dslam_command" WHERE ("dslam_command"."id" IN (SELECT...
                                                             ^


The above exception was the direct cause of the following exception:

Traceback (most recent call last):
  File "/home/mrtbadboy/.local/lib/python3.9/site-packages/django/core/handlers/exception.py", line 47, in inner
    response = get_response(request)
  File "/home/mrtbadboy/.local/lib/python3.9/site-packages/django/core/handlers/base.py", line 181, in _get_response
    response = wrapped_callback(request, *callback_args, **callback_kwargs)
  File "/home/mrtbadboy/.local/lib/python3.9/site-packages/django/views/decorators/csrf.py", line 54, in wrapped_view
    return view_func(*args, **kwargs)
  File "/home/mrtbadboy/.local/lib/python3.9/site-packages/rest_framework/viewsets.py", line 125, in view
    return self.dispatch(request, *args, **kwargs)
  File "/home/mrtbadboy/.local/lib/python3.9/site-packages/rest_framework/views.py", line 509, in dispatch
    response = self.handle_exception(exc)
  File "/home/mrtbadboy/.local/lib/python3.9/site-packages/rest_framework/views.py", line 469, in handle_exception
    self.raise_uncaught_exception(exc)
  File "/home/mrtbadboy/.local/lib/python3.9/site-packages/rest_framework/views.py", line 480, in raise_uncaught_exception
    raise exc
  File "/home/mrtbadboy/.local/lib/python3.9/site-packages/rest_framework/views.py", line 506, in dispatch
    response = handler(request, *args, **kwargs)
  File "/home/mrtbadboy/.local/lib/python3.9/site-packages/rest_framework/mixins.py", line 46, in list
    return Response(serializer.data)
  File "/home/mrtbadboy/.local/lib/python3.9/site-packages/rest_framework/serializers.py", line 745, in data
    ret = super().data
  File "/home/mrtbadboy/.local/lib/python3.9/site-packages/rest_framework/serializers.py", line 246, in data
    self._data = self.to_representation(self.instance)
  File "/home/mrtbadboy/.local/lib/python3.9/site-packages/rest_framework/serializers.py", line 663, in to_representation
    return [
  File "/home/mrtbadboy/.local/lib/python3.9/site-packages/django/db/models/query.py", line 280, in __iter__
    self._fetch_all()
  File "/home/mrtbadboy/.local/lib/python3.9/site-packages/django/db/models/query.py", line 1324, in _fetch_all
    self._result_cache = list(self._iterable_class(self))
  File "/home/mrtbadboy/.local/lib/python3.9/site-packages/django/db/models/query.py", line 51, in __iter__
    results = compiler.execute_sql(chunked_fetch=self.chunked_fetch, chunk_size=self.chunk_size)
  File "/home/mrtbadboy/.local/lib/python3.9/site-packages/django/db/models/sql/compiler.py", line 1175, in execute_sql
    cursor.execute(sql, params)
  File "/home/mrtbadboy/.local/lib/python3.9/site-packages/django/db/backends/utils.py", line 98, in execute
    return super().execute(sql, params)
  File "/home/mrtbadboy/.local/lib/python3.9/site-packages/django/db/backends/utils.py", line 66, in execute
    return self._execute_with_wrappers(sql, params, many=False, executor=self._execute)
  File "/home/mrtbadboy/.local/lib/python3.9/site-packages/django/db/backends/utils.py", line 75, in _execute_with_wrappers
    return executor(sql, params, many, context)
  File "/home/mrtbadboy/.local/lib/python3.9/site-packages/django/db/backends/utils.py", line 84, in _execute
    return self.cursor.execute(sql, params)
  File "/home/mrtbadboy/.local/lib/python3.9/site-packages/django/db/utils.py", line 90, in __exit__
    raise dj_exc_value.with_traceback(traceback) from exc_value
  File "/home/mrtbadboy/.local/lib/python3.9/site-packages/django/db/backends/utils.py", line 84, in _execute
    return self.cursor.execute(sql, params)
django.db.utils.ProgrammingError: subquery has too many columns
LINE 1: ... FROM "dslam_command" WHERE ("dslam_command"."id" IN (SELECT...
                                                             ^

Internal Server Error: /api/v1/command/
Traceback (most recent call last):
  File "/home/mrtbadboy/.local/lib/python3.9/site-packages/django/db/backends/utils.py", line 84, in _execute
    return self.cursor.execute(sql, params)
psycopg2.errors.SyntaxError: subquery has too many columns
LINE 1: ... FROM "dslam_command" WHERE ("dslam_command"."id" IN (SELECT...
                                                             ^


The above exception was the direct cause of the following exception:

Traceback (most recent call last):
  File "/home/mrtbadboy/.local/lib/python3.9/site-packages/django/core/handlers/exception.py", line 47, in inner
    response = get_response(request)
  File "/home/mrtbadboy/.local/lib/python3.9/site-packages/django/core/handlers/base.py", line 181, in _get_response
    response = wrapped_callback(request, *callback_args, **callback_kwargs)
  File "/home/mrtbadboy/.local/lib/python3.9/site-packages/django/views/decorators/csrf.py", line 54, in wrapped_view
    return view_func(*args, **kwargs)
  File "/home/mrtbadboy/.local/lib/python3.9/site-packages/rest_framework/viewsets.py", line 125, in view
    return self.dispatch(request, *args, **kwargs)
  File "/home/mrtbadboy/.local/lib/python3.9/site-packages/rest_framework/views.py", line 509, in dispatch
    response = self.handle_exception(exc)
  File "/home/mrtbadboy/.local/lib/python3.9/site-packages/rest_framework/views.py", line 469, in handle_exception
    self.raise_uncaught_exception(exc)
  File "/home/mrtbadboy/.local/lib/python3.9/site-packages/rest_framework/views.py", line 480, in raise_uncaught_exception
    raise exc
  File "/home/mrtbadboy/.local/lib/python3.9/site-packages/rest_framework/views.py", line 506, in dispatch
    response = handler(request, *args, **kwargs)
  File "/home/mrtbadboy/.local/lib/python3.9/site-packages/rest_framework/mixins.py", line 46, in list
    return Response(serializer.data)
  File "/home/mrtbadboy/.local/lib/python3.9/site-packages/rest_framework/serializers.py", line 745, in data
    ret = super().data
  File "/home/mrtbadboy/.local/lib/python3.9/site-packages/rest_framework/serializers.py", line 246, in data
    self._data = self.to_representation(self.instance)
  File "/home/mrtbadboy/.local/lib/python3.9/site-packages/rest_framework/serializers.py", line 663, in to_representation
    return [
  File "/home/mrtbadboy/.local/lib/python3.9/site-packages/django/db/models/query.py", line 280, in __iter__
    self._fetch_all()
  File "/home/mrtbadboy/.local/lib/python3.9/site-packages/django/db/models/query.py", line 1324, in _fetch_all
    self._result_cache = list(self._iterable_class(self))
  File "/home/mrtbadboy/.local/lib/python3.9/site-packages/django/db/models/query.py", line 51, in __iter__
    results = compiler.execute_sql(chunked_fetch=self.chunked_fetch, chunk_size=self.chunk_size)
  File "/home/mrtbadboy/.local/lib/python3.9/site-packages/django/db/models/sql/compiler.py", line 1175, in execute_sql
    cursor.execute(sql, params)
  File "/home/mrtbadboy/.local/lib/python3.9/site-packages/django/db/backends/utils.py", line 98, in execute
    return super().execute(sql, params)
  File "/home/mrtbadboy/.local/lib/python3.9/site-packages/django/db/backends/utils.py", line 66, in execute
    return self._execute_with_wrappers(sql, params, many=False, executor=self._execute)
  File "/home/mrtbadboy/.local/lib/python3.9/site-packages/django/db/backends/utils.py", line 75, in _execute_with_wrappers
    return executor(sql, params, many, context)
  File "/home/mrtbadboy/.local/lib/python3.9/site-packages/django/db/backends/utils.py", line 84, in _execute
    return self.cursor.execute(sql, params)
  File "/home/mrtbadboy/.local/lib/python3.9/site-packages/django/db/utils.py", line 90, in __exit__
    raise dj_exc_value.with_traceback(traceback) from exc_value
  File "/home/mrtbadboy/.local/lib/python3.9/site-packages/django/db/backends/utils.py", line 84, in _execute
    return self.cursor.execute(sql, params)
django.db.utils.ProgrammingError: subquery has too many columns
LINE 1: ... FROM "dslam_command" WHERE ("dslam_command"."id" IN (SELECT...
                                                             ^

Internal Server Error: /api/v1/command/
Traceback (most recent call last):
  File "/home/mrtbadboy/.local/lib/python3.9/site-packages/django/db/backends/utils.py", line 84, in _execute
    return self.cursor.execute(sql, params)
psycopg2.errors.SyntaxError: subquery has too many columns
LINE 1: ... FROM "dslam_command" WHERE ("dslam_command"."id" IN (SELECT...
                                                             ^


The above exception was the direct cause of the following exception:

Traceback (most recent call last):
  File "/home/mrtbadboy/.local/lib/python3.9/site-packages/django/core/handlers/exception.py", line 47, in inner
    response = get_response(request)
  File "/home/mrtbadboy/.local/lib/python3.9/site-packages/django/core/handlers/base.py", line 181, in _get_response
    response = wrapped_callback(request, *callback_args, **callback_kwargs)
  File "/home/mrtbadboy/.local/lib/python3.9/site-packages/django/views/decorators/csrf.py", line 54, in wrapped_view
    return view_func(*args, **kwargs)
  File "/home/mrtbadboy/.local/lib/python3.9/site-packages/rest_framework/viewsets.py", line 125, in view
    return self.dispatch(request, *args, **kwargs)
  File "/home/mrtbadboy/.local/lib/python3.9/site-packages/rest_framework/views.py", line 509, in dispatch
    response = self.handle_exception(exc)
  File "/home/mrtbadboy/.local/lib/python3.9/site-packages/rest_framework/views.py", line 469, in handle_exception
    self.raise_uncaught_exception(exc)
  File "/home/mrtbadboy/.local/lib/python3.9/site-packages/rest_framework/views.py", line 480, in raise_uncaught_exception
    raise exc
  File "/home/mrtbadboy/.local/lib/python3.9/site-packages/rest_framework/views.py", line 506, in dispatch
    response = handler(request, *args, **kwargs)
  File "/home/mrtbadboy/.local/lib/python3.9/site-packages/rest_framework/mixins.py", line 46, in list
    return Response(serializer.data)
  File "/home/mrtbadboy/.local/lib/python3.9/site-packages/rest_framework/serializers.py", line 745, in data
    ret = super().data
  File "/home/mrtbadboy/.local/lib/python3.9/site-packages/rest_framework/serializers.py", line 246, in data
    self._data = self.to_representation(self.instance)
  File "/home/mrtbadboy/.local/lib/python3.9/site-packages/rest_framework/serializers.py", line 663, in to_representation
    return [
  File "/home/mrtbadboy/.local/lib/python3.9/site-packages/django/db/models/query.py", line 280, in __iter__
    self._fetch_all()
  File "/home/mrtbadboy/.local/lib/python3.9/site-packages/django/db/models/query.py", line 1324, in _fetch_all
    self._result_cache = list(self._iterable_class(self))
  File "/home/mrtbadboy/.local/lib/python3.9/site-packages/django/db/models/query.py", line 51, in __iter__
    results = compiler.execute_sql(chunked_fetch=self.chunked_fetch, chunk_size=self.chunk_size)
  File "/home/mrtbadboy/.local/lib/python3.9/site-packages/django/db/models/sql/compiler.py", line 1175, in execute_sql
    cursor.execute(sql, params)
  File "/home/mrtbadboy/.local/lib/python3.9/site-packages/django/db/backends/utils.py", line 98, in execute
    return super().execute(sql, params)
  File "/home/mrtbadboy/.local/lib/python3.9/site-packages/django/db/backends/utils.py", line 66, in execute
    return self._execute_with_wrappers(sql, params, many=False, executor=self._execute)
  File "/home/mrtbadboy/.local/lib/python3.9/site-packages/django/db/backends/utils.py", line 75, in _execute_with_wrappers
    return executor(sql, params, many, context)
  File "/home/mrtbadboy/.local/lib/python3.9/site-packages/django/db/backends/utils.py", line 84, in _execute
    return self.cursor.execute(sql, params)
  File "/home/mrtbadboy/.local/lib/python3.9/site-packages/django/db/utils.py", line 90, in __exit__
    raise dj_exc_value.with_traceback(traceback) from exc_value
  File "/home/mrtbadboy/.local/lib/python3.9/site-packages/django/db/backends/utils.py", line 84, in _execute
    return self.cursor.execute(sql, params)
django.db.utils.ProgrammingError: subquery has too many columns
LINE 1: ... FROM "dslam_command" WHERE ("dslam_command"."id" IN (SELECT...
                                                             ^

Internal Server Error: /api/v1/command/
Traceback (most recent call last):
  File "/home/mrtbadboy/.local/lib/python3.9/site-packages/django/db/backends/utils.py", line 84, in _execute
    return self.cursor.execute(sql, params)
psycopg2.errors.SyntaxError: subquery has too many columns
LINE 1: ... FROM "dslam_command" WHERE ("dslam_command"."id" IN (SELECT...
                                                             ^


The above exception was the direct cause of the following exception:

Traceback (most recent call last):
  File "/home/mrtbadboy/.local/lib/python3.9/site-packages/django/core/handlers/exception.py", line 47, in inner
    response = get_response(request)
  File "/home/mrtbadboy/.local/lib/python3.9/site-packages/django/core/handlers/base.py", line 181, in _get_response
    response = wrapped_callback(request, *callback_args, **callback_kwargs)
  File "/home/mrtbadboy/.local/lib/python3.9/site-packages/django/views/decorators/csrf.py", line 54, in wrapped_view
    return view_func(*args, **kwargs)
  File "/home/mrtbadboy/.local/lib/python3.9/site-packages/rest_framework/viewsets.py", line 125, in view
    return self.dispatch(request, *args, **kwargs)
  File "/home/mrtbadboy/.local/lib/python3.9/site-packages/rest_framework/views.py", line 509, in dispatch
    response = self.handle_exception(exc)
  File "/home/mrtbadboy/.local/lib/python3.9/site-packages/rest_framework/views.py", line 469, in handle_exception
    self.raise_uncaught_exception(exc)
  File "/home/mrtbadboy/.local/lib/python3.9/site-packages/rest_framework/views.py", line 480, in raise_uncaught_exception
    raise exc
  File "/home/mrtbadboy/.local/lib/python3.9/site-packages/rest_framework/views.py", line 506, in dispatch
    response = handler(request, *args, **kwargs)
  File "/home/mrtbadboy/.local/lib/python3.9/site-packages/rest_framework/mixins.py", line 46, in list
    return Response(serializer.data)
  File "/home/mrtbadboy/.local/lib/python3.9/site-packages/rest_framework/serializers.py", line 745, in data
    ret = super().data
  File "/home/mrtbadboy/.local/lib/python3.9/site-packages/rest_framework/serializers.py", line 246, in data
    self._data = self.to_representation(self.instance)
  File "/home/mrtbadboy/.local/lib/python3.9/site-packages/rest_framework/serializers.py", line 663, in to_representation
    return [
  File "/home/mrtbadboy/.local/lib/python3.9/site-packages/django/db/models/query.py", line 280, in __iter__
    self._fetch_all()
  File "/home/mrtbadboy/.local/lib/python3.9/site-packages/django/db/models/query.py", line 1324, in _fetch_all
    self._result_cache = list(self._iterable_class(self))
  File "/home/mrtbadboy/.local/lib/python3.9/site-packages/django/db/models/query.py", line 51, in __iter__
    results = compiler.execute_sql(chunked_fetch=self.chunked_fetch, chunk_size=self.chunk_size)
  File "/home/mrtbadboy/.local/lib/python3.9/site-packages/django/db/models/sql/compiler.py", line 1175, in execute_sql
    cursor.execute(sql, params)
  File "/home/mrtbadboy/.local/lib/python3.9/site-packages/django/db/backends/utils.py", line 98, in execute
    return super().execute(sql, params)
  File "/home/mrtbadboy/.local/lib/python3.9/site-packages/django/db/backends/utils.py", line 66, in execute
    return self._execute_with_wrappers(sql, params, many=False, executor=self._execute)
  File "/home/mrtbadboy/.local/lib/python3.9/site-packages/django/db/backends/utils.py", line 75, in _execute_with_wrappers
    return executor(sql, params, many, context)
  File "/home/mrtbadboy/.local/lib/python3.9/site-packages/django/db/backends/utils.py", line 84, in _execute
    return self.cursor.execute(sql, params)
  File "/home/mrtbadboy/.local/lib/python3.9/site-packages/django/db/utils.py", line 90, in __exit__
    raise dj_exc_value.with_traceback(traceback) from exc_value
  File "/home/mrtbadboy/.local/lib/python3.9/site-packages/django/db/backends/utils.py", line 84, in _execute
    return self.cursor.execute(sql, params)
django.db.utils.ProgrammingError: subquery has too many columns
LINE 1: ... FROM "dslam_command" WHERE ("dslam_command"."id" IN (SELECT...
                                                             ^

Not Found: /favicon.ico
Unauthorized: /api/v1/dslam/
Internal Server Error: /api/v1/dslam/
Traceback (most recent call last):
  File "/home/mrtbadboy/.local/lib/python3.9/site-packages/django/core/handlers/exception.py", line 47, in inner
    response = get_response(request)
  File "/home/mrtbadboy/.local/lib/python3.9/site-packages/django/core/handlers/base.py", line 181, in _get_response
    response = wrapped_callback(request, *callback_args, **callback_kwargs)
  File "/home/mrtbadboy/.local/lib/python3.9/site-packages/django/views/decorators/csrf.py", line 54, in wrapped_view
    return view_func(*args, **kwargs)
  File "/home/mrtbadboy/.local/lib/python3.9/site-packages/rest_framework/viewsets.py", line 125, in view
    return self.dispatch(request, *args, **kwargs)
  File "/home/mrtbadboy/.local/lib/python3.9/site-packages/rest_framework/views.py", line 509, in dispatch
    response = self.handle_exception(exc)
  File "/home/mrtbadboy/.local/lib/python3.9/site-packages/rest_framework/views.py", line 469, in handle_exception
    self.raise_uncaught_exception(exc)
  File "/home/mrtbadboy/.local/lib/python3.9/site-packages/rest_framework/views.py", line 480, in raise_uncaught_exception
    raise exc
  File "/home/mrtbadboy/.local/lib/python3.9/site-packages/rest_framework/views.py", line 506, in dispatch
    response = handler(request, *args, **kwargs)
  File "/home/mrtbadboy/.local/lib/python3.9/site-packages/rest_framework/mixins.py", line 38, in list
    queryset = self.filter_queryset(self.get_queryset())
  File "/opt/portmanv3/portman_web/dslam/views.py", line 608, in get_queryset
    allowed_dslams = model_user.get_allowed_dslams()
  File "/opt/portmanv3/portman_web/users/models.py", line 237, in get_allowed_dslams
    return self.allowed_dslams
  File "/opt/portmanv3/portman_web/users/models.py", line 86, in allowed_dslams
    if self.reseller.name == 'fanava':
AttributeError: 'NoneType' object has no attribute 'name'
Internal Server Error: /api/v1/dslam/
Traceback (most recent call last):
  File "/home/mrtbadboy/.local/lib/python3.9/site-packages/django/core/handlers/exception.py", line 47, in inner
    response = get_response(request)
  File "/home/mrtbadboy/.local/lib/python3.9/site-packages/django/core/handlers/base.py", line 181, in _get_response
    response = wrapped_callback(request, *callback_args, **callback_kwargs)
  File "/home/mrtbadboy/.local/lib/python3.9/site-packages/django/views/decorators/csrf.py", line 54, in wrapped_view
    return view_func(*args, **kwargs)
  File "/home/mrtbadboy/.local/lib/python3.9/site-packages/rest_framework/viewsets.py", line 125, in view
    return self.dispatch(request, *args, **kwargs)
  File "/home/mrtbadboy/.local/lib/python3.9/site-packages/rest_framework/views.py", line 509, in dispatch
    response = self.handle_exception(exc)
  File "/home/mrtbadboy/.local/lib/python3.9/site-packages/rest_framework/views.py", line 469, in handle_exception
    self.raise_uncaught_exception(exc)
  File "/home/mrtbadboy/.local/lib/python3.9/site-packages/rest_framework/views.py", line 480, in raise_uncaught_exception
    raise exc
  File "/home/mrtbadboy/.local/lib/python3.9/site-packages/rest_framework/views.py", line 506, in dispatch
    response = handler(request, *args, **kwargs)
  File "/home/mrtbadboy/.local/lib/python3.9/site-packages/rest_framework/mixins.py", line 38, in list
    queryset = self.filter_queryset(self.get_queryset())
  File "/opt/portmanv3/portman_web/dslam/views.py", line 608, in get_queryset
    allowed_dslams = model_user.get_allowed_dslams()
  File "/opt/portmanv3/portman_web/users/models.py", line 238, in get_allowed_dslams
    return self.allowed_dslams
  File "/opt/portmanv3/portman_web/users/models.py", line 87, in allowed_dslams
    if self.reseller.name == 'fanava':
AttributeError: 'NoneType' object has no attribute 'name'
Unauthorized: /api/v1/dslam/
Not Found: /favicon.ico
Not Found: /api/v1/dslam/
